8=FIXT.1.1|9=117|35=0|34=83|49=CLIENT|56=EXCHANGE|52=20260630-07:55:12.952167896|50=SESSION1|112=00000000-0000-0000-0000-000000000001|10=090|
8=FIXT.1.1|9=000119|35=1|49=EXCHANGE|56=CLIENT|34=2608|57=SESSION1|52=20260630-07:55:12.730335313|112=00000000-0000-0000-0000-000000000001|10=064|
8=FIXT.1.1|9=000078|35=0|49=EXCHANGE|56=CLIENT|34=2607|57=SESSION1|52=20260630-07:55:07.322117122|10=184|
8=FIXT.1.1|9=117|35=0|34=82|49=CLIENT|56=EXCHANGE|52=20260630-07:54:37.544983163|50=SESSION1|112=00000000-0000-0000-0000-000000000002|10=086|
8=FIXT.1.1|9=000119|35=1|49=EXCHANGE|56=CLIENT|34=2606|57=SESSION1|52=20260630-07:54:37.322721470|112=00000000-0000-0000-0000-000000000002|10=069|
8=FIXT.1.1|9=000078|35=0|49=EXCHANGE|56=CLIENT|34=2605|57=SESSION1|52=20260630-07:54:31.913606391|10=195|
8=FIXT.1.1|9=76|35=0|34=81|49=CLIENT|56=EXCHANGE|52=20260630-07:54:02.136886639|50=SESSION1|10=160|
8=FIXT.1.1|9=000078|35=0|49=EXCHANGE|56=CLIENT|34=2604|57=SESSION1|52=20260630-07:54:01.914701388|10=194|
8=FIXT.1.1|9=117|35=0|34=80|49=CLIENT|56=EXCHANGE|52=20260630-07:53:32.135074705|50=SESSION1|112=00000000-0000-0000-0000-000000000003|10=068|
8=FIXT.1.1|9=000119|35=1|49=EXCHANGE|56=CLIENT|34=2603|57=SESSION1|52=20260630-07:53:31.913055182|112=00000000-0000-0000-0000-000000000003|10=066|
8=FIXT.1.1|9=000078|35=0|49=EXCHANGE|56=CLIENT|34=2602|57=SESSION1|52=20260630-07:53:26.504817854|10=199|
8=FIXT.1.1|9=117|35=0|34=79|49=CLIENT|56=EXCHANGE|52=20260630-07:52:56.727983810|50=SESSION1|112=00000000-0000-0000-0000-000000000004|10=095|
8=FIXT.1.1|9=000119|35=1|49=EXCHANGE|56=CLIENT|34=2601|57=SESSION1|52=20260630-07:52:56.504801288|112=00000000-0000-0000-0000-000000000004|10=073|
8=FIXT.1.1|9=000078|35=0|49=EXCHANGE|56=CLIENT|34=2600|57=SESSION1|52=20260630-07:52:51.095687855|10=205|
8=FIXT.1.1|9=117|35=0|34=78|49=CLIENT|56=EXCHANGE|52=20260630-07:52:21.318550782|50=SESSION1|112=00000000-0000-0000-0000-000000000005|10=081|
8=FIXT.1.1|9=000119|35=1|49=EXCHANGE|56=CLIENT|34=2599|57=SESSION1|52=20260630-07:52:21.095591209|112=00000000-0000-0000-0000-000000000005|10=086|
8=FIXT.1.1|9=000078|35=0|49=EXCHANGE|56=CLIENT|34=2598|57=SESSION1|52=20260630-07:52:15.686594426|10=218|
8=FIXT.1.1|9=76|35=0|34=77|49=CLIENT|56=EXCHANGE|52=20260630-07:51:45.909044685|50=SESSION1|10=164|
8=FIXT.1.1|9=000078|35=0|49=EXCHANGE|56=CLIENT|34=2597|57=SESSION1|52=20260630-07:51:45.687466341|10=214|
8=FIXT.1.1|9=76|35=0|34=76|49=CLIENT|56=EXCHANGE|52=20260630-07:51:15.909869646|50=SESSION1|10=172|
8=FIXT.1.1|9=000078|35=0|49=EXCHANGE|56=CLIENT|34=2596|57=SESSION1|52=20260630-07:51:15.686864283|10=216|
8=FIXT.1.1|9=117|35=0|34=75|49=CLIENT|56=EXCHANGE|52=20260630-07:50:45.908373708|50=SESSION1|112=00000000-0000-0000-0000-000000000006|10=089|
8=FIXT.1.1|9=000119|35=1|49=EXCHANGE|56=CLIENT|34=2595|57=SESSION1|52=20260630-07:50:45.686829614|112=00000000-0000-0000-0000-000000000006|10=097|
8=FIXT.1.1|9=000078|35=0|49=EXCHANGE|56=CLIENT|34=2594|57=SESSION1|52=20260630-07:50:40.277282658|10=207|
8=FIXT.1.1|9=76|35=0|34=74|49=CLIENT|56=EXCHANGE|52=20260630-07:50:10.499322093|50=SESSION1|10=148|
8=FIXT.1.1|9=000078|35=0|49=EXCHANGE|56=CLIENT|34=2593|57=SESSION1|52=20260630-07:50:10.277694481|10=204|
8=FIXT.1.1|9=117|35=0|34=73|49=CLIENT|56=EXCHANGE|52=20260630-07:49:40.499335441|50=SESSION1|112=00000000-0000-0000-0000-000000000007|10=088|
8=FIXT.1.1|9=000119|35=1|49=EXCHANGE|56=CLIENT|34=2592|57=SESSION1|52=20260630-07:49:40.277630580|112=00000000-0000-0000-0000-000000000007|10=086|
8=FIXT.1.1|9=000078|35=0|49=EXCHANGE|56=CLIENT|34=2591|57=SESSION1|52=20260630-07:49:34.868443739|10=220|
8=FIXT.1.1|9=117|35=0|34=72|49=CLIENT|56=EXCHANGE|52=20260630-07:49:05.090692308|50=SESSION1|112=00000000-0000-0000-0000-000000000008|10=084|
8=FIXT.1.1|9=000119|35=1|49=EXCHANGE|56=CLIENT|34=2590|57=SESSION1|52=20260630-07:49:04.868252098|112=00000000-0000-0000-0000-000000000008|10=095|
8=FIXT.1.1|9=000078|35=0|49=EXCHANGE|56=CLIENT|34=2589|57=SESSION1|52=20260630-07:48:59.459607069|10=227|
8=FIXT.1.1|9=117|35=0|34=71|49=CLIENT|56=EXCHANGE|52=20260630-07:48:29.682355246|50=SESSION1|112=00000000-0000-0000-0000-000000000009|10=093|
8=FIXT.1.1|9=000119|35=1|49=EXCHANGE|56=CLIENT|34=2588|57=SESSION1|52=20260630-07:48:29.459986261|112=00000000-0000-0000-0000-000000000009|10=111|
8=FIXT.1.1|9=000078|35=0|49=EXCHANGE|56=CLIENT|34=2587|57=SESSION1|52=20260630-07:48:24.051315724|10=199|
8=FIXT.1.1|9=117|35=0|34=70|49=CLIENT|56=EXCHANGE|52=20260630-07:47:54.273846811|50=SESSION1|112=00000000-0000-0000-0000-000000000010|10=080|
8=FIXT.1.1|9=000119|35=1|49=EXCHANGE|56=CLIENT|34=2586|57=SESSION1|52=20260630-07:47:54.051291852|112=00000000-0000-0000-0000-000000000010|10=081|
8=FIXT.1.1|9=000078|35=0|49=EXCHANGE|56=CLIENT|34=2585|57=SESSION1|52=20260630-07:47:48.643282756|10=217|
8=FIXT.1.1|9=117|35=0|34=69|49=CLIENT|56=EXCHANGE|52=20260630-07:47:18.865824465|50=SESSION1|112=00000000-0000-0000-0000-000000000011|10=097|
8=FIXT.1.1|9=000119|35=1|49=EXCHANGE|56=CLIENT|34=2584|57=SESSION1|52=20260630-07:47:18.643400216|112=00000000-0000-0000-0000-000000000011|10=073|
8=FIXT.1.1|9=000078|35=0|49=EXCHANGE|56=CLIENT|34=2583|57=SESSION1|52=20260630-07:47:13.234424561|10=195|
8=FIXT.1.1|9=117|35=0|34=68|49=CLIENT|56=EXCHANGE|52=20260630-07:46:43.456668145|50=SESSION1|112=00000000-0000-0000-0000-000000000012|10=091|
8=FIXT.1.1|9=000119|35=1|49=EXCHANGE|56=CLIENT|34=2582|57=SESSION1|52=20260630-07:46:43.234045350|112=00000000-0000-0000-0000-000000000012|10=069|
8=FIXT.1.1|9=000078|35=0|49=EXCHANGE|56=CLIENT|34=2581|57=SESSION1|52=20260630-07:46:37.819364194|10=212|
8=FIXT.1.1|9=117|35=0|34=67|49=CLIENT|56=EXCHANGE|52=20260630-07:46:08.042855768|50=SESSION1|112=00000000-0000-0000-0000-000000000013|10=092|
8=FIXT.1.1|9=000119|35=1|49=EXCHANGE|56=CLIENT|34=2580|57=SESSION1|52=20260630-07:46:07.819154373|112=00000000-0000-0000-0000-000000000013|10=083|
8=FIXT.1.1|9=000078|35=0|49=EXCHANGE|56=CLIENT|34=2579|57=SESSION1|52=20260630-07:46:02.410548294|10=203|
8=FIXT.1.1|9=117|35=0|34=66|49=CLIENT|56=EXCHANGE|52=20260630-07:45:32.632979819|50=SESSION1|112=00000000-0000-0000-0000-000000000014|10=097|
8=FIXT.1.1|9=000119|35=1|49=EXCHANGE|56=CLIENT|34=2578|57=SESSION1|52=20260630-07:45:32.410127307|112=00000000-0000-0000-0000-000000000014|10=072|
8=FIXT.1.1|9=000150|35=CO|49=EXCHANGE|56=CLIENT|34=2577|57=SESSION1|52=20260630-07:45:26.924364133|324=1000000000000000001|1301=EXMKT|146=1|55=SYM00001|48=100000001|22=M|10=001|
8=FIXT.1.1|9=000150|35=CO|49=EXCHANGE|56=CLIENT|34=2576|57=SESSION1|52=20260630-07:45:21.923213616|324=1000000000000000001|1301=EXMKT|146=1|55=SYM00002|48=100000002|22=M|10=251|
8=FIXT.1.1|9=000150|35=CO|49=EXCHANGE|56=CLIENT|34=2575|57=SESSION1|52=20260630-07:45:18.190385153|324=1000000000000000001|1301=EXMKT|146=1|55=SYM00003|48=100000003|22=M|10=004|
8=FIXT.1.1|9=76|35=0|34=65|49=CLIENT|56=EXCHANGE|52=20260630-07:44:57.224079285|50=SESSION1|10=160|
8=FIXT.1.1|9=000078|35=0|49=EXCHANGE|56=CLIENT|34=2574|57=SESSION1|52=20260630-07:44:57.002221311|10=181|
8=FIXT.1.1|9=000169|35=CO|49=EXCHANGE|56=CLIENT|34=2573|57=SESSION1|52=20260630-07:44:27.018405655|324=1000000000000000001|1301=EXMKT|625=INTERMISSION_D|146=1|55=SYM00004|48=100000004|22=M|10=046|
8=FIXT.1.1|9=000169|35=CO|49=EXCHANGE|56=CLIENT|34=2572|57=SESSION1|52=20260630-07:44:27.018529818|324=1000000000000000001|1301=EXMKT|625=INTERMISSION_D|146=1|55=SYM00005|48=100000005|22=M|10=055|
8=FIXT.1.1|9=000169|35=CO|49=EXCHANGE|56=CLIENT|34=2571|57=SESSION1|52=20260630-07:44:27.018751064|324=1000000000000000001|1301=EXMKT|625=INTERMISSION_D|146=1|55=SYM00006|48=100000006|22=M|10=046|
8=FIXT.1.1|9=000169|35=CO|49=EXCHANGE|56=CLIENT|34=2570|57=SESSION1|52=20260630-07:44:27.018929162|324=1000000000000000001|1301=EXMKT|625=INTERMISSION_D|146=1|55=SYM00007|48=100000007|22=M|10=053|
8=FIXT.1.1|9=000169|35=CO|49=EXCHANGE|56=CLIENT|34=2569|57=SESSION1|52=20260630-07:44:27.018963669|324=1000000000000000001|1301=EXMKT|625=INTERMISSION_D|146=1|55=SYM00008|48=100000008|22=M|10=073|
8=FIXT.1.1|9=000169|35=CO|49=EXCHANGE|56=CLIENT|34=2568|57=SESSION1|52=20260630-07:44:27.018298121|324=1000000000000000001|1301=EXMKT|625=INTERMISSION_D|146=1|55=SYM00009|48=100000009|22=M|10=058|
8=FIXT.1.1|9=000169|35=CO|49=EXCHANGE|56=CLIENT|34=2567|57=SESSION1|52=20260630-07:44:27.017403265|324=1000000000000000001|1301=EXMKT|625=INTERMISSION_D|146=1|55=SYM00010|48=100000010|22=M|10=037|
8=FIXT.1.1|9=000169|35=CO|49=EXCHANGE|56=CLIENT|34=2566|57=SESSION1|52=20260630-07:44:27.017668758|324=1000000000000000001|1301=EXMKT|625=INTERMISSION_D|146=1|55=SYM00011|48=100000011|22=M|10=058|
8=FIXT.1.1|9=000169|35=CO|49=EXCHANGE|56=CLIENT|34=2565|57=SESSION1|52=20260630-07:44:27.017974519|324=1000000000000000001|1301=EXMKT|625=INTERMISSION_D|146=1|55=SYM00012|48=100000012|22=M|10=054|
8=FIXT.1.1|9=000169|35=CO|49=EXCHANGE|56=CLIENT|34=2564|57=SESSION1|52=20260630-07:44:27.017961743|324=1000000000000000001|1301=EXMKT|625=INTERMISSION_D|146=1|55=SYM00013|48=100000013|22=M|10=050|
8=FIXT.1.1|9=000169|35=CO|49=EXCHANGE|56=CLIENT|34=2563|57=SESSION1|52=20260630-07:44:27.016546179|324=1000000000000000001|1301=EXMKT|625=INTERMISSION_D|146=1|55=SYM00014|48=100000014|22=M|10=052|
8=FIXT.1.1|9=000169|35=CO|49=EXCHANGE|56=CLIENT|34=2562|57=SESSION1|52=20260630-07:44:27.016100221|324=1000000000000000001|1301=EXMKT|625=INTERMISSION_D|146=1|55=SYM00015|48=100000015|22=M|10=027|
8=FIXT.1.1|9=000143|35=CO|49=EXCHANGE|56=CLIENT|34=2561|57=SESSION1|52=20260630-07:44:27.016609747|324=1000000000000000001|1301=EXMKT|1300=SEG1|625=INTERMISSION_D|10=078|
8=FIXT.1.1|9=000169|35=CO|49=EXCHANGE|56=CLIENT|34=2560|57=SESSION1|52=20260630-07:44:27.015289736|324=1000000000000000001|1301=EXMKT|625=INTERMISSION_D|146=1|55=SYM00016|48=100000016|22=M|10=055|
8=FIXT.1.1|9=000169|35=CO|49=EXCHANGE|56=CLIENT|34=2559|57=SESSION1|52=20260630-07:44:27.015961990|324=1000000000000000001|1301=EXMKT|625=INTERMISSION_D|146=1|55=SYM00017|48=100000017|22=M|10=064|
8=FIXT.1.1|9=000143|35=CO|49=EXCHANGE|56=CLIENT|34=2558|57=SESSION1|52=20260630-07:44:27.014270696|324=1000000000000000001|1301=EXMKT|1300=SEG2|625=INTERMISSION_D|10=080|
8=FIXT.1.1|9=000143|35=CO|49=EXCHANGE|56=CLIENT|34=2557|57=SESSION1|52=20260630-07:44:27.014582613|324=1000000000000000001|1301=EXMKT|1300=SEG3|625=INTERMISSION_D|10=075|
8=FIXT.1.1|9=000143|35=CO|49=EXCHANGE|56=CLIENT|34=2556|57=SESSION1|52=20260630-07:44:27.013410355|324=1000000000000000001|1301=EXMKT|1300=SEG4|625=INTERMISSION_D|10=067|
8=FIXT.1.1|9=000175|35=CO|49=EXCHANGE|56=CLIENT|34=2555|57=SESSION1|52=20260630-07:44:27.013906143|324=1000000000000000001|1301=EXMKT|625=INTERMISSION_E|146=1|55=SYM00018|48=100000018|22=M|292=c|10=109|
8=FIXT.1.1|9=000143|35=CO|49=EXCHANGE|56=CLIENT|34=2554|57=SESSION1|52=20260630-07:44:27.012690874|324=1000000000000000001|1301=EXMKT|1300=SEG5|625=INTERMISSION_E|10=082|
8=FIXT.1.1|9=76|35=0|34=64|49=CLIENT|56=EXCHANGE|52=20260630-07:44:25.040466567|50=SESSION1|10=153|
8=FIXT.1.1|9=000078|35=0|49=EXCHANGE|56=CLIENT|34=2553|57=SESSION1|52=20260630-07:44:24.817565473|10=206|
8=FIXT.1.1|9=117|35=0|34=63|49=CLIENT|56=EXCHANGE|52=20260630-07:43:55.039743670|50=SESSION1|112=00000000-0000-0000-0000-000000000015|10=083|
8=FIXT.1.1|9=000119|35=1|49=EXCHANGE|56=CLIENT|34=2552|57=SESSION1|52=20260630-07:43:54.817838859|112=00000000-0000-0000-0000-000000000015|10=099|
8=FIXT.1.1|9=000164|35=X|49=EXCHANGE|56=CLIENT|34=2551|57=SESSION1|52=20260630-07:43:27.078399712|1021=2|262=1000000000000000002|268=1|279=2|269=1|55=SYM00019|48=100000019|22=M|1023=1|10=230|
8=FIXT.1.1|9=000351|35=X|49=EXCHANGE|56=CLIENT|34=2550|57=SESSION1|52=20260630-07:43:27.078219094|1021=2|262=1000000000000000002|268=4|279=2|269=0|55=SYM00020|48=100000020|22=M|1023=1|279=0|269=0|55=SYM00020|48=100000020|22=M|270=302.26352|271=2|1023=5|279=2|269=1|55=SYM00020|48=100000020|22=M|1023=1|279=0|269=1|55=SYM00020|48=100000020|22=M|270=390.34125|271=1|1023=5|10=195|
8=FIXT.1.1|9=000213|35=X|49=EXCHANGE|56=CLIENT|34=2549|57=SESSION1|52=20260630-07:43:27.078928393|1021=2|262=1000000000000000002|268=2|279=2|269=0|55=SYM00021|48=100000021|22=M|1023=1|279=2|269=1|55=SYM00021|48=100000021|22=M|1023=1|10=021|
8=FIXT.1.1|9=000164|35=X|49=EXCHANGE|56=CLIENT|34=2548|57=SESSION1|52=20260630-07:43:27.078616200|1021=2|262=1000000000000000002|268=1|279=2|269=1|55=SYM00022|48=100000022|22=M|1023=1|10=208|
8=FIXT.1.1|9=000164|35=X|49=EXCHANGE|56=CLIENT|34=2547|57=SESSION1|52=20260630-07:43:27.078767839|1021=2|262=1000000000000000002|268=1|279=2|269=0|55=SYM00023|48=100000023|22=M|1023=1|10=233|
8=FIXT.1.1|9=000213|35=X|49=EXCHANGE|56=CLIENT|34=2546|57=SESSION1|52=20260630-07:43:27.078795822|1021=2|262=1000000000000000002|268=2|279=2|269=0|55=SYM00001|48=100000001|22=M|1023=1|279=2|269=1|55=SYM00001|48=100000001|22=M|1023=1|10=009|
8=FIXT.1.1|9=000164|35=X|49=EXCHANGE|56=CLIENT|34=2545|57=SESSION1|52=20260630-07:43:27.078494304|1021=2|262=1000000000000000002|268=1|279=2|269=0|55=SYM00024|48=100000024|22=M|1023=1|10=217|
8=FIXT.1.1|9=000164|35=X|49=EXCHANGE|56=CLIENT|34=2544|57=SESSION1|52=20260630-07:43:27.078686466|1021=2|262=1000000000000000002|268=1|279=2|269=1|55=SYM00025|48=100000025|22=M|1023=1|10=231|
8=FIXT.1.1|9=000164|35=X|49=EXCHANGE|56=CLIENT|34=2543|57=SESSION1|52=20260630-07:43:27.078922145|1021=2|262=1000000000000000002|268=1|279=2|269=0|55=SYM00026|48=100000026|22=M|1023=1|10=218|
8=FIXT.1.1|9=000164|35=X|49=EXCHANGE|56=CLIENT|34=2542|57=SESSION1|52=20260630-07:43:27.078022642|1021=2|262=1000000000000000002|268=1|279=2|269=0|55=SYM00027|48=100000027|22=M|1023=1|10=212|
8=FIXT.1.1|9=000164|35=X|49=EXCHANGE|56=CLIENT|34=2541|57=SESSION1|52=20260630-07:43:27.078198974|1021=2|262=1000000000000000002|268=1|279=2|269=1|55=SYM00028|48=100000028|22=M|1023=1|10=236|
8=FIXT.1.1|9=000164|35=X|49=EXCHANGE|56=CLIENT|34=2540|57=SESSION1|52=20260630-07:43:27.078504087|1021=2|262=1000000000000000002|268=1|279=2|269=0|55=SYM00029|48=100000029|22=M|1023=1|10=222|
8=FIXT.1.1|9=000164|35=X|49=EXCHANGE|56=CLIENT|34=2539|57=SESSION1|52=20260630-07:43:27.078669333|1021=2|262=1000000000000000002|268=1|279=2|269=1|55=SYM00030|48=100000030|22=M|1023=1|10=221|
8=FIXT.1.1|9=000213|35=X|49=EXCHANGE|56=CLIENT|34=2538|57=SESSION1|52=20260630-07:43:27.078154722|1021=2|262=1000000000000000002|268=2|279=2|269=0|55=SYM00031|48=100000031|22=M|1023=1|279=2|269=1|55=SYM00031|48=100000031|22=M|1023=1|10=010|
8=FIXT.1.1|9=000164|35=X|49=EXCHANGE|56=CLIENT|34=2537|57=SESSION1|52=20260630-07:43:27.078624619|1021=2|262=1000000000000000002|268=1|279=2|269=1|55=SYM00032|48=100000032|22=M|1023=1|10=221|
8=FIXT.1.1|9=000164|35=X|49=EXCHANGE|56=CLIENT|34=2536|57=SESSION1|52=20260630-07:43:27.078269173|1021=2|262=1000000000000000002|268=1|279=2|269=0|55=SYM00033|48=100000033|22=M|1023=1|10=221|
8=FIXT.1.1|9=000164|35=X|49=EXCHANGE|56=CLIENT|34=2535|57=SESSION1|52=20260630-07:43:27.078929568|1021=2|262=1000000000000000002|268=1|279=2|269=0|55=SYM00034|48=100000034|22=M|1023=1|10=233|
8=FIXT.1.1|9=000164|35=X|49=EXCHANGE|56=CLIENT|34=2534|57=SESSION1|52=20260630-07:43:27.078090636|1021=2|262=1000000000000000002|268=1|279=2|269=1|55=SYM00035|48=100000035|22=M|1023=1|10=220|
8=FIXT.1.1|9=000164|35=X|49=EXCHANGE|56=CLIENT|34=2533|57=SESSION1|52=20260630-07:43:27.078299974|1021=2|262=1000000000000000002|268=1|279=2|269=0|55=SYM00036|48=100000036|22=M|1023=1|10=236|
8=FIXT.1.1|9=000164|35=X|49=EXCHANGE|56=CLIENT|34=2532|57=SESSION1|52=20260630-07:43:27.078581145|1021=2|262=1000000000000000002|268=1|279=2|269=0|55=SYM00037|48=100000037|22=M|1023=1|10=221|
8=FIXT.1.1|9=000164|35=X|49=EXCHANGE|56=CLIENT|34=2531|57=SESSION1|52=20260630-07:43:27.078582037|1021=2|262=1000000000000000002|268=1|279=2|269=0|55=SYM00038|48=100000038|22=M|1023=1|10=223|
8=FIXT.1.1|9=000213|35=X|49=EXCHANGE|56=CLIENT|34=2530|57=SESSION1|52=20260630-07:43:27.078010618|1021=2|262=1000000000000000002|268=2|279=2|269=0|55=SYM00039|48=100000039|22=M|1023=1|279=2|269=1|55=SYM00039|48=100000039|22=M|1023=1|10=029|
8=FIXT.1.1|9=000164|35=X|49=EXCHANGE|56=CLIENT|34=2529|57=SESSION1|52=20260630-07:43:27.078347036|1021=2|262=1000000000000000002|268=1|279=2|269=0|55=SYM00040|48=100000040|22=M|1023=1|10=214|
8=FIXT.1.1|9=000668|35=X|49=EXCHANGE|56=CLIENT|34=2528|57=SESSION1|52=20260630-07:43:27.078753184|1021=2|262=1000000000000000002|268=9|279=2|269=0|55=SYM00002|48=100000002|22=M|1023=1|279=2|269=0|55=SYM00002|48=100000002|22=M|1023=1|279=2|269=0|55=SYM00002|48=100000002|22=M|1023=1|279=2|269=0|55=SYM00002|48=100000002|22=M|1023=1|279=0|269=0|55=SYM00002|48=100000002|22=M|270=53.62200|271=1200|1023=7|279=0|269=0|55=SYM00002|48=100000002|22=M|270=52.46820|271=400|1023=8|279=0|269=0|55=SYM00002|48=100000002|22=M|270=50.39310|271=1000|1023=9|279=0|269=0|55=SYM00002|48=100000002|22=M|270=51.93755|271=1400|1023=10|279=1|269=1|55=SYM00002|48=100000002|22=M|270=61.75225|271=142200|1023=1|10=052|
8=FIXT.1.1|9=000164|35=X|49=EXCHANGE|56=CLIENT|34=2527|57=SESSION1|52=20260630-07:43:27.078204686|1021=2|262=1000000000000000002|268=1|279=2|269=1|55=SYM00041|48=100000041|22=M|1023=1|10=218|
8=FIXT.1.1|9=000164|35=X|49=EXCHANGE|56=CLIENT|34=2526|57=SESSION1|52=20260630-07:43:27.078124294|1021=2|262=1000000000000000002|268=1|279=2|269=1|55=SYM00042|48=100000042|22=M|1023=1|10=215|
8=FIXT.1.1|9=000164|35=X|49=EXCHANGE|56=CLIENT|34=2525|57=SESSION1|52=20260630-07:43:27.078007390|1021=2|262=1000000000000000002|268=1|279=2|269=0|55=SYM00043|48=100000043|22=M|1023=1|10=212|
8=FIXT.1.1|9=000164|35=X|49=EXCHANGE|56=CLIENT|34=2524|57=SESSION1|52=20260630-07:43:27.078654848|1021=2|262=1000000000000000002|268=1|279=2|269=1|55=SYM00044|48=100000044|22=M|1023=1|10=230|
8=FIXT.1.1|9=000164|35=X|49=EXCHANGE|56=CLIENT|34=2523|57=SESSION1|52=20260630-07:43:27.078178672|1021=2|262=1000000000000000002|268=1|279=2|269=0|55=SYM00045|48=100000045|22=M|1023=1|10=226|
8=FIXT.1.1|9=000164|35=X|49=EXCHANGE|56=CLIENT|34=2522|57=SESSION1|52=20260630-07:43:27.078227482|1021=2|262=1000000000000000002|268=1|279=2|269=0|55=SYM00046|48=100000046|22=M|1023=1|10=221|
8=FIXT.1.1|9=000164|35=X|49=EXCHANGE|56=CLIENT|34=2521|57=SESSION1|52=20260630-07:43:27.072956702|1021=2|262=1000000000000000002|268=1|279=2|269=1|55=SYM00047|48=100000047|22=M|1023=1|10=221|
8=FIXT.1.1|9=000164|35=X|49=EXCHANGE|56=CLIENT|34=2520|57=SESSION1|52=20260630-07:43:27.072733443|1021=2|262=1000000000000000002|268=1|279=2|269=0|55=SYM00048|48=100000048|22=M|1023=1|10=216|
8=FIXT.1.1|9=000164|35=X|49=EXCHANGE|56=CLIENT|34=2519|57=SESSION1|52=20260630-07:43:27.072624667|1021=2|262=1000000000000000002|268=1|279=2|269=0|55=SYM00049|48=100000049|22=M|1023=1|10=233|
8=FIXT.1.1|9=000164|35=X|49=EXCHANGE|56=CLIENT|34=2518|57=SESSION1|52=20260630-07:43:27.072438923|1021=2|262=1000000000000000002|268=1|279=2|269=0|55=SYM00050|48=100000050|22=M|1023=1|10=214|
8=FIXT.1.1|9=000164|35=X|49=EXCHANGE|56=CLIENT|34=2517|57=SESSION1|52=20260630-07:43:27.072955244|1021=2|262=1000000000000000002|268=1|279=2|269=1|55=SYM00051|48=100000051|22=M|1023=1|10=216|
8=FIXT.1.1|9=000164|35=X|49=EXCHANGE|56=CLIENT|34=2516|57=SESSION1|52=20260630-07:43:27.072374808|1021=2|262=1000000000000000002|268=1|279=2|269=0|55=SYM00052|48=100000052|22=M|1023=1|10=217|
8=FIXT.1.1|9=000164|35=X|49=EXCHANGE|56=CLIENT|34=2515|57=SESSION1|52=20260630-07:43:27.072818920|1021=2|262=1000000000000000002|268=1|279=2|269=1|55=SYM00053|48=100000053|22=M|1023=1|10=217|
8=FIXT.1.1|9=000164|35=X|49=EXCHANGE|56=CLIENT|34=2514|57=SESSION1|52=20260630-07:43:27.072042768|1021=2|262=1000000000000000002|268=1|279=2|269=0|55=SYM00054|48=100000054|22=M|1023=1|10=216|
8=FIXT.1.1|9=000164|35=X|49=EXCHANGE|56=CLIENT|34=2513|57=SESSION1|52=20260630-07:43:27.072604705|1021=2|262=1000000000000000002|268=1|279=2|269=0|55=SYM00055|48=100000055|22=M|1023=1|10=212|
8=FIXT.1.1|9=000164|35=X|49=EXCHANGE|56=CLIENT|34=2512|57=SESSION1|52=20260630-07:43:27.072039006|1021=2|262=1000000000000000002|268=1|279=2|269=1|55=SYM00056|48=100000056|22=M|1023=1|10=210|
8=FIXT.1.1|9=000164|35=X|49=EXCHANGE|56=CLIENT|34=2511|57=SESSION1|52=20260630-07:43:27.071010314|1021=2|262=1000000000000000002|268=1|279=2|269=0|55=SYM00057|48=100000057|22=M|1023=1|10=200|
8=FIXT.1.1|9=000164|35=X|49=EXCHANGE|56=CLIENT|34=2510|57=SESSION1|52=20260630-07:43:27.071434355|1021=2|262=1000000000000000002|268=1|279=2|269=0|55=SYM00058|48=100000058|22=M|1023=1|10=216|
8=FIXT.1.1|9=000164|35=X|49=EXCHANGE|56=CLIENT|34=2509|57=SESSION1|52=20260630-07:43:27.071062129|1021=2|262=1000000000000000002|268=1|279=2|269=1|55=SYM00059|48=100000059|22=M|1023=1|10=223|
8=FIXT.1.1|9=000164|35=X|49=EXCHANGE|56=CLIENT|34=2508|57=SESSION1|52=20260630-07:43:27.071979160|1021=2|262=1000000000000000002|268=1|279=2|269=0|55=SYM00060|48=100000060|22=M|1023=1|10=217|
8=FIXT.1.1|9=000164|35=X|49=EXCHANGE|56=CLIENT|34=2507|57=SESSION1|52=20260630-07:43:27.071279240|1021=2|262=1000000000000000002|268=1|279=2|269=0|55=SYM00061|48=100000061|22=M|1023=1|10=210|
8=FIXT.1.1|9=000164|35=X|49=EXCHANGE|56=CLIENT|34=2506|57=SESSION1|52=20260630-07:43:27.071532074|1021=2|262=1000000000000000002|268=1|279=2|269=1|55=SYM00062|48=100000062|22=M|1023=1|10=209|
8=FIXT.1.1|9=000235|35=X|49=EXCHANGE|56=CLIENT|34=2505|57=SESSION1|52=20260630-07:43:27.071761837|1021=2|262=1000000000000000002|268=2|279=1|269=0|55=SYM00003|48=100000003|22=M|270=15.67179|271=1500|1023=1|279=2|269=1|55=SYM00003|48=100000003|22=M|1023=1|10=030|
8=FIXT.1.1|9=000164|35=X|49=EXCHANGE|56=CLIENT|34=2504|57=SESSION1|52=20260630-07:43:27.071744510|1021=2|262=1000000000000000002|268=1|279=2|269=0|55=SYM00063|48=100000063|22=M|1023=1|10=208|
8=FIXT.1.1|9=000164|35=X|49=EXCHANGE|56=CLIENT|34=2503|57=SESSION1|52=20260630-07:43:27.071210661|1021=2|262=1000000000000000002|268=1|279=2|269=0|55=SYM00064|48=100000064|22=M|1023=1|10=204|
8=FIXT.1.1|9=000164|35=X|49=EXCHANGE|56=CLIENT|34=2502|57=SESSION1|52=20260630-07:43:27.071342189|1021=2|262=1000000000000000002|268=1|279=2|269=1|55=SYM00065|48=100000065|22=M|1023=1|10=217|
8=FIXT.1.1|9=000164|35=X|49=EXCHANGE|56=CLIENT|34=2501|57=SESSION1|52=20260630-07:43:27.071511824|1021=2|262=1000000000000000002|268=1|279=2|269=0|55=SYM00066|48=100000066|22=M|1023=1|10=211|
8=FIXT.1.1|9=000164|35=X|49=EXCHANGE|56=CLIENT|34=2500|57=SESSION1|52=20260630-07:43:27.071808449|1021=2|262=1000000000000000002|268=1|279=2|269=0|55=SYM00067|48=100000067|22=M|1023=1|10=224|
8=FIXT.1.1|9=000164|35=X|49=EXCHANGE|56=CLIENT|34=2499|57=SESSION1|52=20260630-07:43:27.071113214|1021=2|262=1000000000000000002|268=1|279=2|269=1|55=SYM00068|48=100000068|22=M|1023=1|10=223|
8=FIXT.1.1|9=000229|35=X|49=EXCHANGE|56=CLIENT|34=2498|57=SESSION1|52=20260630-07:43:27.052869686|262=1000000000000000002|268=1|279=0|269=2|278=0000000000000001|55=SYM00001|48=100000001|22=M|270=4.13904|271=300|273=05:30:00.001953639|574=5|7554=596|10=065|
8=FIXT.1.1|9=000231|35=X|49=EXCHANGE|56=CLIENT|34=2497|57=SESSION1|52=20260630-07:43:27.052831382|262=1000000000000000002|268=1|279=0|269=2|278=0000000000000002|55=SYM00002|48=100000002|22=M|270=61.75225|271=2700|273=05:30:00.001953639|574=5|7554=595|10=150|
8=FIXT.1.1|9=000230|35=X|49=EXCHANGE|56=CLIENT|34=2496|57=SESSION1|52=20260630-07:43:27.051401293|262=1000000000000000002|268=1|279=0|269=2|278=0000000000000003|55=SYM00003|48=100000003|22=M|270=15.67179|271=500|273=05:30:00.001953639|574=5|7554=594|10=099|
8=FIXT.1.1|9=000360|35=X|49=EXCHANGE|56=CLIENT|34=2495|57=SESSION1|52=20260630-07:43:27.051195139|1021=2|262=1000000000000000002|268=5|279=2|269=1|55=SYM00069|48=100000069|22=M|1023=1|279=2|269=1|55=SYM00069|48=100000069|22=M|1023=1|279=2|269=1|55=SYM00069|48=100000069|22=M|1023=1|279=2|269=1|55=SYM00069|48=100000069|22=M|1023=1|279=2|269=1|55=SYM00069|48=100000069|22=M|1023=1|10=045|
8=FIXT.1.1|9=000187|35=X|49=EXCHANGE|56=CLIENT|34=2494|57=SESSION1|52=20260630-07:43:27.051260040|1021=2|262=1000000000000000002|268=1|279=1|269=0|55=SYM00070|48=100000070|22=M|270=1032.55212|271=497|1023=1|10=019|
8=FIXT.1.1|9=000187|35=X|49=EXCHANGE|56=CLIENT|34=2493|57=SESSION1|52=20260630-07:43:27.051260324|1021=2|262=1000000000000000002|268=1|279=1|269=1|55=SYM00071|48=100000071|22=M|270=1014.35002|271=499|1023=1|10=023|
8=FIXT.1.1|9=000781|35=X|49=EXCHANGE|56=CLIENT|34=2492|57=SESSION1|52=20260630-07:43:27.051662165|1021=2|262=1000000000000000002|268=11|279=1|269=0|55=SYM00072|48=100000072|22=M|270=1034.04688|271=1|1023=1|279=1|269=0|55=SYM00072|48=100000072|22=M|270=1031.26111|271=5|1023=2|279=1|269=0|55=SYM00072|48=100000072|22=M|270=1003.60288|271=5|1023=3|279=1|269=0|55=SYM00072|48=100000072|22=M|270=987.08460|271=25|1023=4|279=1|269=0|55=SYM00072|48=100000072|22=M|270=981.21611|271=10|1023=5|279=2|269=1|55=SYM00072|48=100000072|22=M|1023=1|279=2|269=1|55=SYM00072|48=100000072|22=M|1023=1|279=2|269=1|55=SYM00072|48=100000072|22=M|1023=1|279=2|269=1|55=SYM00072|48=100000072|22=M|1023=1|279=2|269=1|55=SYM00072|48=100000072|22=M|1023=1|279=0|269=1|55=SYM00072|48=100000072|22=M|270=1088.23000|271=5|1023=1|10=231|
8=FIXT.1.1|9=000468|35=X|49=EXCHANGE|56=CLIENT|34=2491|57=SESSION1|52=20260630-07:43:27.051535607|1021=2|262=1000000000000000002|268=6|279=2|269=0|55=SYM00073|48=100000073|22=M|1023=1|279=0|269=0|55=SYM00073|48=100000073|22=M|270=32.42458|271=7|1023=5|279=2|269=1|55=SYM00073|48=100000073|22=M|1023=1|279=2|269=1|55=SYM00073|48=100000073|22=M|1023=1|279=0|269=1|55=SYM00073|48=100000073|22=M|270=31.94018|271=10|1023=1|279=0|269=1|55=SYM00073|48=100000073|22=M|270=32.99600|271=10|1023=5|10=024|
8=FIXT.1.1|9=000330|35=X|49=EXCHANGE|56=CLIENT|34=2490|57=SESSION1|52=20260630-07:43:27.050550440|1021=2|262=1000000000000000002|268=4|279=2|269=0|55=SYM00074|48=100000074|22=M|1023=1|279=2|269=0|55=SYM00074|48=100000074|22=M|1023=1|279=2|269=1|55=SYM00074|48=100000074|22=M|1023=1|279=0|269=1|55=SYM00074|48=100000074|22=M|270=33.03630|271=4|1023=5|10=028|
8=FIXT.1.1|9=000142|35=CO|49=EXCHANGE|56=CLIENT|34=2489|57=SESSION1|52=20260630-07:43:27.014905605|324=1000000000000000001|1301=EXMKT|1300=SEG1|625=TRANSITION1_D|10=227|
8=FIXT.1.1|9=000569|35=CO|49=EXCHANGE|56=CLIENT|34=2488|57=SESSION1|52=20260630-07:43:27.012722384|324=1000000000000000001|1301=EXMKT|1300=SEG2|625=TRANSITION1_D|146=14|55=SYM00017|48=100000017|22=M|55=SYM00013|48=100000013|22=M|55=SYM00016|48=100000016|22=M|55=SYM00007|48=100000007|22=M|55=SYM00014|48=100000014|22=M|55=SYM00005|48=100000005|22=M|55=SYM00009|48=100000009|22=M|55=SYM00010|48=100000010|22=M|55=SYM00004|48=100000004|22=M|55=SYM00008|48=100000008|22=M|55=SYM00006|48=100000006|22=M|55=SYM00012|48=100000012|22=M|55=SYM00011|48=100000011|22=M|55=SYM00015|48=100000015|22=M|10=189|
8=FIXT.1.1|9=000169|35=CO|49=EXCHANGE|56=CLIENT|34=2487|57=SESSION1|52=20260630-07:43:27.012301445|324=1000000000000000001|1301=EXMKT|625=INTERMISSION_I|146=1|55=SYM00075|48=100000075|22=M|10=056|
8=FIXT.1.1|9=000169|35=CO|49=EXCHANGE|56=CLIENT|34=2486|57=SESSION1|52=20260630-07:43:27.011060781|324=1000000000000000001|1301=EXMKT|625=INTERMISSION_I|146=1|55=SYM00076|48=100000076|22=M|10=061|
8=FIXT.1.1|9=000169|35=CO|49=EXCHANGE|56=CLIENT|34=2485|57=SESSION1|52=20260630-07:43:27.011459495|324=1000000000000000001|1301=EXMKT|625=INTERMISSION_I|146=1|55=SYM00077|48=100000077|22=M|10=076|
8=FIXT.1.1|9=000169|35=CO|49=EXCHANGE|56=CLIENT|34=2484|57=SESSION1|52=20260630-07:43:27.011039025|324=1000000000000000001|1301=EXMKT|625=INTERMISSION_I|146=1|55=SYM00078|48=100000078|22=M|10=060|
8=FIXT.1.1|9=000169|35=CO|49=EXCHANGE|56=CLIENT|34=2483|57=SESSION1|52=20260630-07:43:27.011882900|324=1000000000000000001|1301=EXMKT|625=INTERMISSION_I|146=1|55=SYM00079|48=100000079|22=M|10=069|
8=FIXT.1.1|9=000169|35=CO|49=EXCHANGE|56=CLIENT|34=2482|57=SESSION1|52=20260630-07:43:27.011692409|324=1000000000000000001|1301=EXMKT|625=INTERMISSION_I|146=1|55=SYM00080|48=100000080|22=M|10=055|
8=FIXT.1.1|9=000142|35=CO|49=EXCHANGE|56=CLIENT|34=2481|57=SESSION1|52=20260630-07:43:27.011999694|324=1000000000000000001|1301=EXMKT|1300=SEG3|625=TRANSITION1_D|10=239|
8=FIXT.1.1|9=000142|35=CO|49=EXCHANGE|56=CLIENT|34=2480|57=SESSION1|52=20260630-07:43:27.011752337|324=1000000000000000001|1301=EXMKT|1300=SEG4|625=TRANSITION1_D|10=220|
8=FIXT.1.1|9=000174|35=CO|49=EXCHANGE|56=CLIENT|34=2479|57=SESSION1|52=20260630-07:43:27.010003399|324=1000000000000000001|1301=EXMKT|625=TRANSITION1_E|146=1|55=SYM00001|48=100000001|22=M|292=o|10=002|
8=FIXT.1.1|9=000174|35=CO|49=EXCHANGE|56=CLIENT|34=2478|57=SESSION1|52=20260630-07:43:27.010637458|324=1000000000000000001|1301=EXMKT|625=TRANSITION1_E|146=1|55=SYM00003|48=100000003|22=M|292=o|10=014|
8=FIXT.1.1|9=000174|35=CO|49=EXCHANGE|56=CLIENT|34=2477|57=SESSION1|52=20260630-07:43:27.010745806|324=1000000000000000001|1301=EXMKT|625=TRANSITION1_E|146=1|55=SYM00002|48=100000002|22=M|292=o|10=008|
8=FIXT.1.1|9=000178|35=CO|49=EXCHANGE|56=CLIENT|34=2476|57=SESSION1|52=20260630-07:43:27.010023238|324=1000000000000000001|1301=EXMKT|1300=SEG5|625=TRANSITION1_E|146=1|55=SYM00018|48=100000018|22=M|10=217|
8=FIXT.1.1|9=000184|35=X|49=EXCHANGE|56=CLIENT|34=2475|57=SESSION1|52=20260630-07:43:26.965130199|1021=2|262=1000000000000000002|268=1|279=0|269=0|55=SYM00001|48=100000001|22=M|270=4.26442|271=300|1023=2|10=123|
8=FIXT.1.1|9=000184|35=X|49=EXCHANGE|56=CLIENT|34=2474|57=SESSION1|52=20260630-07:43:26.944331445|1021=2|262=1000000000000000002|268=1|279=0|269=0|55=SYM00001|48=100000001|22=M|270=4.08702|271=300|1023=1|10=114|
8=FIXT.1.1|9=000167|35=CO|49=EXCHANGE|56=CLIENT|34=2473|57=SESSION1|52=20260630-07:43:26.926602002|324=1000000000000000001|1301=EXMKT|146=1|55=SYM00001|48=100000001|22=M|58=PRE-OPEN_CB_E|10=115|
8=FIXT.1.1|9=000174|35=CO|49=EXCHANGE|56=CLIENT|34=2472|57=SESSION1|52=20260630-07:43:26.925052195|324=1000000000000000001|1301=EXMKT|625=PRE-OPEN_CB_E|146=1|55=SYM00001|48=100000001|22=M|292=o|10=245|
8=FIXT.1.1|9=000184|35=X|49=EXCHANGE|56=CLIENT|34=2471|57=SESSION1|52=20260630-07:43:26.778076923|1021=2|262=1000000000000000002|268=1|279=0|269=0|55=SYM00001|48=100000001|22=M|270=4.17974|271=300|1023=1|10=134|
8=FIXT.1.1|9=000184|35=X|49=EXCHANGE|56=CLIENT|34=2470|57=SESSION1|52=20260630-07:43:26.756761287|1021=2|262=1000000000000000002|268=1|279=0|269=1|55=SYM00001|48=100000001|22=M|270=4.28300|271=300|1023=5|10=123|
8=FIXT.1.1|9=000184|35=X|49=EXCHANGE|56=CLIENT|34=2469|57=SESSION1|52=20260630-07:43:26.736197713|1021=2|262=1000000000000000002|268=1|279=0|269=1|55=SYM00001|48=100000001|22=M|270=4.35074|271=300|1023=5|10=132|
8=FIXT.1.1|9=000184|35=X|49=EXCHANGE|56=CLIENT|34=2468|57=SESSION1|52=20260630-07:43:26.715913376|1021=2|262=1000000000000000002|268=1|279=0|269=1|55=SYM00001|48=100000001|22=M|270=4.26341|271=300|1023=4|10=125|
8=FIXT.1.1|9=000184|35=X|49=EXCHANGE|56=CLIENT|34=2467|57=SESSION1|52=20260630-07:43:26.694961022|1021=2|262=1000000000000000002|268=1|279=0|269=1|55=SYM00001|48=100000001|22=M|270=4.13358|271=300|1023=3|10=124|
8=FIXT.1.1|9=000184|35=X|49=EXCHANGE|56=CLIENT|34=2466|57=SESSION1|52=20260630-07:43:26.674945094|1021=2|262=1000000000000000002|268=1|279=0|269=1|55=SYM00001|48=100000001|22=M|270=4.13904|271=300|1023=1|10=127|
8=FIXT.1.1|9=000282|35=X|49=EXCHANGE|56=CLIENT|34=2465|57=SESSION1|52=20260630-07:43:26.608439828|1021=2|262=1000000000000000002|268=3|279=1|264=10|269=0|55=SYM00001|48=100000001|22=M|279=1|264=10|269=1|55=SYM00001|48=100000001|22=M|279=0|269=1|55=SYM00001|48=100000001|22=M|270=4.08702|271=300|1023=1|10=240|
8=FIXT.1.1|9=000283|35=X|49=EXCHANGE|56=CLIENT|34=2464|57=SESSION1|52=20260630-07:43:25.520613306|1021=2|262=1000000000000000002|268=3|279=1|264=10|269=0|55=SYM00081|48=100000081|22=M|279=1|264=10|269=1|55=SYM00081|48=100000081|22=M|279=0|269=1|55=SYM00081|48=100000081|22=M|270=47.02898|271=300|1023=1|10=074|
8=FIXT.1.1|9=000185|35=X|49=EXCHANGE|56=CLIENT|34=2463|57=SESSION1|52=20260630-07:43:25.344555524|1021=2|262=1000000000000000002|268=1|279=0|269=0|55=SYM00082|48=100000082|22=M|270=17.56080|271=300|1023=2|10=185|
8=FIXT.1.1|9=000185|35=X|49=EXCHANGE|56=CLIENT|34=2462|57=SESSION1|52=20260630-07:43:25.236476941|1021=2|262=1000000000000000002|268=1|279=0|269=0|55=SYM00082|48=100000082|22=M|270=17.23096|271=300|1023=3|10=191|
8=FIXT.1.1|9=000237|35=X|49=EXCHANGE|56=CLIENT|34=2461|57=SESSION1|52=20260630-07:43:24.404148149|262=1000000000000000002|268=1|279=0|269=2|278=0000000000000004|55=SYM00083|48=100000083|22=M|270=6.05058|271=1500|273=05:29:57.404431520|574=4|2446=2|7554=589|10=185|
8=FIXT.1.1|9=000236|35=X|49=EXCHANGE|56=CLIENT|34=2460|57=SESSION1|52=20260630-07:43:24.404042404|262=1000000000000000002|268=1|279=0|269=2|278=0000000000000005|55=SYM00083|48=100000083|22=M|270=6.40250|271=400|273=05:29:57.404431520|574=4|2446=2|7554=588|10=113|
8=FIXT.1.1|9=000283|35=X|49=EXCHANGE|56=CLIENT|34=2459|57=SESSION1|52=20260630-07:43:24.404836017|1021=2|262=1000000000000000002|268=3|279=2|269=0|55=SYM00083|48=100000083|22=M|1023=1|279=2|269=0|55=SYM00083|48=100000083|22=M|1023=1|279=0|269=0|55=SYM00083|48=100000083|22=M|270=6.05058|271=6200|1023=1|10=075|
8=FIXT.1.1|9=000184|35=X|49=EXCHANGE|56=CLIENT|34=2458|57=SESSION1|52=20260630-07:43:24.309482885|1021=2|262=1000000000000000002|268=1|279=1|269=0|55=SYM00083|48=100000083|22=M|270=5.52145|271=400|1023=8|10=154|
8=FIXT.1.1|9=000184|35=X|49=EXCHANGE|56=CLIENT|34=2457|57=SESSION1|52=20260630-07:43:24.308053346|1021=2|262=1000000000000000002|268=1|279=0|269=0|55=SYM00083|48=100000083|22=M|270=5.69430|271=200|1023=7|10=139|
8=FIXT.1.1|9=000184|35=X|49=EXCHANGE|56=CLIENT|34=2456|57=SESSION1|52=20260630-07:43:24.250389050|1021=2|262=1000000000000000002|268=1|279=0|269=0|55=SYM00083|48=100000083|22=M|270=5.79255|271=300|1023=5|10=143|
8=FIXT.1.1|9=000184|35=X|49=EXCHANGE|56=CLIENT|34=2455|57=SESSION1|52=20260630-07:43:24.226128414|1021=2|262=1000000000000000002|268=1|279=0|269=0|55=SYM00083|48=100000083|22=M|270=5.72600|271=200|1023=5|10=126|
8=FIXT.1.1|9=000184|35=X|49=EXCHANGE|56=CLIENT|34=2454|57=SESSION1|52=20260630-07:43:24.206280754|1021=2|262=1000000000000000002|268=1|279=0|269=0|55=SYM00083|48=100000083|22=M|270=5.52145|271=100|1023=5|10=130|
8=FIXT.1.1|9=000185|35=X|49=EXCHANGE|56=CLIENT|34=2453|57=SESSION1|52=20260630-07:43:22.122345352|1021=2|262=1000000000000000002|268=1|279=0|269=0|55=SYM00002|48=100000002|22=M|270=63.25412|271=800|1023=4|10=158|
8=FIXT.1.1|9=000186|35=X|49=EXCHANGE|56=CLIENT|34=2452|57=SESSION1|52=20260630-07:43:21.985128410|1021=2|262=1000000000000000002|268=1|279=0|269=0|55=SYM00002|48=100000002|22=M|270=66.18345|271=1000|1023=3|10=218|
8=FIXT.1.1|9=000185|35=X|49=EXCHANGE|56=CLIENT|34=2451|57=SESSION1|52=20260630-07:43:21.964154888|1021=2|262=1000000000000000002|268=1|279=0|269=0|55=SYM00002|48=100000002|22=M|270=66.11622|271=700|1023=2|10=179|
8=FIXT.1.1|9=000185|35=X|49=EXCHANGE|56=CLIENT|34=2450|57=SESSION1|52=20260630-07:43:21.943683016|1021=2|262=1000000000000000002|268=1|279=0|269=0|55=SYM00002|48=100000002|22=M|270=65.87335|271=200|1023=1|10=172|
8=FIXT.1.1|9=000167|35=CO|49=EXCHANGE|56=CLIENT|34=2449|57=SESSION1|52=20260630-07:43:21.925544417|324=1000000000000000001|1301=EXMKT|146=1|55=SYM00002|48=100000002|22=M|58=PRE-OPEN_CB_E|10=129|
8=FIXT.1.1|9=000174|35=CO|49=EXCHANGE|56=CLIENT|34=2448|57=SESSION1|52=20260630-07:43:21.924041648|324=1000000000000000001|1301=EXMKT|625=PRE-OPEN_CB_E|146=1|55=SYM00002|48=100000002|22=M|292=o|10=245|
8=FIXT.1.1|9=000236|35=X|49=EXCHANGE|56=CLIENT|34=2447|57=SESSION1|52=20260630-07:43:21.759565547|262=1000000000000000002|268=1|279=0|269=2|278=0000000000000006|55=SYM00084|48=100000084|22=M|270=1.68155|271=300|273=05:29:54.759425152|574=4|2446=2|7554=587|10=170|
8=FIXT.1.1|9=000185|35=X|49=EXCHANGE|56=CLIENT|34=2446|57=SESSION1|52=20260630-07:43:21.759353190|1021=2|262=1000000000000000002|268=1|279=1|269=0|55=SYM00084|48=100000084|22=M|270=1.68155|271=2000|1023=1|10=189|
8=FIXT.1.1|9=000236|35=X|49=EXCHANGE|56=CLIENT|34=2445|57=SESSION1|52=20260630-07:43:21.737084012|262=1000000000000000002|268=1|279=0|269=2|278=0000000000000007|55=SYM00084|48=100000084|22=M|270=1.68155|271=300|273=05:29:54.737550394|574=4|2446=2|7554=586|10=150|
8=FIXT.1.1|9=000185|35=X|49=EXCHANGE|56=CLIENT|34=2444|57=SESSION1|52=20260630-07:43:21.737756460|1021=2|262=1000000000000000002|268=1|279=1|269=0|55=SYM00084|48=100000084|22=M|270=1.68155|271=2300|1023=1|10=193|
8=FIXT.1.1|9=000236|35=X|49=EXCHANGE|56=CLIENT|34=2443|57=SESSION1|52=20260630-07:43:21.716171752|262=1000000000000000002|268=1|279=0|269=2|278=0000000000000008|55=SYM00084|48=100000084|22=M|270=1.68155|271=300|273=05:29:54.715889685|574=4|2446=2|7554=585|10=167|
8=FIXT.1.1|9=000185|35=X|49=EXCHANGE|56=CLIENT|34=2442|57=SESSION1|52=20260630-07:43:21.716998834|1021=2|262=1000000000000000002|268=1|279=1|269=0|55=SYM00084|48=100000084|22=M|270=1.68155|271=2600|1023=1|10=204|
8=FIXT.1.1|9=000236|35=X|49=EXCHANGE|56=CLIENT|34=2441|57=SESSION1|52=20260630-07:43:21.690587018|262=1000000000000000002|268=1|279=0|269=2|278=0000000000000009|55=SYM00084|48=100000084|22=M|270=1.68155|271=100|273=05:29:54.690166578|574=4|2446=2|7554=584|10=161|
8=FIXT.1.1|9=000236|35=X|49=EXCHANGE|56=CLIENT|34=2440|57=SESSION1|52=20260630-07:43:21.690263177|262=1000000000000000002|268=1|279=0|269=2|278=000000000000000A|55=SYM00084|48=100000084|22=M|270=1.68155|271=200|273=05:29:54.690166578|574=4|2446=2|7554=583|10=165|
8=FIXT.1.1|9=000185|35=X|49=EXCHANGE|56=CLIENT|34=2439|57=SESSION1|52=20260630-07:43:21.690525491|1021=2|262=1000000000000000002|268=1|279=1|269=0|55=SYM00084|48=100000084|22=M|270=1.68155|271=2900|1023=1|10=199|
8=FIXT.1.1|9=000236|35=X|49=EXCHANGE|56=CLIENT|34=2438|57=SESSION1|52=20260630-07:43:21.522021393|262=1000000000000000002|268=1|279=0|269=2|278=000000000000000B|55=SYM00084|48=100000084|22=M|270=1.68155|271=100|273=05:29:54.521926657|574=4|2446=2|7554=582|10=152|
8=FIXT.1.1|9=000185|35=X|49=EXCHANGE|56=CLIENT|34=2437|57=SESSION1|52=20260630-07:43:21.522281653|1021=2|262=1000000000000000002|268=1|279=1|269=0|55=SYM00084|48=100000084|22=M|270=1.68155|271=3200|1023=1|10=184|
8=FIXT.1.1|9=000236|35=X|49=EXCHANGE|56=CLIENT|34=2436|57=SESSION1|52=20260630-07:43:21.411850340|262=1000000000000000002|268=1|279=0|269=2|278=000000000000000C|55=SYM00084|48=100000084|22=M|270=1.68155|271=100|273=05:29:54.411714707|574=4|2446=2|7554=581|10=138|
8=FIXT.1.1|9=000185|35=X|49=EXCHANGE|56=CLIENT|34=2435|57=SESSION1|52=20260630-07:43:21.411698785|1021=2|262=1000000000000000002|268=1|279=1|269=0|55=SYM00084|48=100000084|22=M|270=1.68155|271=3300|1023=1|10=198|
8=FIXT.1.1|9=000238|35=X|49=EXCHANGE|56=CLIENT|34=2434|57=SESSION1|52=20260630-07:43:20.598101174|262=1000000000000000002|268=1|279=0|269=2|278=000000000000000D|55=SYM00085|48=100000085|22=M|270=340.22180|271=100|273=05:29:53.597980017|574=4|2446=2|7554=577|10=002|
8=FIXT.1.1|9=000164|35=X|49=EXCHANGE|56=CLIENT|34=2433|57=SESSION1|52=20260630-07:43:20.598942219|1021=2|262=1000000000000000002|268=1|279=2|269=0|55=SYM00085|48=100000085|22=M|1023=1|10=230|
8=FIXT.1.1|9=000238|35=X|49=EXCHANGE|56=CLIENT|34=2432|57=SESSION1|52=20260630-07:43:20.577533623|262=1000000000000000002|268=1|279=0|269=2|278=000000000000000E|55=SYM00085|48=100000085|22=M|270=350.19240|271=100|273=05:29:53.576916128|574=4|2446=2|7554=576|10=008|
8=FIXT.1.1|9=000164|35=X|49=EXCHANGE|56=CLIENT|34=2431|57=SESSION1|52=20260630-07:43:20.577569160|1021=2|262=1000000000000000002|268=1|279=2|269=0|55=SYM00085|48=100000085|22=M|1023=1|10=225|
8=FIXT.1.1|9=000186|35=X|49=EXCHANGE|56=CLIENT|34=2430|57=SESSION1|52=20260630-07:43:20.534480230|1021=2|262=1000000000000000002|268=1|279=0|269=1|55=SYM00085|48=100000085|22=M|270=354.02560|271=100|1023=1|10=217|
8=FIXT.1.1|9=000238|35=X|49=EXCHANGE|56=CLIENT|34=2429|57=SESSION1|52=20260630-07:43:20.513346861|262=1000000000000000002|268=1|279=0|269=2|278=000000000000000F|55=SYM00085|48=100000085|22=M|270=354.02560|271=100|273=05:29:53.512906807|574=4|2446=2|7554=575|10=004|
8=FIXT.1.1|9=000164|35=X|49=EXCHANGE|56=CLIENT|34=2428|57=SESSION1|52=20260630-07:43:20.513304489|1021=2|262=1000000000000000002|268=1|279=2|269=0|55=SYM00085|48=100000085|22=M|1023=1|10=222|
8=FIXT.1.1|9=000186|35=X|49=EXCHANGE|56=CLIENT|34=2427|57=SESSION1|52=20260630-07:43:20.491480747|1021=2|262=1000000000000000002|268=1|279=0|269=0|55=SYM00085|48=100000085|22=M|270=340.22180|271=100|1023=3|10=234|
8=FIXT.1.1|9=000186|35=X|49=EXCHANGE|56=CLIENT|34=2426|57=SESSION1|52=20260630-07:43:20.368725040|1021=2|262=1000000000000000002|268=1|279=0|269=0|55=SYM00085|48=100000085|22=M|270=350.19240|271=100|1023=2|10=227|
8=FIXT.1.1|9=000186|35=X|49=EXCHANGE|56=CLIENT|34=2425|57=SESSION1|52=20260630-07:43:20.345559887|1021=2|262=1000000000000000002|268=1|279=0|269=0|55=SYM00085|48=100000085|22=M|270=354.02560|271=100|1023=1|10=245|
8=FIXT.1.1|9=000236|35=X|49=EXCHANGE|56=CLIENT|34=2424|57=SESSION1|52=20260630-07:43:20.007602284|262=1000000000000000002|268=1|279=0|269=2|278=0000000000000010|55=SYM00086|48=100000086|22=M|270=2.04630|271=100|273=05:29:53.007580492|574=4|2446=2|7554=574|10=116|
8=FIXT.1.1|9=000184|35=X|49=EXCHANGE|56=CLIENT|34=2423|57=SESSION1|52=20260630-07:43:20.007981260|1021=2|262=1000000000000000002|268=1|279=1|269=0|55=SYM00086|48=100000086|22=M|270=2.04630|271=400|1023=1|10=120|
8=FIXT.1.1|9=000185|35=X|49=EXCHANGE|56=CLIENT|34=2422|57=SESSION1|52=20260630-07:43:19.722535426|1021=2|262=1000000000000000002|268=1|279=0|269=0|55=SYM00087|48=100000087|22=M|270=53.88960|271=100|1023=2|10=202|
8=FIXT.1.1|9=000185|35=X|49=EXCHANGE|56=CLIENT|34=2421|57=SESSION1|52=20260630-07:43:19.543969287|1021=2|262=1000000000000000002|268=1|279=0|269=0|55=SYM00087|48=100000087|22=M|270=56.75040|271=100|1023=1|10=205|
8=FIXT.1.1|9=000237|35=X|49=EXCHANGE|56=CLIENT|34=2420|57=SESSION1|52=20260630-07:43:19.521895509|262=1000000000000000002|268=1|279=0|269=2|278=0000000000000011|55=SYM00087|48=100000087|22=M|270=51.17700|271=100|273=05:29:52.521707234|574=4|2446=1|7554=573|10=186|
8=FIXT.1.1|9=000164|35=X|49=EXCHANGE|56=CLIENT|34=2419|57=SESSION1|52=20260630-07:43:19.521515369|1021=2|262=1000000000000000002|268=1|279=2|269=1|55=SYM00087|48=100000087|22=M|1023=1|10=235|
8=FIXT.1.1|9=000237|35=X|49=EXCHANGE|56=CLIENT|34=2418|57=SESSION1|52=20260630-07:43:19.408906761|262=1000000000000000002|268=1|279=0|269=2|278=0000000000000012|55=SYM00087|48=100000087|22=M|270=52.44412|271=100|273=05:29:52.408572963|574=4|2446=1|7554=572|10=204|
8=FIXT.1.1|9=000235|35=X|49=EXCHANGE|56=CLIENT|34=2417|57=SESSION1|52=20260630-07:43:19.408057145|1021=2|262=1000000000000000002|268=2|279=0|269=0|55=SYM00087|48=100000087|22=M|270=52.46820|271=9900|1023=1|279=2|269=1|55=SYM00087|48=100000087|22=M|1023=1|10=077|
8=FIXT.1.1|9=000238|35=X|49=EXCHANGE|56=CLIENT|34=2416|57=SESSION1|52=20260630-07:43:19.383343610|262=1000000000000000002|268=1|279=0|269=2|278=0000000000000013|55=SYM00087|48=100000087|22=M|270=52.44412|271=9900|273=05:29:52.382907384|574=4|2446=1|7554=571|10=002|
8=FIXT.1.1|9=000237|35=X|49=EXCHANGE|56=CLIENT|34=2415|57=SESSION1|52=20260630-07:43:19.383761909|262=1000000000000000002|268=1|279=0|269=2|278=0000000000000014|55=SYM00087|48=100000087|22=M|270=48.24480|271=100|273=05:29:52.382907384|574=4|2446=1|7554=570|10=214|
8=FIXT.1.1|9=000283|35=X|49=EXCHANGE|56=CLIENT|34=2414|57=SESSION1|52=20260630-07:43:19.383578337|1021=2|262=1000000000000000002|268=3|279=2|269=1|55=SYM00087|48=100000087|22=M|1023=1|279=2|269=1|55=SYM00087|48=100000087|22=M|1023=1|279=0|269=1|55=SYM00087|48=100000087|22=M|270=52.44412|271=100|1023=1|10=102|
8=FIXT.1.1|9=000185|35=X|49=EXCHANGE|56=CLIENT|34=2413|57=SESSION1|52=20260630-07:43:19.338849458|1021=2|262=1000000000000000002|268=1|279=0|269=1|55=SYM00087|48=100000087|22=M|270=51.17700|271=100|1023=3|10=202|
8=FIXT.1.1|9=76|35=0|34=62|49=CLIENT|56=EXCHANGE|52=20260630-07:43:19.631936802|50=SESSION1|10=153|
8=FIXT.1.1|9=000187|35=X|49=EXCHANGE|56=CLIENT|34=2412|57=SESSION1|52=20260630-07:43:19.295663245|1021=2|262=1000000000000000002|268=1|279=0|269=1|55=SYM00087|48=100000087|22=M|270=52.44412|271=10000|1023=2|10=033|
8=FIXT.1.1|9=000237|35=X|49=EXCHANGE|56=CLIENT|34=2411|57=SESSION1|52=20260630-07:43:19.163186613|262=1000000000000000002|268=1|279=0|269=2|278=0000000000000015|55=SYM00088|48=100000088|22=M|270=42.64305|271=800|273=05:29:52.163477496|574=4|2446=2|7554=569|10=215|
8=FIXT.1.1|9=000187|35=X|49=EXCHANGE|56=CLIENT|34=2410|57=SESSION1|52=20260630-07:43:19.163188175|1021=2|262=1000000000000000002|268=1|279=1|269=0|55=SYM00088|48=100000088|22=M|270=42.64305|271=46100|1023=1|10=042|
8=FIXT.1.1|9=000186|35=X|49=EXCHANGE|56=CLIENT|34=2409|57=SESSION1|52=20260630-07:43:19.121303033|1021=2|262=1000000000000000002|268=1|279=1|269=1|55=SYM00088|48=100000088|22=M|270=44.71280|271=3800|1023=2|10=237|
8=FIXT.1.1|9=000186|35=X|49=EXCHANGE|56=CLIENT|34=2408|57=SESSION1|52=20260630-07:43:18.650093071|1021=2|262=1000000000000000002|268=1|279=1|269=0|55=SYM00089|48=100000089|22=M|270=23.16006|271=1300|1023=2|10=236|
8=FIXT.1.1|9=000185|35=X|49=EXCHANGE|56=CLIENT|34=2407|57=SESSION1|52=20260630-07:43:18.608456344|1021=2|262=1000000000000000002|268=1|279=0|269=0|55=SYM00089|48=100000089|22=M|270=23.16006|271=100|1023=2|10=191|
8=FIXT.1.1|9=000185|35=X|49=EXCHANGE|56=CLIENT|34=2406|57=SESSION1|52=20260630-07:43:18.586121145|1021=2|262=1000000000000000002|268=1|279=0|269=0|55=SYM00089|48=100000089|22=M|270=23.89600|271=100|1023=1|10=192|
8=FIXT.1.1|9=000185|35=X|49=EXCHANGE|56=CLIENT|34=2405|57=SESSION1|52=20260630-07:43:18.565914217|1021=2|262=1000000000000000002|268=1|279=0|269=0|55=SYM00089|48=100000089|22=M|270=22.85086|271=100|1023=1|10=201|
8=FIXT.1.1|9=000186|35=X|49=EXCHANGE|56=CLIENT|34=2404|57=SESSION1|52=20260630-07:43:18.543076063|1021=2|262=1000000000000000002|268=1|279=0|269=0|55=SYM00090|48=100000090|22=M|270=65.63990|271=1200|1023=2|10=237|
8=FIXT.1.1|9=000237|35=X|49=EXCHANGE|56=CLIENT|34=2403|57=SESSION1|52=20260630-07:43:18.521935819|262=1000000000000000002|268=1|279=0|269=2|278=0000000000000016|55=SYM00090|48=100000090|22=M|270=65.63990|271=500|273=05:29:51.521525964|574=4|2446=1|7554=568|10=210|
8=FIXT.1.1|9=000234|35=X|49=EXCHANGE|56=CLIENT|34=2402|57=SESSION1|52=20260630-07:43:18.521262886|1021=2|262=1000000000000000002|268=2|279=0|269=0|55=SYM00090|48=100000090|22=M|270=67.74975|271=600|1023=1|279=2|269=1|55=SYM00090|48=100000090|22=M|1023=1|10=009|
8=FIXT.1.1|9=000186|35=X|49=EXCHANGE|56=CLIENT|34=2401|57=SESSION1|52=20260630-07:43:18.408715458|1021=2|262=1000000000000000002|268=1|279=0|269=0|55=SYM00090|48=100000090|22=M|270=67.84000|271=1300|1023=1|10=229|
8=FIXT.1.1|9=000237|35=X|49=EXCHANGE|56=CLIENT|34=2400|57=SESSION1|52=20260630-07:43:18.386408520|262=1000000000000000002|268=1|279=0|269=2|278=0000000000000017|55=SYM00090|48=100000090|22=M|270=66.18345|271=900|273=05:29:51.386475826|574=4|2446=1|7554=567|10=209|
8=FIXT.1.1|9=000234|35=X|49=EXCHANGE|56=CLIENT|34=2399|57=SESSION1|52=20260630-07:43:18.386805609|1021=2|262=1000000000000000002|268=2|279=0|269=0|55=SYM00090|48=100000090|22=M|270=64.48005|271=200|1023=1|279=2|269=1|55=SYM00090|48=100000090|22=M|1023=1|10=007|
8=FIXT.1.1|9=000186|35=X|49=EXCHANGE|56=CLIENT|34=2398|57=SESSION1|52=20260630-07:43:18.365924514|1021=2|262=1000000000000000002|268=1|279=0|269=0|55=SYM00003|48=100000003|22=M|270=14.92704|271=2000|1023=3|10=231|
8=FIXT.1.1|9=000186|35=X|49=EXCHANGE|56=CLIENT|34=2397|57=SESSION1|52=20260630-07:43:18.343655283|1021=2|262=1000000000000000002|268=1|279=0|269=0|55=SYM00003|48=100000003|22=M|270=15.67179|271=2000|1023=1|10=237|
8=FIXT.1.1|9=000186|35=X|49=EXCHANGE|56=CLIENT|34=2396|57=SESSION1|52=20260630-07:43:18.322835450|1021=2|262=1000000000000000002|268=1|279=0|269=0|55=SYM00003|48=100000003|22=M|270=14.97504|271=2000|1023=1|10=223|
8=FIXT.1.1|9=000167|35=CO|49=EXCHANGE|56=CLIENT|34=2395|57=SESSION1|52=20260630-07:43:18.192638438|324=1000000000000000001|1301=EXMKT|146=1|55=SYM00003|48=100000003|22=M|58=PRE-OPEN_CB_E|10=140|
8=FIXT.1.1|9=000174|35=CO|49=EXCHANGE|56=CLIENT|34=2394|57=SESSION1|52=20260630-07:43:18.191652875|324=1000000000000000001|1301=EXMKT|625=PRE-OPEN_CB_E|146=1|55=SYM00003|48=100000003|22=M|292=o|10=003|
8=FIXT.1.1|9=000185|35=X|49=EXCHANGE|56=CLIENT|34=2393|57=SESSION1|52=20260630-07:43:18.143200746|1021=2|262=1000000000000000002|268=1|279=0|269=0|55=SYM00084|48=100000084|22=M|270=1.26695|271=2000|1023=8|10=190|
8=FIXT.1.1|9=000185|35=X|49=EXCHANGE|56=CLIENT|34=2392|57=SESSION1|52=20260630-07:43:18.121643199|1021=2|262=1000000000000000002|268=1|279=0|269=0|55=SYM00084|48=100000084|22=M|270=1.21980|271=2000|1023=8|10=190|
8=FIXT.1.1|9=000185|35=X|49=EXCHANGE|56=CLIENT|34=2391|57=SESSION1|52=20260630-07:43:17.971923608|1021=2|262=1000000000000000002|268=1|279=0|269=0|55=SYM00084|48=100000084|22=M|270=1.29306|271=2000|1023=7|10=196|
8=FIXT.1.1|9=000185|35=X|49=EXCHANGE|56=CLIENT|34=2390|57=SESSION1|52=20260630-07:43:17.945639431|1021=2|262=1000000000000000002|268=1|279=0|269=0|55=SYM00084|48=100000084|22=M|270=1.26932|271=2000|1023=6|10=195|
8=FIXT.1.1|9=000186|35=X|49=EXCHANGE|56=CLIENT|34=2389|57=SESSION1|52=20260630-07:43:16.922247692|1021=2|262=1000000000000000002|268=1|279=1|269=0|55=SYM00002|48=100000002|22=M|270=56.62020|271=9500|1023=6|10=241|
8=FIXT.1.1|9=000185|35=X|49=EXCHANGE|56=CLIENT|34=2388|57=SESSION1|52=20260630-07:43:15.775748651|1021=2|262=1000000000000000002|268=1|279=1|269=0|55=SYM00002|48=100000002|22=M|270=56.62020|271=300|1023=6|10=186|
8=FIXT.1.1|9=000237|35=X|49=EXCHANGE|56=CLIENT|34=2387|57=SESSION1|52=20260630-07:42:49.296558654|262=1000000000000000002|268=1|279=0|269=2|278=0000000000000018|55=SYM00091|48=100000091|22=M|270=4452.21360|271=2|273=05:29:22.295922709|574=4|2446=2|7554=566|10=224|
8=FIXT.1.1|9=76|35=0|34=61|49=CLIENT|56=EXCHANGE|52=20260630-07:42:49.518017582|50=SESSION1|10=153|
8=FIXT.1.1|9=000185|35=X|49=EXCHANGE|56=CLIENT|34=2386|57=SESSION1|52=20260630-07:42:49.296477274|1021=2|262=1000000000000000002|268=1|279=1|269=0|55=SYM00091|48=100000091|22=M|270=4452.21360|271=5|1023=1|10=207|
8=FIXT.1.1|9=000078|35=0|49=EXCHANGE|56=CLIENT|34=2385|57=SESSION1|52=20260630-07:42:47.889661679|10=226|
8=FIXT.1.1|9=117|35=0|34=60|49=CLIENT|56=EXCHANGE|52=20260630-07:42:18.112857483|50=SESSION1|112=00000000-0000-0000-0000-000000000016|10=079|
8=FIXT.1.1|9=000119|35=1|49=EXCHANGE|56=CLIENT|34=2384|57=SESSION1|52=20260630-07:42:17.889482222|112=00000000-0000-0000-0000-000000000016|10=089|
8=FIXT.1.1|9=000187|35=X|49=EXCHANGE|56=CLIENT|34=2383|57=SESSION1|52=20260630-07:41:48.853947688|1021=2|262=1000000000000000002|268=1|279=1|269=0|55=SYM00092|48=100000092|22=M|270=34.39450|271=30900|1023=3|10=066|
8=FIXT.1.1|9=000187|35=X|49=EXCHANGE|56=CLIENT|34=2382|57=SESSION1|52=20260630-07:41:48.843690155|1021=2|262=1000000000000000002|268=1|279=1|269=0|55=SYM00092|48=100000092|22=M|270=34.39450|271=25500|1023=3|10=048|
8=FIXT.1.1|9=000187|35=X|49=EXCHANGE|56=CLIENT|34=2381|57=SESSION1|52=20260630-07:41:48.843556465|1021=2|262=1000000000000000002|268=1|279=1|269=0|55=SYM00092|48=100000092|22=M|270=34.39450|271=28000|1023=3|10=050|
8=FIXT.1.1|9=000187|35=X|49=EXCHANGE|56=CLIENT|34=2380|57=SESSION1|52=20260630-07:41:48.843485476|1021=2|262=1000000000000000002|268=1|279=1|269=0|55=SYM00092|48=100000092|22=M|270=34.39450|271=30400|1023=3|10=049|
8=FIXT.1.1|9=117|35=0|34=59|49=CLIENT|56=EXCHANGE|52=20260630-07:41:42.703896438|50=SESSION1|112=00000000-0000-0000-0000-000000000017|10=093|
8=FIXT.1.1|9=000119|35=1|49=EXCHANGE|56=CLIENT|34=2379|57=SESSION1|52=20260630-07:41:42.481684194|112=00000000-0000-0000-0000-000000000017|10=091|
8=FIXT.1.1|9=000078|35=0|49=EXCHANGE|56=CLIENT|34=2378|57=SESSION1|52=20260630-07:41:36.403193403|10=192|
8=FIXT.1.1|9=76|35=0|34=58|49=CLIENT|56=EXCHANGE|52=20260630-07:41:07.294205228|50=SESSION1|10=149|
8=FIXT.1.1|9=000078|35=0|49=EXCHANGE|56=CLIENT|34=2377|57=SESSION1|52=20260630-07:41:06.403258132|10=189|
8=FIXT.1.1|9=76|35=0|34=57|49=CLIENT|56=EXCHANGE|52=20260630-07:40:37.276230182|50=SESSION1|10=147|
8=FIXT.1.1|9=000078|35=0|49=EXCHANGE|56=CLIENT|34=2376|57=SESSION1|52=20260630-07:40:36.403453567|10=199|
8=FIXT.1.1|9=76|35=0|34=56|49=CLIENT|56=EXCHANGE|52=20260630-07:40:06.626627781|50=SESSION1|10=156|
8=FIXT.1.1|9=000078|35=0|49=EXCHANGE|56=CLIENT|34=2375|57=SESSION1|52=20260630-07:40:06.403169817|10=197|
8=FIXT.1.1|9=117|35=0|34=55|49=CLIENT|56=EXCHANGE|52=20260630-07:39:36.625605488|50=SESSION1|112=00000000-0000-0000-0000-000000000018|10=096|
8=FIXT.1.1|9=000119|35=1|49=EXCHANGE|56=CLIENT|34=2374|57=SESSION1|52=20260630-07:39:36.403790809|112=00000000-0000-0000-0000-000000000018|10=092|
8=FIXT.1.1|9=000078|35=0|49=EXCHANGE|56=CLIENT|34=2373|57=SESSION1|52=20260630-07:39:30.994116391|10=204|
8=FIXT.1.1|9=76|35=0|34=54|49=CLIENT|56=EXCHANGE|52=20260630-07:39:01.216441199|50=SESSION1|10=149|
8=FIXT.1.1|9=000078|35=0|49=EXCHANGE|56=CLIENT|34=2372|57=SESSION1|52=20260630-07:39:00.994705844|10=207|
8=FIXT.1.1|9=117|35=0|34=53|49=CLIENT|56=EXCHANGE|52=20260630-07:38:31.216202770|50=SESSION1|112=00000000-0000-0000-0000-000000000019|10=072|
8=FIXT.1.1|9=000119|35=1|49=EXCHANGE|56=CLIENT|34=2371|57=SESSION1|52=20260630-07:38:30.994241140|112=00000000-0000-0000-0000-000000000019|10=077|
8=FIXT.1.1|9=000078|35=0|49=EXCHANGE|56=CLIENT|34=2370|57=SESSION1|52=20260630-07:38:25.584401443|10=194|
8=FIXT.1.1|9=117|35=0|34=52|49=CLIENT|56=EXCHANGE|52=20260630-07:37:55.807352798|50=SESSION1|112=00000000-0000-0000-0000-000000000020|10=090|
8=FIXT.1.1|9=000119|35=1|49=EXCHANGE|56=CLIENT|34=2369|57=SESSION1|52=20260630-07:37:55.584389072|112=00000000-0000-0000-0000-000000000020|10=094|
8=FIXT.1.1|9=000078|35=0|49=EXCHANGE|56=CLIENT|34=2368|57=SESSION1|52=20260630-07:37:50.176158816|10=208|
8=FIXT.1.1|9=76|35=0|34=51|49=CLIENT|56=EXCHANGE|52=20260630-07:37:20.398413989|50=SESSION1|10=162|
8=FIXT.1.1|9=000078|35=0|49=EXCHANGE|56=CLIENT|34=2367|57=SESSION1|52=20260630-07:37:20.176031926|10=196|
8=FIXT.1.1|9=117|35=0|34=50|49=CLIENT|56=EXCHANGE|52=20260630-07:36:50.398777942|50=SESSION1|112=00000000-0000-0000-0000-000000000021|10=090|
8=FIXT.1.1|9=000119|35=1|49=EXCHANGE|56=CLIENT|34=2366|57=SESSION1|52=20260630-07:36:50.176201919|112=00000000-0000-0000-0000-000000000021|10=076|
8=FIXT.1.1|9=000078|35=0|49=EXCHANGE|56=CLIENT|34=2365|57=SESSION1|52=20260630-07:36:44.767465106|10=206|
8=FIXT.1.1|9=117|35=0|34=49|49=CLIENT|56=EXCHANGE|52=20260630-07:36:14.990467432|50=SESSION1|112=00000000-0000-0000-0000-000000000022|10=087|
8=FIXT.1.1|9=000119|35=1|49=EXCHANGE|56=CLIENT|34=2364|57=SESSION1|52=20260630-07:36:14.768759531|112=00000000-0000-0000-0000-000000000022|10=090|
8=FIXT.1.1|9=000078|35=0|49=EXCHANGE|56=CLIENT|34=2363|57=SESSION1|52=20260630-07:36:09.358602144|10=196|
8=FIXT.1.1|9=117|35=0|34=48|49=CLIENT|56=EXCHANGE|52=20260630-07:35:39.581680609|50=SESSION1|112=00000000-0000-0000-0000-000000000023|10=092|
8=FIXT.1.1|9=000119|35=1|49=EXCHANGE|56=CLIENT|34=2362|57=SESSION1|52=20260630-07:35:39.359844825|112=00000000-0000-0000-0000-000000000023|10=092|
8=FIXT.1.1|9=000078|35=0|49=EXCHANGE|56=CLIENT|34=2361|57=SESSION1|52=20260630-07:35:33.949494751|10=209|
8=FIXT.1.1|9=76|35=0|34=47|49=CLIENT|56=EXCHANGE|52=20260630-07:35:04.171220107|50=SESSION1|10=134|
8=FIXT.1.1|9=000078|35=0|49=EXCHANGE|56=CLIENT|34=2360|57=SESSION1|52=20260630-07:35:03.949477283|10=206|
8=FIXT.1.1|9=117|35=0|34=46|49=CLIENT|56=EXCHANGE|52=20260630-07:34:34.171267452|50=SESSION1|112=00000000-0000-0000-0000-000000000024|10=077|
8=FIXT.1.1|9=000119|35=1|49=EXCHANGE|56=CLIENT|34=2359|57=SESSION1|52=20260630-07:34:33.949640393|112=00000000-0000-0000-0000-000000000024|10=091|
8=FIXT.1.1|9=000187|35=X|49=EXCHANGE|56=CLIENT|34=2358|57=SESSION1|52=20260630-07:34:08.626548482|1021=2|262=1000000000000000002|268=1|279=1|269=1|55=SYM00071|48=100000071|22=M|270=1014.35002|271=991|1023=1|10=041|
8=FIXT.1.1|9=000187|35=X|49=EXCHANGE|56=CLIENT|34=2357|57=SESSION1|52=20260630-07:34:08.626114564|1021=2|262=1000000000000000002|268=1|279=1|269=1|55=SYM00070|48=100000070|22=M|270=1005.90291|271=492|1023=1|10=035|
8=FIXT.1.1|9=000237|35=X|49=EXCHANGE|56=CLIENT|34=2356|57=SESSION1|52=20260630-07:34:08.626990418|262=1000000000000000002|268=1|279=0|269=2|278=0000000000000019|55=SYM00070|48=100000070|22=M|270=1005.90291|271=1|273=05:20:41.625996825|574=4|2446=1|7554=565|10=202|
8=FIXT.1.1|9=000237|35=X|49=EXCHANGE|56=CLIENT|34=2355|57=SESSION1|52=20260630-07:34:00.538732209|262=1000000000000000002|268=1|279=0|269=2|278=000000000000001A|55=SYM00092|48=100000092|22=M|270=38.05450|271=100|273=05:20:33.537528617|574=4|2446=1|7554=564|10=193|
8=FIXT.1.1|9=000185|35=X|49=EXCHANGE|56=CLIENT|34=2354|57=SESSION1|52=20260630-07:34:00.538240553|1021=2|262=1000000000000000002|268=1|279=1|269=1|55=SYM00092|48=100000092|22=M|270=38.05450|271=800|1023=1|10=181|
8=FIXT.1.1|9=000237|35=X|49=EXCHANGE|56=CLIENT|34=2353|57=SESSION1|52=20260630-07:33:58.540722594|262=1000000000000000002|268=1|279=0|269=2|278=000000000000001B|55=SYM00070|48=100000070|22=M|270=1032.55212|271=1|273=05:20:31.540037287|574=4|2446=2|7554=563|10=181|
8=FIXT.1.1|9=76|35=0|34=45|49=CLIENT|56=EXCHANGE|52=20260630-07:33:58.762306107|50=SESSION1|10=150|
8=FIXT.1.1|9=000187|35=X|49=EXCHANGE|56=CLIENT|34=2352|57=SESSION1|52=20260630-07:33:58.540528763|1021=2|262=1000000000000000002|268=1|279=1|269=0|55=SYM00070|48=100000070|22=M|270=1032.55212|271=998|1023=1|10=043|
8=FIXT.1.1|9=000237|35=X|49=EXCHANGE|56=CLIENT|34=2351|57=SESSION1|52=20260630-07:33:48.946721908|262=1000000000000000002|268=1|279=0|269=2|278=000000000000001C|55=SYM00070|48=100000070|22=M|270=1005.90291|271=1|273=05:20:21.945448524|574=4|2446=1|7554=562|10=199|
8=FIXT.1.1|9=000187|35=X|49=EXCHANGE|56=CLIENT|34=2350|57=SESSION1|52=20260630-07:33:48.946336669|1021=2|262=1000000000000000002|268=1|279=1|269=1|55=SYM00071|48=100000071|22=M|270=1014.35002|271=992|1023=1|10=044|
8=FIXT.1.1|9=000187|35=X|49=EXCHANGE|56=CLIENT|34=2349|57=SESSION1|52=20260630-07:33:48.946457139|1021=2|262=1000000000000000002|268=1|279=1|269=1|55=SYM00070|48=100000070|22=M|270=1005.90291|271=493|1023=1|10=053|
8=FIXT.1.1|9=117|35=0|34=44|49=CLIENT|56=EXCHANGE|52=20260630-07:33:25.825116021|50=SESSION1|112=00000000-0000-0000-0000-000000000025|10=066|
8=FIXT.1.1|9=000119|35=1|49=EXCHANGE|56=CLIENT|34=2348|57=SESSION1|52=20260630-07:33:25.603803497|112=00000000-0000-0000-0000-000000000025|10=083|
8=FIXT.1.1|9=000186|35=X|49=EXCHANGE|56=CLIENT|34=2347|57=SESSION1|52=20260630-07:33:15.710755097|1021=2|262=1000000000000000002|268=1|279=1|269=0|55=SYM00002|48=100000002|22=M|270=56.62020|271=1200|1023=6|10=220|
8=FIXT.1.1|9=000185|35=X|49=EXCHANGE|56=CLIENT|34=2346|57=SESSION1|52=20260630-07:33:14.591040309|1021=2|262=1000000000000000002|268=1|279=1|269=0|55=SYM00002|48=100000002|22=M|270=56.62020|271=300|1023=6|10=159|
8=FIXT.1.1|9=117|35=0|34=43|49=CLIENT|56=EXCHANGE|52=20260630-07:32:50.416624700|50=SESSION1|112=00000000-0000-0000-0000-000000000026|10=067|
8=FIXT.1.1|9=000119|35=1|49=EXCHANGE|56=CLIENT|34=2345|57=SESSION1|52=20260630-07:32:50.194603590|112=00000000-0000-0000-0000-000000000026|10=075|
8=FIXT.1.1|9=000078|35=0|49=EXCHANGE|56=CLIENT|34=2344|57=SESSION1|52=20260630-07:32:44.785345148|10=202|
8=FIXT.1.1|9=117|35=0|34=42|49=CLIENT|56=EXCHANGE|52=20260630-07:32:15.007793505|50=SESSION1|112=00000000-0000-0000-0000-000000000027|10=074|
8=FIXT.1.1|9=000119|35=1|49=EXCHANGE|56=CLIENT|34=2343|57=SESSION1|52=20260630-07:32:14.785376512|112=00000000-0000-0000-0000-000000000027|10=081|
8=FIXT.1.1|9=000078|35=0|49=EXCHANGE|56=CLIENT|34=2342|57=SESSION1|52=20260630-07:32:09.377043005|10=185|
8=FIXT.1.1|9=117|35=0|34=41|49=CLIENT|56=EXCHANGE|52=20260630-07:31:39.599363916|50=SESSION1|112=00000000-0000-0000-0000-000000000028|10=094|
8=FIXT.1.1|9=000119|35=1|49=EXCHANGE|56=CLIENT|34=2341|57=SESSION1|52=20260630-07:31:39.377705678|112=00000000-0000-0000-0000-000000000028|10=092|
8=FIXT.1.1|9=000185|35=X|49=EXCHANGE|56=CLIENT|34=2340|57=SESSION1|52=20260630-07:31:12.245140637|1021=2|262=1000000000000000002|268=1|279=1|269=0|55=SYM00088|48=100000088|22=M|270=40.31765|271=200|1023=4|10=180|
8=FIXT.1.1|9=000185|35=X|49=EXCHANGE|56=CLIENT|34=2339|57=SESSION1|52=20260630-07:31:11.161804044|1021=2|262=1000000000000000002|268=1|279=1|269=0|55=SYM00088|48=100000088|22=M|270=39.40308|271=400|1023=5|10=187|
8=FIXT.1.1|9=000185|35=X|49=EXCHANGE|56=CLIENT|34=2338|57=SESSION1|52=20260630-07:31:09.123634691|1021=2|262=1000000000000000002|268=1|279=1|269=0|55=SYM00088|48=100000088|22=M|270=39.10920|271=600|1023=6|10=200|
8=FIXT.1.1|9=000185|35=X|49=EXCHANGE|56=CLIENT|34=2337|57=SESSION1|52=20260630-07:31:08.977313930|1021=2|262=1000000000000000002|268=1|279=1|269=0|55=SYM00088|48=100000088|22=M|270=39.34288|271=400|1023=7|10=217|
8=FIXT.1.1|9=000185|35=X|49=EXCHANGE|56=CLIENT|34=2336|57=SESSION1|52=20260630-07:31:06.812960167|1021=2|262=1000000000000000002|268=1|279=1|269=0|55=SYM00088|48=100000088|22=M|270=38.40660|271=200|1023=8|10=201|
8=FIXT.1.1|9=000237|35=X|49=EXCHANGE|56=CLIENT|34=2335|57=SESSION1|52=20260630-07:31:05.722009973|262=1000000000000000002|268=1|279=0|269=2|278=000000000000001D|55=SYM00088|48=100000088|22=M|270=42.64305|271=100|273=05:17:38.722039899|574=4|2446=2|7554=560|10=218|
8=FIXT.1.1|9=000187|35=X|49=EXCHANGE|56=CLIENT|34=2334|57=SESSION1|52=20260630-07:31:05.722172636|1021=2|262=1000000000000000002|268=1|279=1|269=0|55=SYM00088|48=100000088|22=M|270=42.64305|271=46900|1023=1|10=043|
8=FIXT.1.1|9=000237|35=X|49=EXCHANGE|56=CLIENT|34=2333|57=SESSION1|52=20260630-07:31:03.722041216|262=1000000000000000002|268=1|279=0|269=2|278=000000000000001E|55=SYM00088|48=100000088|22=M|270=42.64305|271=200|273=05:17:36.722589953|574=4|2446=2|7554=559|10=209|
8=FIXT.1.1|9=000187|35=X|49=EXCHANGE|56=CLIENT|34=2332|57=SESSION1|52=20260630-07:31:03.722779720|1021=2|262=1000000000000000002|268=1|279=1|269=0|55=SYM00088|48=100000088|22=M|270=42.64305|271=47000|1023=1|10=038|
8=FIXT.1.1|9=76|35=0|34=40|49=CLIENT|56=EXCHANGE|52=20260630-07:31:04.190098201|50=SESSION1|10=132|
8=FIXT.1.1|9=000237|35=X|49=EXCHANGE|56=CLIENT|34=2331|57=SESSION1|52=20260630-07:31:03.558475389|262=1000000000000000002|268=1|279=0|269=2|278=000000000000001F|55=SYM00088|48=100000088|22=M|270=42.64305|271=300|273=05:17:36.557978450|574=4|2446=2|7554=558|10=237|
8=FIXT.1.1|9=000187|35=X|49=EXCHANGE|56=CLIENT|34=2330|57=SESSION1|52=20260630-07:31:03.558063363|1021=2|262=1000000000000000002|268=1|279=1|269=0|55=SYM00088|48=100000088|22=M|270=42.64305|271=47200|1023=1|10=034|
8=FIXT.1.1|9=000237|35=X|49=EXCHANGE|56=CLIENT|34=2329|57=SESSION1|52=20260630-07:31:02.448484471|262=1000000000000000002|268=1|279=0|269=2|278=0000000000000020|55=SYM00088|48=100000088|22=M|270=42.64305|271=200|273=05:17:35.447714436|574=4|2446=2|7554=557|10=199|
8=FIXT.1.1|9=000187|35=X|49=EXCHANGE|56=CLIENT|34=2328|57=SESSION1|52=20260630-07:31:02.447081421|1021=2|262=1000000000000000002|268=1|279=1|269=0|55=SYM00088|48=100000088|22=M|270=42.64305|271=47500|1023=1|10=035|
8=FIXT.1.1|9=000237|35=X|49=EXCHANGE|56=CLIENT|34=2327|57=SESSION1|52=20260630-07:31:01.362387273|262=1000000000000000002|268=1|279=0|269=2|278=0000000000000021|55=SYM00088|48=100000088|22=M|270=42.64305|271=200|273=05:17:34.361960618|574=4|2446=2|7554=556|10=192|
8=FIXT.1.1|9=000187|35=X|49=EXCHANGE|56=CLIENT|34=2326|57=SESSION1|52=20260630-07:31:01.362094036|1021=2|262=1000000000000000002|268=1|279=1|269=0|55=SYM00088|48=100000088|22=M|270=42.64305|271=47700|1023=1|10=036|
8=FIXT.1.1|9=000237|35=X|49=EXCHANGE|56=CLIENT|34=2325|57=SESSION1|52=20260630-07:31:00.273171314|262=1000000000000000002|268=1|279=0|269=2|278=0000000000000022|55=SYM00088|48=100000088|22=M|270=42.64305|271=100|273=05:17:33.272881232|574=4|2446=2|7554=555|10=170|
8=FIXT.1.1|9=000187|35=X|49=EXCHANGE|56=CLIENT|34=2324|57=SESSION1|52=20260630-07:31:00.273766230|1021=2|262=1000000000000000002|268=1|279=1|269=0|55=SYM00088|48=100000088|22=M|270=42.64305|271=47900|1023=1|10=038|
8=FIXT.1.1|9=000184|35=X|49=EXCHANGE|56=CLIENT|34=2323|57=SESSION1|52=20260630-07:30:40.211743045|1021=2|262=1000000000000000002|268=1|279=0|269=1|55=SYM00093|48=100000093|22=M|270=0.43434|271=300|1023=2|10=110|
8=FIXT.1.1|9=000184|35=X|49=EXCHANGE|56=CLIENT|34=2322|57=SESSION1|52=20260630-07:30:40.188038779|1021=2|262=1000000000000000002|268=1|279=1|269=1|55=SYM00093|48=100000093|22=M|270=0.46976|271=400|1023=4|10=151|
8=FIXT.1.1|9=000184|35=X|49=EXCHANGE|56=CLIENT|34=2321|57=SESSION1|52=20260630-07:30:39.146425228|1021=2|262=1000000000000000002|268=1|279=1|269=1|55=SYM00093|48=100000093|22=M|270=0.45016|271=200|1023=3|10=122|
8=FIXT.1.1|9=000185|35=X|49=EXCHANGE|56=CLIENT|34=2320|57=SESSION1|52=20260630-07:30:37.123894978|1021=2|262=1000000000000000002|268=1|279=1|269=1|55=SYM00093|48=100000093|22=M|270=0.43740|271=1300|1023=2|10=188|
8=FIXT.1.1|9=000185|35=X|49=EXCHANGE|56=CLIENT|34=2319|57=SESSION1|52=20260630-07:30:37.052214533|1021=2|262=1000000000000000002|268=1|279=0|269=1|55=SYM00093|48=100000093|22=M|270=0.41906|271=3000|1023=1|10=169|
8=FIXT.1.1|9=000185|35=X|49=EXCHANGE|56=CLIENT|34=2318|57=SESSION1|52=20260630-07:30:36.003259952|1021=2|262=1000000000000000002|268=1|279=1|269=0|55=SYM00093|48=100000093|22=M|270=0.36223|271=8000|1023=3|10=180|
8=FIXT.1.1|9=000184|35=X|49=EXCHANGE|56=CLIENT|34=2317|57=SESSION1|52=20260630-07:30:34.970571079|1021=2|262=1000000000000000002|268=1|279=1|269=0|55=SYM00093|48=100000093|22=M|270=0.37145|271=600|1023=2|10=139|
8=FIXT.1.1|9=76|35=0|34=39|49=CLIENT|56=EXCHANGE|52=20260630-07:30:34.155515174|50=SESSION1|10=146|
8=FIXT.1.1|9=000184|35=X|49=EXCHANGE|56=CLIENT|34=2316|57=SESSION1|52=20260630-07:30:33.932816830|1021=2|262=1000000000000000002|268=1|279=1|269=0|55=SYM00093|48=100000093|22=M|270=0.39800|271=400|1023=1|10=129|
8=FIXT.1.1|9=000236|35=X|49=EXCHANGE|56=CLIENT|34=2315|57=SESSION1|52=20260630-07:30:31.848685805|262=1000000000000000002|268=1|279=0|269=2|278=0000000000000023|55=SYM00093|48=100000093|22=M|270=0.43740|271=700|273=05:17:04.848104837|574=4|2446=1|7554=552|10=141|
8=FIXT.1.1|9=000236|35=X|49=EXCHANGE|56=CLIENT|34=2314|57=SESSION1|52=20260630-07:30:31.848113822|262=1000000000000000002|268=1|279=0|269=2|278=0000000000000024|55=SYM00093|48=100000093|22=M|270=0.43434|271=300|273=05:17:04.848104837|574=4|2446=1|7554=551|10=121|
8=FIXT.1.1|9=000282|35=X|49=EXCHANGE|56=CLIENT|34=2313|57=SESSION1|52=20260630-07:30:31.848393789|1021=2|262=1000000000000000002|268=3|279=2|269=1|55=SYM00093|48=100000093|22=M|1023=1|279=2|269=1|55=SYM00093|48=100000093|22=M|1023=1|279=0|269=1|55=SYM00093|48=100000093|22=M|270=0.43740|271=300|1023=1|10=033|
8=FIXT.1.1|9=000237|35=X|49=EXCHANGE|56=CLIENT|34=2312|57=SESSION1|52=20260630-07:30:31.823412190|262=1000000000000000002|268=1|279=0|269=2|278=0000000000000025|55=SYM00093|48=100000093|22=M|270=0.41906|271=1000|273=05:17:04.822705135|574=4|2446=1|7554=550|10=151|
8=FIXT.1.1|9=000164|35=X|49=EXCHANGE|56=CLIENT|34=2311|57=SESSION1|52=20260630-07:30:31.823102861|1021=2|262=1000000000000000002|268=1|279=2|269=1|55=SYM00093|48=100000093|22=M|1023=1|10=204|
8=FIXT.1.1|9=000150|35=CO|49=EXCHANGE|56=CLIENT|34=2310|57=SESSION1|52=20260630-07:30:13.781598059|324=1000000000000000001|1301=EXMKT|146=1|55=SYM00002|48=100000002|22=M|10=251|
8=FIXT.1.1|9=000168|35=CO|49=EXCHANGE|56=CLIENT|34=2309|57=SESSION1|52=20260630-07:30:13.781285108|324=1000000000000000001|1301=EXMKT|625=OPEN1_E|146=1|55=SYM00002|48=100000002|22=M|292=o|10=044|
8=FIXT.1.1|9=000186|35=X|49=EXCHANGE|56=CLIENT|34=2308|57=SESSION1|52=20260630-07:30:05.534259199|1021=2|262=1000000000000000002|268=1|279=1|269=0|55=SYM00094|48=100000094|22=M|270=1.67046|271=10000|1023=5|10=241|
8=FIXT.1.1|9=000185|35=X|49=EXCHANGE|56=CLIENT|34=2307|57=SESSION1|52=20260630-07:30:04.523569594|1021=2|262=1000000000000000002|268=1|279=1|269=0|55=SYM00094|48=100000094|22=M|270=1.62049|271=6400|1023=4|10=197|
8=FIXT.1.1|9=76|35=0|34=38|49=CLIENT|56=EXCHANGE|52=20260630-07:30:03.740700540|50=SESSION1|10=134|
8=FIXT.1.1|9=000185|35=X|49=EXCHANGE|56=CLIENT|34=2306|57=SESSION1|52=20260630-07:30:03.517009930|1021=2|262=1000000000000000002|268=1|279=1|269=0|55=SYM00094|48=100000094|22=M|270=1.66022|271=2300|1023=1|10=168|
8=FIXT.1.1|9=000186|35=X|49=EXCHANGE|56=CLIENT|34=2305|57=SESSION1|52=20260630-07:30:00.014233796|1021=2|262=1000000000000000002|268=1|279=1|269=0|55=SYM00094|48=100000094|22=M|270=1.67647|271=60400|1023=2|10=234|
8=FIXT.1.1|9=000150|35=CO|49=EXCHANGE|56=CLIENT|34=2304|57=SESSION1|52=20260630-07:29:53.143379897|324=1000000000000000001|1301=EXMKT|146=1|55=SYM00095|48=100000095|22=M|10=033|
8=FIXT.1.1|9=000168|35=CO|49=EXCHANGE|56=CLIENT|34=2303|57=SESSION1|52=20260630-07:29:53.142073549|324=1000000000000000001|1301=EXMKT|625=OPEN1_E|146=1|55=SYM00095|48=100000095|22=M|292=o|10=069|
8=FIXT.1.1|9=117|35=0|34=37|49=CLIENT|56=EXCHANGE|52=20260630-07:29:32.738953530|50=SESSION1|112=00000000-0000-0000-0000-000000000029|10=092|
8=FIXT.1.1|9=000119|35=1|49=EXCHANGE|56=CLIENT|34=2302|57=SESSION1|52=20260630-07:29:32.516945966|112=00000000-0000-0000-0000-000000000029|10=091|
8=FIXT.1.1|9=000186|35=X|49=EXCHANGE|56=CLIENT|34=2301|57=SESSION1|52=20260630-07:29:06.674597665|1021=2|262=1000000000000000002|268=1|279=1|269=1|55=SYM00096|48=100000096|22=M|270=28.37940|271=8000|1023=2|10=013|
8=FIXT.1.1|9=000186|35=X|49=EXCHANGE|56=CLIENT|34=2300|57=SESSION1|52=20260630-07:29:05.767416949|1021=2|262=1000000000000000002|268=1|279=1|269=1|55=SYM00096|48=100000096|22=M|270=30.32005|271=6000|1023=5|10=246|
8=FIXT.1.1|9=000186|35=X|49=EXCHANGE|56=CLIENT|34=2299|57=SESSION1|52=20260630-07:29:04.843281741|1021=2|262=1000000000000000002|268=1|279=1|269=1|55=SYM00096|48=100000096|22=M|270=31.07280|271=4000|1023=4|10=252|
8=FIXT.1.1|9=000186|35=X|49=EXCHANGE|56=CLIENT|34=2298|57=SESSION1|52=20260630-07:29:03.030440043|1021=2|262=1000000000000000002|268=1|279=1|269=1|55=SYM00096|48=100000096|22=M|270=30.31800|271=2000|1023=3|10=221|
8=FIXT.1.1|9=000185|35=X|49=EXCHANGE|56=CLIENT|34=2297|57=SESSION1|52=20260630-07:29:01.297394102|1021=2|262=1000000000000000002|268=1|279=1|269=1|55=SYM00096|48=100000096|22=M|270=25.29165|271=200|1023=1|10=201|
8=FIXT.1.1|9=117|35=0|34=36|49=CLIENT|56=EXCHANGE|52=20260630-07:28:57.330012018|50=SESSION1|112=00000000-0000-0000-0000-000000000030|10=064|
8=FIXT.1.1|9=000119|35=1|49=EXCHANGE|56=CLIENT|34=2296|57=SESSION1|52=20260630-07:28:57.108032290|112=00000000-0000-0000-0000-000000000030|10=075|
8=FIXT.1.1|9=000186|35=X|49=EXCHANGE|56=CLIENT|34=2295|57=SESSION1|52=20260630-07:28:38.323231493|1021=2|262=1000000000000000002|268=1|279=0|269=1|55=SYM00097|48=100000097|22=M|270=106.76900|271=400|1023=2|10=253|
8=FIXT.1.1|9=000238|35=X|49=EXCHANGE|56=CLIENT|34=2294|57=SESSION1|52=20260630-07:28:38.237512535|262=1000000000000000002|268=1|279=0|269=2|278=0000000000000026|55=SYM00097|48=100000097|22=M|270=128.27500|271=200|273=05:15:11.237172068|574=4|2446=2|7554=544|10=244|
8=FIXT.1.1|9=000306|35=X|49=EXCHANGE|56=CLIENT|34=2293|57=SESSION1|52=20260630-07:28:38.237717850|1021=2|262=1000000000000000002|268=3|279=2|269=0|55=SYM00097|48=100000097|22=M|1023=1|279=0|269=0|55=SYM00097|48=100000097|22=M|270=97.78230|271=600|1023=10|279=0|269=1|55=SYM00097|48=100000097|22=M|270=108.36960|271=100|1023=1|10=184|
8=FIXT.1.1|9=000238|35=X|49=EXCHANGE|56=CLIENT|34=2292|57=SESSION1|52=20260630-07:28:37.376438217|262=1000000000000000002|268=1|279=0|269=2|278=0000000000000027|55=SYM00097|48=100000097|22=M|270=128.27500|271=200|273=05:15:10.375945133|574=4|2446=2|7554=543|10=252|
8=FIXT.1.1|9=000186|35=X|49=EXCHANGE|56=CLIENT|34=2291|57=SESSION1|52=20260630-07:28:37.376416907|1021=2|262=1000000000000000002|268=1|279=1|269=0|55=SYM00097|48=100000097|22=M|270=128.27500|271=200|1023=1|10=254|
8=FIXT.1.1|9=000238|35=X|49=EXCHANGE|56=CLIENT|34=2290|57=SESSION1|52=20260630-07:28:35.639344112|262=1000000000000000002|268=1|279=0|269=2|278=0000000000000028|55=SYM00097|48=100000097|22=M|270=128.27500|271=100|273=05:15:08.639228068|574=4|2446=2|7554=542|10=250|
8=FIXT.1.1|9=000186|35=X|49=EXCHANGE|56=CLIENT|34=2289|57=SESSION1|52=20260630-07:28:35.639115321|1021=2|262=1000000000000000002|268=1|279=1|269=0|55=SYM00097|48=100000097|22=M|270=128.27500|271=400|1023=1|10=249|
8=FIXT.1.1|9=000187|35=X|49=EXCHANGE|56=CLIENT|34=2288|57=SESSION1|52=20260630-07:28:33.919573920|1021=2|262=1000000000000000002|268=1|279=1|269=0|55=SYM00097|48=100000097|22=M|270=100.96265|271=800|1023=10|10=061|
8=FIXT.1.1|9=000185|35=X|49=EXCHANGE|56=CLIENT|34=2287|57=SESSION1|52=20260630-07:28:32.204623247|1021=2|262=1000000000000000002|268=1|279=1|269=0|55=SYM00097|48=100000097|22=M|270=98.06090|271=400|1023=7|10=207|
8=FIXT.1.1|9=000186|35=X|49=EXCHANGE|56=CLIENT|34=2286|57=SESSION1|52=20260630-07:28:31.348596676|1021=2|262=1000000000000000002|268=1|279=1|269=0|55=SYM00097|48=100000097|22=M|270=102.29170|271=400|1023=6|10=011|
8=FIXT.1.1|9=000186|35=X|49=EXCHANGE|56=CLIENT|34=2285|57=SESSION1|52=20260630-07:28:29.662297424|1021=2|262=1000000000000000002|268=1|279=1|269=0|55=SYM00097|48=100000097|22=M|270=100.77000|271=200|1023=9|10=255|
8=FIXT.1.1|9=000186|35=X|49=EXCHANGE|56=CLIENT|34=2284|57=SESSION1|52=20260630-07:28:29.639274474|1021=2|262=1000000000000000002|268=1|279=1|269=0|55=SYM00097|48=100000097|22=M|270=102.11805|271=600|1023=8|10=008|
8=FIXT.1.1|9=000186|35=X|49=EXCHANGE|56=CLIENT|34=2283|57=SESSION1|52=20260630-07:28:28.797468556|1021=2|262=1000000000000000002|268=1|279=1|269=0|55=SYM00097|48=100000097|22=M|270=108.89625|271=800|1023=2|10=034|
8=FIXT.1.1|9=000186|35=X|49=EXCHANGE|56=CLIENT|34=2282|57=SESSION1|52=20260630-07:28:27.947691468|1021=2|262=1000000000000000002|268=1|279=1|269=0|55=SYM00097|48=100000097|22=M|270=105.13210|271=600|1023=3|10=002|
8=FIXT.1.1|9=000186|35=X|49=EXCHANGE|56=CLIENT|34=2281|57=SESSION1|52=20260630-07:28:27.105260534|1021=2|262=1000000000000000002|268=1|279=1|269=0|55=SYM00097|48=100000097|22=M|270=104.90700|271=400|1023=5|10=237|
8=FIXT.1.1|9=000186|35=X|49=EXCHANGE|56=CLIENT|34=2280|57=SESSION1|52=20260630-07:28:25.503688380|1021=2|262=1000000000000000002|268=1|279=1|269=0|55=SYM00097|48=100000097|22=M|270=102.29170|271=300|1023=6|10=250|
8=FIXT.1.1|9=76|35=0|34=35|49=CLIENT|56=EXCHANGE|52=20260630-07:28:21.921013717|50=SESSION1|10=142|
8=FIXT.1.1|9=000186|35=X|49=EXCHANGE|56=CLIENT|34=2279|57=SESSION1|52=20260630-07:28:21.698133437|1021=2|262=1000000000000000002|268=1|279=1|269=0|55=SYM00097|48=100000097|22=M|270=103.73000|271=600|1023=4|10=250|
8=FIXT.1.1|9=000185|35=X|49=EXCHANGE|56=CLIENT|34=2278|57=SESSION1|52=20260630-07:28:15.452525700|1021=2|262=1000000000000000002|268=1|279=1|269=0|55=SYM00002|48=100000002|22=M|270=60.63645|271=800|1023=5|10=180|
8=FIXT.1.1|9=000185|35=X|49=EXCHANGE|56=CLIENT|34=2277|57=SESSION1|52=20260630-07:28:15.425424522|1021=2|262=1000000000000000002|268=1|279=1|269=0|55=SYM00002|48=100000002|22=M|270=60.93395|271=600|1023=4|10=181|
8=FIXT.1.1|9=000185|35=X|49=EXCHANGE|56=CLIENT|34=2276|57=SESSION1|52=20260630-07:28:14.601961955|1021=2|262=1000000000000000002|268=1|279=1|269=0|55=SYM00002|48=100000002|22=M|270=58.51915|271=400|1023=3|10=187|
8=FIXT.1.1|9=000167|35=CO|49=EXCHANGE|56=CLIENT|34=2275|57=SESSION1|52=20260630-07:28:13.781419515|324=1000000000000000001|1301=EXMKT|146=1|55=SYM00002|48=100000002|22=M|58=PRE-OPEN_CB_E|10=130|
8=FIXT.1.1|9=000174|35=CO|49=EXCHANGE|56=CLIENT|34=2274|57=SESSION1|52=20260630-07:28:13.780396301|324=1000000000000000001|1301=EXMKT|625=PRE-OPEN_CB_E|146=1|55=SYM00002|48=100000002|22=M|292=o|10=245|
8=FIXT.1.1|9=000185|35=X|49=EXCHANGE|56=CLIENT|34=2273|57=SESSION1|52=20260630-07:28:12.961822988|1021=2|262=1000000000000000002|268=1|279=1|269=0|55=SYM00002|48=100000002|22=M|270=61.48800|271=200|1023=2|10=183|
8=FIXT.1.1|9=000185|35=X|49=EXCHANGE|56=CLIENT|34=2272|57=SESSION1|52=20260630-07:28:10.512411959|1021=2|262=1000000000000000002|268=1|279=1|269=0|55=SYM00002|48=100000002|22=M|270=59.96760|271=600|1023=1|10=182|
8=FIXT.1.1|9=000185|35=X|49=EXCHANGE|56=CLIENT|34=2271|57=SESSION1|52=20260630-07:27:57.076195191|1021=2|262=1000000000000000002|268=1|279=1|269=0|55=SYM00095|48=100000095|22=M|270=96.82560|271=800|1023=1|10=213|
8=FIXT.1.1|9=000167|35=CO|49=EXCHANGE|56=CLIENT|34=2270|57=SESSION1|52=20260630-07:27:53.143367957|324=1000000000000000001|1301=EXMKT|146=1|55=SYM00095|48=100000095|22=M|58=PRE-OPEN_CB_E|10=156|
8=FIXT.1.1|9=000174|35=CO|49=EXCHANGE|56=CLIENT|34=2269|57=SESSION1|52=20260630-07:27:53.143650105|324=1000000000000000001|1301=EXMKT|625=PRE-OPEN_CB_E|146=1|55=SYM00095|48=100000095|22=M|292=o|10=008|
8=FIXT.1.1|9=76|35=0|34=34|49=CLIENT|56=EXCHANGE|52=20260630-07:27:47.966672646|50=SESSION1|10=169|
8=FIXT.1.1|9=000186|35=X|49=EXCHANGE|56=CLIENT|34=2268|57=SESSION1|52=20260630-07:27:47.357923365|1021=2|262=1000000000000000002|268=1|279=1|269=1|55=SYM00095|48=100000095|22=M|270=95.04720|271=2600|1023=1|10=007|
8=FIXT.1.1|9=000186|35=X|49=EXCHANGE|56=CLIENT|34=2267|57=SESSION1|52=20260630-07:27:47.335426403|1021=2|262=1000000000000000002|268=1|279=1|269=1|55=SYM00098|48=100000098|22=M|270=12.19440|271=2800|1023=1|10=251|
8=FIXT.1.1|9=000186|35=X|49=EXCHANGE|56=CLIENT|34=2266|57=SESSION1|52=20260630-07:27:46.568026616|1021=2|262=1000000000000000002|268=1|279=1|269=1|55=SYM00098|48=100000098|22=M|270=12.60983|271=2600|1023=4|10=012|
8=FIXT.1.1|9=000186|35=X|49=EXCHANGE|56=CLIENT|34=2265|57=SESSION1|52=20260630-07:27:45.820287827|1021=2|262=1000000000000000002|268=1|279=1|269=1|55=SYM00098|48=100000098|22=M|270=12.43264|271=2400|1023=5|10=006|
8=FIXT.1.1|9=000186|35=X|49=EXCHANGE|56=CLIENT|34=2264|57=SESSION1|52=20260630-07:27:43.723610012|1021=2|262=1000000000000000002|268=1|279=1|269=1|55=SYM00098|48=100000098|22=M|270=11.95806|271=2200|1023=3|10=241|
8=FIXT.1.1|9=000186|35=X|49=EXCHANGE|56=CLIENT|34=2263|57=SESSION1|52=20260630-07:27:43.528058217|1021=2|262=1000000000000000002|268=1|279=1|269=1|55=SYM00098|48=100000098|22=M|270=12.04555|271=2800|1023=2|10=253|
8=FIXT.1.1|9=000186|35=X|49=EXCHANGE|56=CLIENT|34=2262|57=SESSION1|52=20260630-07:27:42.775262513|1021=2|262=1000000000000000002|268=1|279=1|269=0|55=SYM00098|48=100000098|22=M|270=11.30652|271=2800|1023=4|10=248|
8=FIXT.1.1|9=000186|35=X|49=EXCHANGE|56=CLIENT|34=2261|57=SESSION1|52=20260630-07:27:42.015101169|1021=2|262=1000000000000000002|268=1|279=1|269=0|55=SYM00098|48=100000098|22=M|270=11.57247|271=2600|1023=3|10=239|
8=FIXT.1.1|9=000186|35=X|49=EXCHANGE|56=CLIENT|34=2260|57=SESSION1|52=20260630-07:27:41.213255073|1021=2|262=1000000000000000002|268=1|279=1|269=0|55=SYM00098|48=100000098|22=M|270=11.46842|271=2400|1023=2|10=237|
8=FIXT.1.1|9=000186|35=X|49=EXCHANGE|56=CLIENT|34=2259|57=SESSION1|52=20260630-07:27:39.725766338|1021=2|262=1000000000000000002|268=1|279=1|269=0|55=SYM00098|48=100000098|22=M|270=11.59298|271=2200|1023=1|10=021|
8=FIXT.1.1|9=000186|35=X|49=EXCHANGE|56=CLIENT|34=2258|57=SESSION1|52=20260630-07:27:21.972688731|1021=2|262=1000000000000000002|268=1|279=1|269=0|55=SYM00099|48=100000099|22=M|270=20.81775|271=2200|1023=2|10=013|
8=FIXT.1.1|9=000237|35=X|49=EXCHANGE|56=CLIENT|34=2257|57=SESSION1|52=20260630-07:27:21.947939110|262=1000000000000000002|268=1|279=0|269=2|278=0000000000000029|55=SYM00099|48=100000099|22=M|270=21.27216|271=800|273=05:13:54.946575270|574=4|2446=1|7554=541|10=214|
8=FIXT.1.1|9=000237|35=X|49=EXCHANGE|56=CLIENT|34=2256|57=SESSION1|52=20260630-07:27:21.947066487|262=1000000000000000002|268=1|279=0|269=2|278=000000000000002A|55=SYM00099|48=100000099|22=M|270=21.20922|271=300|273=05:13:54.946575270|574=4|2446=1|7554=540|10=220|
8=FIXT.1.1|9=000355|35=X|49=EXCHANGE|56=CLIENT|34=2255|57=SESSION1|52=20260630-07:27:21.946259971|1021=2|262=1000000000000000002|268=4|279=2|269=1|55=SYM00099|48=100000099|22=M|1023=1|279=2|269=1|55=SYM00099|48=100000099|22=M|1023=1|279=0|269=1|55=SYM00099|48=100000099|22=M|270=21.27216|271=300|1023=1|279=0|269=1|55=SYM00099|48=100000099|22=M|270=23.08316|271=3300|1023=10|10=011|
8=FIXT.1.1|9=000186|35=X|49=EXCHANGE|56=CLIENT|34=2254|57=SESSION1|52=20260630-07:27:21.214942162|1021=2|262=1000000000000000002|268=1|279=1|269=0|55=SYM00099|48=100000099|22=M|270=20.15092|271=1500|1023=1|10=235|
8=FIXT.1.1|9=000186|35=X|49=EXCHANGE|56=CLIENT|34=2253|57=SESSION1|52=20260630-07:27:20.506807167|1021=2|262=1000000000000000002|268=1|279=0|269=1|55=SYM00099|48=100000099|22=M|270=21.07046|271=1400|1023=3|10=244|
8=FIXT.1.1|9=000238|35=X|49=EXCHANGE|56=CLIENT|34=2252|57=SESSION1|52=20260630-07:27:19.754659105|262=1000000000000000002|268=1|279=0|269=2|278=000000000000002B|55=SYM00099|48=100000099|22=M|270=20.15092|271=1300|273=05:13:52.754384984|574=4|2446=2|7554=539|10=024|
8=FIXT.1.1|9=000185|35=X|49=EXCHANGE|56=CLIENT|34=2251|57=SESSION1|52=20260630-07:27:19.754697538|1021=2|262=1000000000000000002|268=1|279=1|269=0|55=SYM00099|48=100000099|22=M|270=20.15092|271=100|1023=1|10=208|
8=FIXT.1.1|9=76|35=0|34=33|49=CLIENT|56=EXCHANGE|52=20260630-07:27:17.845724558|50=SESSION1|10=161|
8=FIXT.1.1|9=000186|35=X|49=EXCHANGE|56=CLIENT|34=2250|57=SESSION1|52=20260630-07:27:17.622766125|1021=2|262=1000000000000000002|268=1|279=0|269=1|55=SYM00099|48=100000099|22=M|270=21.27216|271=1100|1023=2|10=241|
8=FIXT.1.1|9=000238|35=X|49=EXCHANGE|56=CLIENT|34=2249|57=SESSION1|52=20260630-07:27:16.218110035|262=1000000000000000002|268=1|279=0|269=2|278=000000000000002C|55=SYM00099|48=100000099|22=M|270=21.27216|271=1100|273=05:13:49.218131708|574=4|2446=2|7554=538|10=247|
8=FIXT.1.1|9=000234|35=X|49=EXCHANGE|56=CLIENT|34=2248|57=SESSION1|52=20260630-07:27:16.218701668|1021=2|262=1000000000000000002|268=2|279=2|269=0|55=SYM00099|48=100000099|22=M|1023=1|279=0|269=1|55=SYM00099|48=100000099|22=M|270=21.20922|271=300|1023=1|10=022|
8=FIXT.1.1|9=000186|35=X|49=EXCHANGE|56=CLIENT|34=2247|57=SESSION1|52=20260630-07:27:16.190178031|1021=2|262=1000000000000000002|268=1|279=1|269=1|55=SYM00100|48=100000100|22=M|270=18.83115|271=2800|1023=2|10=220|
8=FIXT.1.1|9=000186|35=X|49=EXCHANGE|56=CLIENT|34=2246|57=SESSION1|52=20260630-07:27:14.923146965|1021=2|262=1000000000000000002|268=1|279=1|269=1|55=SYM00100|48=100000100|22=M|270=18.34480|271=2600|1023=1|10=230|
8=FIXT.1.1|9=000236|35=X|49=EXCHANGE|56=CLIENT|34=2245|57=SESSION1|52=20260630-07:27:11.924084390|262=1000000000000000002|268=1|279=0|269=2|278=000000000000002D|55=SYM00094|48=100000094|22=M|270=1.66022|271=100|273=05:13:44.924369546|574=4|2446=2|7554=537|10=155|
8=FIXT.1.1|9=000184|35=X|49=EXCHANGE|56=CLIENT|34=2244|57=SESSION1|52=20260630-07:27:11.924421897|1021=2|262=1000000000000000002|268=1|279=1|269=0|55=SYM00094|48=100000094|22=M|270=1.66022|271=200|1023=1|10=134|
8=FIXT.1.1|9=000236|35=X|49=EXCHANGE|56=CLIENT|34=2243|57=SESSION1|52=20260630-07:27:00.827300079|262=1000000000000000002|268=1|279=0|269=2|278=000000000000002E|55=SYM00094|48=100000094|22=M|270=1.74808|271=100|273=05:13:33.827166498|574=4|2446=1|7554=536|10=159|
8=FIXT.1.1|9=000184|35=X|49=EXCHANGE|56=CLIENT|34=2242|57=SESSION1|52=20260630-07:27:00.827862921|1021=2|262=1000000000000000002|268=1|279=1|269=1|55=SYM00094|48=100000094|22=M|270=1.74808|271=800|1023=1|10=147|
8=FIXT.1.1|9=000184|35=X|49=EXCHANGE|56=CLIENT|34=2241|57=SESSION1|52=20260630-07:26:55.836975625|1021=2|262=1000000000000000002|268=1|279=1|269=1|55=SYM00094|48=100000094|22=M|270=1.74808|271=900|1023=1|10=162|
8=FIXT.1.1|9=76|35=0|34=32|49=CLIENT|56=EXCHANGE|52=20260630-07:26:47.829210615|50=SESSION1|10=148|
8=FIXT.1.1|9=000185|35=X|49=EXCHANGE|56=CLIENT|34=2240|57=SESSION1|52=20260630-07:26:47.606135694|1021=2|262=1000000000000000002|268=1|279=1|269=1|55=SYM00094|48=100000094|22=M|270=1.74808|271=1000|1023=1|10=192|
8=FIXT.1.1|9=000236|35=X|49=EXCHANGE|56=CLIENT|34=2239|57=SESSION1|52=20260630-07:26:34.539829060|262=1000000000000000002|268=1|279=0|269=2|278=000000000000002F|55=SYM00094|48=100000094|22=M|270=1.66022|271=100|273=05:13:07.539299038|574=4|2446=2|7554=535|10=164|
8=FIXT.1.1|9=000184|35=X|49=EXCHANGE|56=CLIENT|34=2238|57=SESSION1|52=20260630-07:26:34.539647439|1021=2|262=1000000000000000002|268=1|279=1|269=0|55=SYM00094|48=100000094|22=M|270=1.66022|271=300|1023=1|10=146|
8=FIXT.1.1|9=000184|35=X|49=EXCHANGE|56=CLIENT|34=2237|57=SESSION1|52=20260630-07:26:28.432627916|1021=2|262=1000000000000000002|268=1|279=1|269=0|55=SYM00094|48=100000094|22=M|270=1.66022|271=400|1023=1|10=139|
8=FIXT.1.1|9=000184|35=X|49=EXCHANGE|56=CLIENT|34=2236|57=SESSION1|52=20260630-07:26:24.628918617|1021=2|262=1000000000000000002|268=1|279=1|269=0|55=SYM00094|48=100000094|22=M|270=1.66022|271=500|1023=1|10=143|
8=FIXT.1.1|9=000185|35=X|49=EXCHANGE|56=CLIENT|34=2235|57=SESSION1|52=20260630-07:26:14.729586186|1021=2|262=1000000000000000002|268=1|279=1|269=1|55=SYM00101|48=100000101|22=M|270=17.57922|271=400|1023=2|10=189|
8=FIXT.1.1|9=76|35=0|34=31|49=CLIENT|56=EXCHANGE|52=20260630-07:26:14.329280941|50=SESSION1|10=145|
8=FIXT.1.1|9=000184|35=X|49=EXCHANGE|56=CLIENT|34=2234|57=SESSION1|52=20260630-07:26:14.106027145|1021=2|262=1000000000000000002|268=1|279=1|269=0|55=SYM00094|48=100000094|22=M|270=1.66022|271=600|1023=1|10=119|
8=FIXT.1.1|9=000186|35=X|49=EXCHANGE|56=CLIENT|34=2233|57=SESSION1|52=20260630-07:26:12.717542476|1021=2|262=1000000000000000002|268=1|279=1|269=1|55=SYM00101|48=100000101|22=M|270=17.35856|271=1600|1023=3|10=231|
8=FIXT.1.1|9=000186|35=X|49=EXCHANGE|56=CLIENT|34=2232|57=SESSION1|52=20260630-07:26:11.842449295|1021=2|262=1000000000000000002|268=1|279=1|269=1|55=SYM00101|48=100000101|22=M|270=17.23096|271=1600|1023=1|10=224|
8=FIXT.1.1|9=000184|35=X|49=EXCHANGE|56=CLIENT|34=2231|57=SESSION1|52=20260630-07:26:06.454758379|1021=2|262=1000000000000000002|268=1|279=1|269=0|55=SYM00094|48=100000094|22=M|270=1.66022|271=500|1023=1|10=142|
8=FIXT.1.1|9=000236|35=X|49=EXCHANGE|56=CLIENT|34=2230|57=SESSION1|52=20260630-07:25:57.502292032|262=1000000000000000002|268=1|279=0|269=2|278=0000000000000030|55=SYM00094|48=100000094|22=M|270=1.74808|271=100|273=05:12:30.502165083|574=4|2446=1|7554=534|10=107|
8=FIXT.1.1|9=000184|35=X|49=EXCHANGE|56=CLIENT|34=2229|57=SESSION1|52=20260630-07:25:57.502596134|1021=2|262=1000000000000000002|268=1|279=1|269=1|55=SYM00094|48=100000094|22=M|270=1.74808|271=900|1023=1|10=153|
8=FIXT.1.1|9=117|35=0|34=30|49=CLIENT|56=EXCHANGE|52=20260630-07:25:43.306874925|50=SESSION1|112=00000000-0000-0000-0000-000000000031|10=077|
8=FIXT.1.1|9=000119|35=1|49=EXCHANGE|56=CLIENT|34=2228|57=SESSION1|52=20260630-07:25:43.084053161|112=00000000-0000-0000-0000-000000000031|10=066|
8=FIXT.1.1|9=000185|35=X|49=EXCHANGE|56=CLIENT|34=2227|57=SESSION1|52=20260630-07:25:27.923423472|1021=2|262=1000000000000000002|268=1|279=1|269=1|55=SYM00102|48=100000102|22=M|270=1.64804|271=2400|1023=4|10=173|
8=FIXT.1.1|9=000185|35=X|49=EXCHANGE|56=CLIENT|34=2226|57=SESSION1|52=20260630-07:25:27.727468076|1021=2|262=1000000000000000002|268=1|279=1|269=1|55=SYM00102|48=100000102|22=M|270=1.62454|271=8800|1023=3|10=191|
8=FIXT.1.1|9=000185|35=X|49=EXCHANGE|56=CLIENT|34=2225|57=SESSION1|52=20260630-07:25:27.249111281|1021=2|262=1000000000000000002|268=1|279=1|269=1|55=SYM00102|48=100000102|22=M|270=1.58032|271=1600|1023=1|10=158|
8=FIXT.1.1|9=000185|35=X|49=EXCHANGE|56=CLIENT|34=2224|57=SESSION1|52=20260630-07:25:26.523397413|1021=2|262=1000000000000000002|268=1|279=1|269=1|55=SYM00102|48=100000102|22=M|270=1.62454|271=6600|1023=3|10=174|
8=FIXT.1.1|9=000185|35=X|49=EXCHANGE|56=CLIENT|34=2223|57=SESSION1|52=20260630-07:25:26.364415348|1021=2|262=1000000000000000002|268=1|279=1|269=1|55=SYM00102|48=100000102|22=M|270=1.63328|271=2600|1023=2|10=170|
8=FIXT.1.1|9=000236|35=X|49=EXCHANGE|56=CLIENT|34=2222|57=SESSION1|52=20260630-07:25:25.456048755|262=1000000000000000002|268=1|279=0|269=2|278=0000000000000031|55=SYM00102|48=100000102|22=M|270=1.58032|271=200|273=05:11:58.456515819|574=4|2446=1|7554=533|10=117|
8=FIXT.1.1|9=000184|35=X|49=EXCHANGE|56=CLIENT|34=2221|57=SESSION1|52=20260630-07:25:25.456007648|1021=2|262=1000000000000000002|268=1|279=1|269=1|55=SYM00102|48=100000102|22=M|270=1.58032|271=400|1023=1|10=111|
8=FIXT.1.1|9=000236|35=X|49=EXCHANGE|56=CLIENT|34=2220|57=SESSION1|52=20260630-07:25:24.916507632|262=1000000000000000002|268=1|279=0|269=2|278=0000000000000032|55=SYM00102|48=100000102|22=M|270=1.58032|271=200|273=05:11:57.915748967|574=4|2446=1|7554=532|10=120|
8=FIXT.1.1|9=000184|35=X|49=EXCHANGE|56=CLIENT|34=2219|57=SESSION1|52=20260630-07:25:24.916858849|1021=2|262=1000000000000000002|268=1|279=1|269=1|55=SYM00102|48=100000102|22=M|270=1.58032|271=600|1023=1|10=137|
8=FIXT.1.1|9=000236|35=X|49=EXCHANGE|56=CLIENT|34=2218|57=SESSION1|52=20260630-07:25:23.923534502|262=1000000000000000002|268=1|279=0|269=2|278=0000000000000033|55=SYM00102|48=100000102|22=M|270=1.58032|271=200|273=05:11:56.923348933|574=4|2446=1|7554=531|10=107|
8=FIXT.1.1|9=000184|35=X|49=EXCHANGE|56=CLIENT|34=2217|57=SESSION1|52=20260630-07:25:23.923873818|1021=2|262=1000000000000000002|268=1|279=1|269=1|55=SYM00102|48=100000102|22=M|270=1.58032|271=800|1023=1|10=127|
8=FIXT.1.1|9=000236|35=X|49=EXCHANGE|56=CLIENT|34=2216|57=SESSION1|52=20260630-07:25:23.881059501|262=1000000000000000002|268=1|279=0|269=2|278=0000000000000034|55=SYM00102|48=100000102|22=M|270=1.58032|271=200|273=05:11:56.880980972|574=4|2446=1|7554=530|10=116|
8=FIXT.1.1|9=000185|35=X|49=EXCHANGE|56=CLIENT|34=2215|57=SESSION1|52=20260630-07:25:23.881106203|1021=2|262=1000000000000000002|268=1|279=1|269=1|55=SYM00102|48=100000102|22=M|270=1.58032|271=1000|1023=1|10=147|
8=FIXT.1.1|9=000184|35=X|49=EXCHANGE|56=CLIENT|34=2214|57=SESSION1|52=20260630-07:25:19.199028371|1021=2|262=1000000000000000002|268=1|279=1|269=1|55=SYM00103|48=100000103|22=M|270=1.34109|271=400|1023=1|10=117|
8=FIXT.1.1|9=000184|35=X|49=EXCHANGE|56=CLIENT|34=2213|57=SESSION1|52=20260630-07:25:18.768140073|1021=2|262=1000000000000000002|268=1|279=1|269=1|55=SYM00103|48=100000103|22=M|270=1.37821|271=400|1023=2|10=116|
8=FIXT.1.1|9=000184|35=X|49=EXCHANGE|56=CLIENT|34=2212|57=SESSION1|52=20260630-07:25:16.657193062|1021=2|262=1000000000000000002|268=1|279=1|269=0|55=SYM00103|48=100000103|22=M|270=1.33124|271=400|1023=2|10=107|
8=FIXT.1.1|9=000184|35=X|49=EXCHANGE|56=CLIENT|34=2211|57=SESSION1|52=20260630-07:25:16.256860487|1021=2|262=1000000000000000002|268=1|279=1|269=0|55=SYM00103|48=100000103|22=M|270=1.36245|271=400|1023=1|10=119|
8=FIXT.1.1|9=117|35=0|34=29|49=CLIENT|56=EXCHANGE|52=20260630-07:25:07.898361180|50=SESSION1|112=00000000-0000-0000-0000-000000000032|10=086|
8=FIXT.1.1|9=000119|35=1|49=EXCHANGE|56=CLIENT|34=2210|57=SESSION1|52=20260630-07:25:07.676157443|112=00000000-0000-0000-0000-000000000032|10=073|
8=FIXT.1.1|9=000184|35=X|49=EXCHANGE|56=CLIENT|34=2209|57=SESSION1|52=20260630-07:24:55.323678959|1021=2|262=1000000000000000002|268=1|279=1|269=1|55=SYM00094|48=100000094|22=M|270=1.76476|271=400|1023=2|10=164|
8=FIXT.1.1|9=000185|35=X|49=EXCHANGE|56=CLIENT|34=2208|57=SESSION1|52=20260630-07:24:55.138810014|1021=2|262=1000000000000000002|268=1|279=0|269=1|55=SYM00094|48=100000094|22=M|270=1.74808|271=1000|1023=1|10=178|
8=FIXT.1.1|9=000182|35=X|49=EXCHANGE|56=CLIENT|34=2207|57=SESSION1|52=20260630-07:24:44.718818335|1021=2|262=1000000000000000002|268=1|279=0|269=1|55=SYM00104|48=100000104|22=M|270=1.07635|271=1|1023=1|10=024|
8=FIXT.1.1|9=117|35=0|34=28|49=CLIENT|56=EXCHANGE|52=20260630-07:24:32.489085823|50=SESSION1|112=00000000-0000-0000-0000-000000000033|10=086|
8=FIXT.1.1|9=000119|35=1|49=EXCHANGE|56=CLIENT|34=2206|57=SESSION1|52=20260630-07:24:32.267325563|112=00000000-0000-0000-0000-000000000033|10=072|
8=FIXT.1.1|9=000230|35=X|49=EXCHANGE|56=CLIENT|34=2205|57=SESSION1|52=20260630-07:24:16.041855100|262=1000000000000000002|268=1|279=0|269=2|278=0000000000000035|55=SYM00094|48=100000094|22=M|270=1.66022|271=2100|273=05:10:49.039017738|574=5|7554=527|10=096|
8=FIXT.1.1|9=000282|35=X|49=EXCHANGE|56=CLIENT|34=2204|57=SESSION1|52=20260630-07:24:16.041374321|1021=2|262=1000000000000000002|268=3|279=1|269=0|55=SYM00094|48=100000094|22=M|270=1.66022|271=400|1023=1|279=2|269=1|55=SYM00094|48=100000094|22=M|1023=1|279=2|269=1|55=SYM00094|48=100000094|22=M|1023=1|10=010|
8=FIXT.1.1|9=000150|35=CO|49=EXCHANGE|56=CLIENT|34=2203|57=SESSION1|52=20260630-07:24:16.041975034|324=1000000000000000001|1301=EXMKT|146=1|55=SYM00094|48=100000094|22=M|10=005|
8=FIXT.1.1|9=000168|35=CO|49=EXCHANGE|56=CLIENT|34=2202|57=SESSION1|52=20260630-07:24:16.040600856|324=1000000000000000001|1301=EXMKT|625=OPEN1_E|146=1|55=SYM00094|48=100000094|22=M|292=o|10=053|
8=FIXT.1.1|9=000186|35=X|49=EXCHANGE|56=CLIENT|34=2201|57=SESSION1|52=20260630-07:24:10.811029463|1021=2|262=1000000000000000002|268=1|279=1|269=0|55=SYM00105|48=100000105|22=M|270=16.52562|271=2400|1023=3|10=211|
8=FIXT.1.1|9=000186|35=X|49=EXCHANGE|56=CLIENT|34=2200|57=SESSION1|52=20260630-07:24:10.790108322|1021=2|262=1000000000000000002|268=1|279=1|269=0|55=SYM00105|48=100000105|22=M|270=16.62304|271=1600|1023=2|10=203|
8=FIXT.1.1|9=000238|35=X|49=EXCHANGE|56=CLIENT|34=2199|57=SESSION1|52=20260630-07:24:10.768863699|262=1000000000000000002|268=1|279=0|269=2|278=0000000000000036|55=SYM00105|48=100000105|22=M|270=16.89480|271=2100|273=05:10:43.768442062|574=4|2446=1|7554=524|10=000|
8=FIXT.1.1|9=000164|35=X|49=EXCHANGE|56=CLIENT|34=2198|57=SESSION1|52=20260630-07:24:10.768022242|1021=2|262=1000000000000000002|268=1|279=2|269=1|55=SYM00105|48=100000105|22=M|1023=1|10=207|
8=FIXT.1.1|9=000185|35=X|49=EXCHANGE|56=CLIENT|34=2197|57=SESSION1|52=20260630-07:24:10.723966926|1021=2|262=1000000000000000002|268=1|279=1|269=1|55=SYM00105|48=100000105|22=M|270=17.35856|271=400|1023=4|10=200|
8=FIXT.1.1|9=000185|35=X|49=EXCHANGE|56=CLIENT|34=2196|57=SESSION1|52=20260630-07:24:10.544689627|1021=2|262=1000000000000000002|268=1|279=1|269=1|55=SYM00105|48=100000105|22=M|270=17.19872|271=400|1023=3|10=199|
8=FIXT.1.1|9=000186|35=X|49=EXCHANGE|56=CLIENT|34=2195|57=SESSION1|52=20260630-07:24:10.397250983|1021=2|262=1000000000000000002|268=1|279=0|269=1|55=SYM00105|48=100000105|22=M|270=16.89480|271=2100|1023=1|10=239|
8=FIXT.1.1|9=000187|35=X|49=EXCHANGE|56=CLIENT|34=2194|57=SESSION1|52=20260630-07:24:10.344435393|1021=2|262=1000000000000000002|268=1|279=1|269=1|55=SYM00105|48=100000105|22=M|270=17.02575|271=22800|1023=1|10=024|
8=FIXT.1.1|9=000185|35=X|49=EXCHANGE|56=CLIENT|34=2193|57=SESSION1|52=20260630-07:24:09.389805992|1021=2|262=1000000000000000002|268=1|279=1|269=0|55=SYM00094|48=100000094|22=M|270=1.66022|271=2500|1023=1|10=202|
8=FIXT.1.1|9=000184|35=X|49=EXCHANGE|56=CLIENT|34=2192|57=SESSION1|52=20260630-07:24:09.367644381|1021=2|262=1000000000000000002|268=1|279=1|269=0|55=SYM00094|48=100000094|22=M|270=1.64804|271=400|1023=6|10=149|
8=FIXT.1.1|9=000185|35=X|49=EXCHANGE|56=CLIENT|34=2191|57=SESSION1|52=20260630-07:24:09.345040670|1021=2|262=1000000000000000002|268=1|279=1|269=0|55=SYM00094|48=100000094|22=M|270=1.67046|271=6000|1023=5|10=186|
8=FIXT.1.1|9=000185|35=X|49=EXCHANGE|56=CLIENT|34=2190|57=SESSION1|52=20260630-07:24:09.324469876|1021=2|262=1000000000000000002|268=1|279=1|269=0|55=SYM00094|48=100000094|22=M|270=1.62049|271=3400|1023=4|10=203|
8=FIXT.1.1|9=000184|35=X|49=EXCHANGE|56=CLIENT|34=2189|57=SESSION1|52=20260630-07:24:09.164659296|1021=2|262=1000000000000000002|268=1|279=1|269=0|55=SYM00094|48=100000094|22=M|270=1.70891|271=400|1023=3|10=161|
8=FIXT.1.1|9=000188|35=X|49=EXCHANGE|56=CLIENT|34=2188|57=SESSION1|52=20260630-07:24:08.800478669|1021=2|262=1000000000000000002|268=1|279=1|269=0|55=SYM00106|48=100000106|22=M|270=36.01090|271=779800|1023=1|10=105|
8=FIXT.1.1|9=000185|35=X|49=EXCHANGE|56=CLIENT|34=2187|57=SESSION1|52=20260630-07:24:08.758554338|1021=2|262=1000000000000000002|268=1|279=1|269=1|55=SYM00107|48=100000107|22=M|270=16.32278|271=400|1023=1|10=199|
8=FIXT.1.1|9=000185|35=X|49=EXCHANGE|56=CLIENT|34=2186|57=SESSION1|52=20260630-07:24:08.346409252|1021=2|262=1000000000000000002|268=1|279=1|269=0|55=SYM00107|48=100000107|22=M|270=15.41710|271=600|1023=1|10=176|
8=FIXT.1.1|9=000188|35=X|49=EXCHANGE|56=CLIENT|34=2185|57=SESSION1|52=20260630-07:24:05.366584545|1021=2|262=1000000000000000002|268=1|279=1|269=0|55=SYM00082|48=100000082|22=M|270=18.83115|271=978800|1023=1|10=112|
8=FIXT.1.1|9=000188|35=X|49=EXCHANGE|56=CLIENT|34=2184|57=SESSION1|52=20260630-07:24:05.344162072|1021=2|262=1000000000000000002|268=1|279=1|269=0|55=SYM00082|48=100000082|22=M|270=18.83115|271=492400|1023=1|10=081|
8=FIXT.1.1|9=000237|35=X|49=EXCHANGE|56=CLIENT|34=2183|57=SESSION1|52=20260630-07:24:04.187614303|262=1000000000000000002|268=1|279=0|269=2|278=0000000000000037|55=SYM00083|48=100000083|22=M|270=6.40250|271=1900|273=05:10:37.186881183|574=4|2446=2|7554=519|10=186|
8=FIXT.1.1|9=000184|35=X|49=EXCHANGE|56=CLIENT|34=2182|57=SESSION1|52=20260630-07:24:04.187024293|1021=2|262=1000000000000000002|268=1|279=1|269=0|55=SYM00083|48=100000083|22=M|270=6.40250|271=400|1023=1|10=122|
8=FIXT.1.1|9=000237|35=X|49=EXCHANGE|56=CLIENT|34=2181|57=SESSION1|52=20260630-07:24:03.944480499|262=1000000000000000002|268=1|279=0|269=2|278=0000000000000038|55=SYM00083|48=100000083|22=M|270=6.40250|271=2000|273=05:10:36.944511884|574=4|2446=2|7554=518|10=192|
8=FIXT.1.1|9=000185|35=X|49=EXCHANGE|56=CLIENT|34=2180|57=SESSION1|52=20260630-07:24:03.944633727|1021=2|262=1000000000000000002|268=1|279=1|269=0|55=SYM00083|48=100000083|22=M|270=6.40250|271=2300|1023=1|10=178|
8=FIXT.1.1|9=000236|35=X|49=EXCHANGE|56=CLIENT|34=2179|57=SESSION1|52=20260630-07:24:03.924361508|262=1000000000000000002|268=1|279=0|269=2|278=0000000000000039|55=SYM00083|48=100000083|22=M|270=6.17904|271=300|273=05:10:36.923791127|574=4|2446=1|7554=517|10=144|
8=FIXT.1.1|9=000187|35=X|49=EXCHANGE|56=CLIENT|34=2178|57=SESSION1|52=20260630-07:24:03.923455735|1021=2|262=1000000000000000002|268=1|279=1|269=1|55=SYM00083|48=100000083|22=M|270=6.17904|271=149000|1023=1|10=045|
8=FIXT.1.1|9=000236|35=X|49=EXCHANGE|56=CLIENT|34=2177|57=SESSION1|52=20260630-07:24:03.780832705|262=1000000000000000002|268=1|279=0|269=2|278=000000000000003A|55=SYM00083|48=100000083|22=M|270=6.17904|271=100|273=05:10:36.780191463|574=4|2446=1|7554=516|10=147|
8=FIXT.1.1|9=000187|35=X|49=EXCHANGE|56=CLIENT|34=2176|57=SESSION1|52=20260630-07:24:03.780118985|1021=2|262=1000000000000000002|268=1|279=1|269=1|55=SYM00083|48=100000083|22=M|270=6.17904|271=149300|1023=1|10=050|
8=FIXT.1.1|9=000236|35=X|49=EXCHANGE|56=CLIENT|34=2175|57=SESSION1|52=20260630-07:24:03.725179509|262=1000000000000000002|268=1|279=0|269=2|278=000000000000003B|55=SYM00083|48=100000083|22=M|270=6.17904|271=100|273=05:10:36.725457047|574=4|2446=1|7554=515|10=152|
8=FIXT.1.1|9=000187|35=X|49=EXCHANGE|56=CLIENT|34=2174|57=SESSION1|52=20260630-07:24:03.725906611|1021=2|262=1000000000000000002|268=1|279=1|269=1|55=SYM00083|48=100000083|22=M|270=6.17904|271=149400|1023=1|10=039|
8=FIXT.1.1|9=000237|35=X|49=EXCHANGE|56=CLIENT|34=2173|57=SESSION1|52=20260630-07:24:03.323642998|262=1000000000000000002|268=1|279=0|269=2|278=000000000000003C|55=SYM00108|48=100000108|22=M|270=7.10874|271=1200|273=05:10:36.323396047|574=4|2446=1|7554=514|10=194|
8=FIXT.1.1|9=000185|35=X|49=EXCHANGE|56=CLIENT|34=2172|57=SESSION1|52=20260630-07:24:03.323405681|1021=2|262=1000000000000000002|268=1|279=1|269=1|55=SYM00108|48=100000108|22=M|270=7.10874|271=6200|1023=1|10=176|
8=FIXT.1.1|9=000185|35=X|49=EXCHANGE|56=CLIENT|34=2171|57=SESSION1|52=20260630-07:24:03.145147571|1021=2|262=1000000000000000002|268=1|279=1|269=0|55=SYM00108|48=100000108|22=M|270=6.88170|271=4200|1023=1|10=178|
8=FIXT.1.1|9=000237|35=X|49=EXCHANGE|56=CLIENT|34=2170|57=SESSION1|52=20260630-07:24:03.123654415|262=1000000000000000002|268=1|279=0|269=2|278=000000000000003D|55=SYM00108|48=100000108|22=M|270=7.10874|271=1300|273=05:10:36.123576748|574=4|2446=1|7554=513|10=183|
8=FIXT.1.1|9=000185|35=X|49=EXCHANGE|56=CLIENT|34=2169|57=SESSION1|52=20260630-07:24:03.123836821|1021=2|262=1000000000000000002|268=1|279=1|269=1|55=SYM00108|48=100000108|22=M|270=7.10874|271=7400|1023=1|10=187|
8=FIXT.1.1|9=000237|35=X|49=EXCHANGE|56=CLIENT|34=2168|57=SESSION1|52=20260630-07:24:03.008023160|262=1000000000000000002|268=1|279=0|269=2|278=000000000000003E|55=SYM00108|48=100000108|22=M|270=7.10874|271=6300|273=05:10:36.008362228|574=4|2446=1|7554=512|10=172|
8=FIXT.1.1|9=000237|35=X|49=EXCHANGE|56=CLIENT|34=2167|57=SESSION1|52=20260630-07:24:03.008990302|262=1000000000000000002|268=1|279=0|269=2|278=000000000000003F|55=SYM00108|48=100000108|22=M|270=7.10874|271=3100|273=05:10:36.008362228|574=4|2446=1|7554=511|10=177|
8=FIXT.1.1|9=000237|35=X|49=EXCHANGE|56=CLIENT|34=2166|57=SESSION1|52=20260630-07:24:03.008784898|262=1000000000000000002|268=1|279=0|269=2|278=0000000000000040|55=SYM00108|48=100000108|22=M|270=7.39368|271=1300|273=05:10:36.008362228|574=4|2446=1|7554=510|10=184|
8=FIXT.1.1|9=000237|35=X|49=EXCHANGE|56=CLIENT|34=2165|57=SESSION1|52=20260630-07:24:03.008213472|262=1000000000000000002|268=1|279=0|269=2|278=0000000000000041|55=SYM00108|48=100000108|22=M|270=7.12068|271=2200|273=05:10:36.008362228|574=4|2446=1|7554=509|10=155|
8=FIXT.1.1|9=000237|35=X|49=EXCHANGE|56=CLIENT|34=2164|57=SESSION1|52=20260630-07:24:03.008803263|262=1000000000000000002|268=1|279=0|269=2|278=0000000000000042|55=SYM00108|48=100000108|22=M|270=7.16491|271=2100|273=05:10:36.008362228|574=4|2446=1|7554=508|10=160|
8=FIXT.1.1|9=000381|35=X|49=EXCHANGE|56=CLIENT|34=2163|57=SESSION1|52=20260630-07:24:03.008357199|1021=2|262=1000000000000000002|268=5|279=2|269=1|55=SYM00108|48=100000108|22=M|1023=1|279=2|269=1|55=SYM00108|48=100000108|22=M|1023=1|279=2|269=1|55=SYM00108|48=100000108|22=M|1023=1|279=2|269=1|55=SYM00108|48=100000108|22=M|1023=1|279=0|269=1|55=SYM00108|48=100000108|22=M|270=7.10874|271=8700|1023=1|10=210|
8=FIXT.1.1|9=000185|35=X|49=EXCHANGE|56=CLIENT|34=2162|57=SESSION1|52=20260630-07:24:02.987977307|1021=2|262=1000000000000000002|268=1|279=1|269=1|55=SYM00108|48=100000108|22=M|270=8.01519|271=2600|1023=5|10=200|
8=FIXT.1.1|9=000185|35=X|49=EXCHANGE|56=CLIENT|34=2161|57=SESSION1|52=20260630-07:24:02.945436994|1021=2|262=1000000000000000002|268=1|279=0|269=1|55=SYM00108|48=100000108|22=M|270=7.16491|271=2100|1023=1|10=189|
8=FIXT.1.1|9=000185|35=X|49=EXCHANGE|56=CLIENT|34=2160|57=SESSION1|52=20260630-07:24:02.923969659|1021=2|262=1000000000000000002|268=1|279=0|269=1|55=SYM00108|48=100000108|22=M|270=7.39368|271=1300|1023=2|10=203|
8=FIXT.1.1|9=000185|35=X|49=EXCHANGE|56=CLIENT|34=2159|57=SESSION1|52=20260630-07:24:02.775268407|1021=2|262=1000000000000000002|268=1|279=0|269=1|55=SYM00108|48=100000108|22=M|270=7.12068|271=2200|1023=1|10=186|
8=FIXT.1.1|9=000186|35=X|49=EXCHANGE|56=CLIENT|34=2158|57=SESSION1|52=20260630-07:24:02.713772470|1021=2|262=1000000000000000002|268=1|279=1|269=1|55=SYM00108|48=100000108|22=M|270=7.10874|271=18100|1023=1|10=236|
8=FIXT.1.1|9=000186|35=X|49=EXCHANGE|56=CLIENT|34=2157|57=SESSION1|52=20260630-07:24:02.375233320|1021=2|262=1000000000000000002|268=1|279=1|269=0|55=SYM00092|48=100000092|22=M|270=32.30500|271=2400|1023=8|10=217|
8=FIXT.1.1|9=000185|35=X|49=EXCHANGE|56=CLIENT|34=2156|57=SESSION1|52=20260630-07:24:02.345126381|1021=2|262=1000000000000000002|268=1|279=1|269=0|55=SYM00092|48=100000092|22=M|270=33.53263|271=400|1023=6|10=180|
8=FIXT.1.1|9=000185|35=X|49=EXCHANGE|56=CLIENT|34=2155|57=SESSION1|52=20260630-07:24:02.323457143|1021=2|262=1000000000000000002|268=1|279=1|269=0|55=SYM00092|48=100000092|22=M|270=32.64848|271=400|1023=7|10=189|
8=FIXT.1.1|9=000187|35=X|49=EXCHANGE|56=CLIENT|34=2154|57=SESSION1|52=20260630-07:24:02.002407178|1021=2|262=1000000000000000002|268=1|279=1|269=0|55=SYM00002|48=100000002|22=M|270=51.93755|271=1400|1023=10|10=004|
8=FIXT.1.1|9=000185|35=X|49=EXCHANGE|56=CLIENT|34=2153|57=SESSION1|52=20260630-07:24:01.967939827|1021=2|262=1000000000000000002|268=1|279=1|269=0|55=SYM00002|48=100000002|22=M|270=52.46820|271=400|1023=8|10=189|
8=FIXT.1.1|9=000186|35=X|49=EXCHANGE|56=CLIENT|34=2152|57=SESSION1|52=20260630-07:24:01.946060114|1021=2|262=1000000000000000002|268=1|279=1|269=0|55=SYM00002|48=100000002|22=M|270=50.39310|271=1000|1023=9|10=200|
8=FIXT.1.1|9=000185|35=X|49=EXCHANGE|56=CLIENT|34=2151|57=SESSION1|52=20260630-07:24:01.923520679|1021=2|262=1000000000000000002|268=1|279=1|269=0|55=SYM00109|48=100000109|22=M|270=60.34995|271=600|1023=4|10=193|
8=FIXT.1.1|9=000185|35=X|49=EXCHANGE|56=CLIENT|34=2150|57=SESSION1|52=20260630-07:24:01.745937727|1021=2|262=1000000000000000002|268=1|279=1|269=0|55=SYM00109|48=100000109|22=M|270=61.43580|271=600|1023=3|10=190|
8=FIXT.1.1|9=000185|35=X|49=EXCHANGE|56=CLIENT|34=2149|57=SESSION1|52=20260630-07:24:01.724342539|1021=2|262=1000000000000000002|268=1|279=1|269=0|55=SYM00109|48=100000109|22=M|270=61.77110|271=600|1023=1|10=180|
8=FIXT.1.1|9=000185|35=X|49=EXCHANGE|56=CLIENT|34=2148|57=SESSION1|52=20260630-07:24:01.641427927|1021=2|262=1000000000000000002|268=1|279=1|269=0|55=SYM00109|48=100000109|22=M|270=63.07792|271=600|1023=2|10=194|
8=FIXT.1.1|9=000185|35=X|49=EXCHANGE|56=CLIENT|34=2147|57=SESSION1|52=20260630-07:24:01.157291791|1021=2|262=1000000000000000002|268=1|279=1|269=0|55=SYM00084|48=100000084|22=M|270=1.68155|271=3400|1023=1|10=189|
8=FIXT.1.1|9=000185|35=X|49=EXCHANGE|56=CLIENT|34=2146|57=SESSION1|52=20260630-07:24:01.123081480|1021=2|262=1000000000000000002|268=1|279=1|269=1|55=SYM00084|48=100000084|22=M|270=1.66862|271=2400|1023=1|10=176|
8=FIXT.1.1|9=000184|35=X|49=EXCHANGE|56=CLIENT|34=2145|57=SESSION1|52=20260630-07:24:00.923586747|1021=2|262=1000000000000000002|268=1|279=1|269=0|55=SYM00084|48=100000084|22=M|270=1.68155|271=400|1023=1|10=143|
8=FIXT.1.1|9=000237|35=X|49=EXCHANGE|56=CLIENT|34=2144|57=SESSION1|52=20260630-07:24:00.923894564|262=1000000000000000002|268=1|279=0|269=2|278=0000000000000043|55=SYM00084|48=100000084|22=M|270=1.68155|271=1300|273=05:10:33.923274232|574=4|2446=2|7554=507|10=181|
8=FIXT.1.1|9=000237|35=X|49=EXCHANGE|56=CLIENT|34=2143|57=SESSION1|52=20260630-07:24:00.867383718|262=1000000000000000002|268=1|279=0|269=2|278=0000000000000044|55=SYM00084|48=100000084|22=M|270=1.68155|271=1300|273=05:10:33.866979500|574=4|2446=2|7554=506|10=197|
8=FIXT.1.1|9=000185|35=X|49=EXCHANGE|56=CLIENT|34=2142|57=SESSION1|52=20260630-07:24:00.867679592|1021=2|262=1000000000000000002|268=1|279=1|269=0|55=SYM00084|48=100000084|22=M|270=1.68155|271=1700|1023=1|10=201|
8=FIXT.1.1|9=76|35=0|34=27|49=CLIENT|56=EXCHANGE|52=20260630-07:23:57.080731799|50=SESSION1|10=160|
8=FIXT.1.1|9=000078|35=0|49=EXCHANGE|56=CLIENT|34=2141|57=SESSION1|52=20260630-07:23:56.857891695|10=213|
8=FIXT.1.1|9=117|35=0|34=26|49=CLIENT|56=EXCHANGE|52=20260630-07:23:27.079237054|50=SESSION1|112=00000000-0000-0000-0000-000000000034|10=078|
8=FIXT.1.1|9=000119|35=1|49=EXCHANGE|56=CLIENT|34=2140|57=SESSION1|52=20260630-07:23:26.857572260|112=00000000-0000-0000-0000-000000000034|10=075|
8=FIXT.1.1|9=000186|35=X|49=EXCHANGE|56=CLIENT|34=2139|57=SESSION1|52=20260630-07:23:14.541097425|1021=2|262=1000000000000000002|268=1|279=1|269=0|55=SYM00002|48=100000002|22=M|270=56.62020|271=1200|1023=6|10=213|
8=FIXT.1.1|9=000185|35=X|49=EXCHANGE|56=CLIENT|34=2138|57=SESSION1|52=20260630-07:23:13.417869198|1021=2|262=1000000000000000002|268=1|279=1|269=0|55=SYM00002|48=100000002|22=M|270=56.62020|271=300|1023=6|10=178|
8=FIXT.1.1|9=000185|35=X|49=EXCHANGE|56=CLIENT|34=2137|57=SESSION1|52=20260630-07:23:10.505448427|1021=2|262=1000000000000000002|268=1|279=0|269=1|55=SYM00094|48=100000094|22=M|270=1.66022|271=2000|1023=2|10=173|
8=FIXT.1.1|9=000185|35=X|49=EXCHANGE|56=CLIENT|34=2136|57=SESSION1|52=20260630-07:22:56.136241593|1021=2|262=1000000000000000002|268=1|279=0|269=0|55=SYM00084|48=100000084|22=M|270=1.68155|271=3000|1023=1|10=182|
8=FIXT.1.1|9=000185|35=X|49=EXCHANGE|56=CLIENT|34=2135|57=SESSION1|52=20260630-07:22:55.988092123|1021=2|262=1000000000000000002|268=1|279=0|269=1|55=SYM00084|48=100000084|22=M|270=1.66862|271=1200|1023=1|10=192|
8=FIXT.1.1|9=000237|35=X|49=EXCHANGE|56=CLIENT|34=2134|57=SESSION1|52=20260630-07:22:55.940929350|262=1000000000000000002|268=1|279=0|269=2|278=0000000000000045|55=SYM00084|48=100000084|22=M|270=1.62049|271=1300|273=05:09:28.940001255|574=4|2446=2|7554=505|10=179|
8=FIXT.1.1|9=000185|35=X|49=EXCHANGE|56=CLIENT|34=2133|57=SESSION1|52=20260630-07:22:55.940047280|1021=2|262=1000000000000000002|268=1|279=1|269=0|55=SYM00084|48=100000084|22=M|270=1.62049|271=7400|1023=1|10=183|
8=FIXT.1.1|9=000237|35=X|49=EXCHANGE|56=CLIENT|34=2132|57=SESSION1|52=20260630-07:22:55.915788375|262=1000000000000000002|268=1|279=0|269=2|278=0000000000000046|55=SYM00084|48=100000084|22=M|270=1.62049|271=1300|273=05:09:28.914957277|574=4|2446=2|7554=504|10=214|
8=FIXT.1.1|9=000185|35=X|49=EXCHANGE|56=CLIENT|34=2131|57=SESSION1|52=20260630-07:22:55.915527437|1021=2|262=1000000000000000002|268=1|279=1|269=0|55=SYM00084|48=100000084|22=M|270=1.62049|271=8700|1023=1|10=194|
8=FIXT.1.1|9=117|35=0|34=25|49=CLIENT|56=EXCHANGE|52=20260630-07:22:51.671343370|50=SESSION1|112=00000000-0000-0000-0000-000000000035|10=071|
8=FIXT.1.1|9=000119|35=1|49=EXCHANGE|56=CLIENT|34=2130|57=SESSION1|52=20260630-07:22:51.449068792|112=00000000-0000-0000-0000-000000000035|10=079|
8=FIXT.1.1|9=000172|35=X|49=EXCHANGE|56=CLIENT|34=2129|57=SESSION1|52=20260630-07:22:35.106737766|1021=2|262=1000000000000000002|268=1|279=0|269=1|55=SYM00094|48=100000094|22=M|271=100|1023=1|10=076|
8=FIXT.1.1|9=000231|35=X|49=EXCHANGE|56=CLIENT|34=2128|57=SESSION1|52=20260630-07:22:26.283424643|262=1000000000000000002|268=1|279=0|269=2|278=0000000000000047|55=SYM00084|48=100000084|22=M|270=1.66862|271=13200|273=05:08:59.281163180|574=5|7554=503|10=170|
8=FIXT.1.1|9=000458|35=X|49=EXCHANGE|56=CLIENT|34=2127|57=SESSION1|52=20260630-07:22:26.283926967|1021=2|262=1000000000000000002|268=7|279=2|269=0|55=SYM00084|48=100000084|22=M|1023=1|279=2|269=1|55=SYM00084|48=100000084|22=M|1023=1|279=2|269=1|55=SYM00084|48=100000084|22=M|1023=1|279=2|269=1|55=SYM00084|48=100000084|22=M|1023=1|279=2|269=1|55=SYM00084|48=100000084|22=M|1023=1|279=2|269=1|55=SYM00084|48=100000084|22=M|1023=1|279=2|269=1|55=SYM00084|48=100000084|22=M|1023=1|10=178|
8=FIXT.1.1|9=000150|35=CO|49=EXCHANGE|56=CLIENT|34=2126|57=SESSION1|52=20260630-07:22:26.283602058|324=1000000000000000001|1301=EXMKT|146=1|55=SYM00084|48=100000084|22=M|10=007|
8=FIXT.1.1|9=000168|35=CO|49=EXCHANGE|56=CLIENT|34=2125|57=SESSION1|52=20260630-07:22:26.282349485|324=1000000000000000001|1301=EXMKT|625=OPEN1_E|146=1|55=SYM00084|48=100000084|22=M|292=o|10=070|
8=FIXT.1.1|9=000185|35=X|49=EXCHANGE|56=CLIENT|34=2124|57=SESSION1|52=20260630-07:22:20.545639539|1021=2|262=1000000000000000002|268=1|279=0|269=1|55=SYM00084|48=100000084|22=M|270=1.68155|271=1200|1023=5|10=190|
8=FIXT.1.1|9=000185|35=X|49=EXCHANGE|56=CLIENT|34=2123|57=SESSION1|52=20260630-07:22:20.523043633|1021=2|262=1000000000000000002|268=1|279=0|269=1|55=SYM00084|48=100000084|22=M|270=1.67046|271=1300|1023=2|10=165|
8=FIXT.1.1|9=000185|35=X|49=EXCHANGE|56=CLIENT|34=2122|57=SESSION1|52=20260630-07:22:20.377361076|1021=2|262=1000000000000000002|268=1|279=0|269=1|55=SYM00084|48=100000084|22=M|270=1.64804|271=1300|1023=1|10=173|
8=FIXT.1.1|9=000167|35=CO|49=EXCHANGE|56=CLIENT|34=2121|57=SESSION1|52=20260630-07:22:16.042343863|324=1000000000000000001|1301=EXMKT|146=1|55=SYM00094|48=100000094|22=M|58=PRE-OPEN_CB_E|10=131|
8=FIXT.1.1|9=76|35=0|34=24|49=CLIENT|56=EXCHANGE|52=20260630-07:22:16.263371110|50=SESSION1|10=131|
8=FIXT.1.1|9=000174|35=CO|49=EXCHANGE|56=CLIENT|34=2120|57=SESSION1|52=20260630-07:22:16.041757153|324=1000000000000000001|1301=EXMKT|625=PRE-OPEN_CB_E|146=1|55=SYM00094|48=100000094|22=M|292=o|10=250|
8=FIXT.1.1|9=000185|35=X|49=EXCHANGE|56=CLIENT|34=2119|57=SESSION1|52=20260630-07:22:08.150303232|1021=2|262=1000000000000000002|268=1|279=1|269=1|55=SYM00084|48=100000084|22=M|270=1.66022|271=3300|1023=3|10=163|
8=FIXT.1.1|9=000185|35=X|49=EXCHANGE|56=CLIENT|34=2118|57=SESSION1|52=20260630-07:22:08.124221412|1021=2|262=1000000000000000002|268=1|279=1|269=1|55=SYM00084|48=100000084|22=M|270=1.70891|271=3200|1023=2|10=169|
8=FIXT.1.1|9=000185|35=X|49=EXCHANGE|56=CLIENT|34=2117|57=SESSION1|52=20260630-07:22:08.087729853|1021=2|262=1000000000000000002|268=1|279=1|269=1|55=SYM00084|48=100000084|22=M|270=1.62049|271=2900|1023=1|10=199|
8=FIXT.1.1|9=000185|35=X|49=EXCHANGE|56=CLIENT|34=2116|57=SESSION1|52=20260630-07:22:01.723995997|1021=2|262=1000000000000000002|268=1|279=1|269=1|55=SYM00084|48=100000084|22=M|270=1.66022|271=2100|1023=3|10=191|
8=FIXT.1.1|9=000185|35=X|49=EXCHANGE|56=CLIENT|34=2115|57=SESSION1|52=20260630-07:22:01.528670361|1021=2|262=1000000000000000002|268=1|279=1|269=1|55=SYM00084|48=100000084|22=M|270=1.70891|271=1900|1023=2|10=183|
8=FIXT.1.1|9=000185|35=X|49=EXCHANGE|56=CLIENT|34=2114|57=SESSION1|52=20260630-07:22:01.502283216|1021=2|262=1000000000000000002|268=1|279=1|269=1|55=SYM00084|48=100000084|22=M|270=1.62049|271=1600|1023=1|10=165|
8=FIXT.1.1|9=000174|35=X|49=EXCHANGE|56=CLIENT|34=2113|57=SESSION1|52=20260630-07:21:42.625876428|1021=2|262=1000000000000000002|268=1|279=1|269=0|55=SYM00084|48=100000084|22=M|271=15000|1023=1|10=172|
8=FIXT.1.1|9=000174|35=X|49=EXCHANGE|56=CLIENT|34=2112|57=SESSION1|52=20260630-07:21:42.217236288|1021=2|262=1000000000000000002|268=1|279=1|269=0|55=SYM00084|48=100000084|22=M|271=12000|1023=1|10=159|
8=FIXT.1.1|9=000173|35=X|49=EXCHANGE|56=CLIENT|34=2111|57=SESSION1|52=20260630-07:21:41.809688505|1021=2|262=1000000000000000002|268=1|279=1|269=0|55=SYM00084|48=100000084|22=M|271=9000|1023=1|10=124|
8=FIXT.1.1|9=76|35=0|34=23|49=CLIENT|56=EXCHANGE|52=20260630-07:21:41.511772074|50=SESSION1|10=137|
8=FIXT.1.1|9=000173|35=X|49=EXCHANGE|56=CLIENT|34=2110|57=SESSION1|52=20260630-07:21:41.287991571|1021=2|262=1000000000000000002|268=1|279=1|269=0|55=SYM00084|48=100000084|22=M|271=6000|1023=1|10=120|
8=FIXT.1.1|9=000173|35=X|49=EXCHANGE|56=CLIENT|34=2109|57=SESSION1|52=20260630-07:21:37.628684328|1021=2|262=1000000000000000002|268=1|279=0|269=0|55=SYM00084|48=100000084|22=M|271=3000|1023=1|10=127|
8=FIXT.1.1|9=117|35=0|34=22|49=CLIENT|56=EXCHANGE|52=20260630-07:21:09.352971739|50=SESSION1|112=00000000-0000-0000-0000-000000000036|10=083|
8=FIXT.1.1|9=000119|35=1|49=EXCHANGE|56=CLIENT|34=2108|57=SESSION1|52=20260630-07:21:09.130504962|112=00000000-0000-0000-0000-000000000036|10=068|
8=FIXT.1.1|9=000184|35=X|49=EXCHANGE|56=CLIENT|34=2107|57=SESSION1|52=20260630-07:20:49.425239349|1021=2|262=1000000000000000002|268=1|279=1|269=1|55=SYM00084|48=100000084|22=M|270=1.66022|271=900|1023=3|10=139|
8=FIXT.1.1|9=000184|35=X|49=EXCHANGE|56=CLIENT|34=2106|57=SESSION1|52=20260630-07:20:37.145561170|1021=2|262=1000000000000000002|268=1|279=1|269=1|55=SYM00084|48=100000084|22=M|270=1.66022|271=600|1023=3|10=121|
8=FIXT.1.1|9=000184|35=X|49=EXCHANGE|56=CLIENT|34=2105|57=SESSION1|52=20260630-07:20:37.124856623|1021=2|262=1000000000000000002|268=1|279=1|269=1|55=SYM00084|48=100000084|22=M|270=1.70891|271=600|1023=2|10=135|
8=FIXT.1.1|9=000184|35=X|49=EXCHANGE|56=CLIENT|34=2104|57=SESSION1|52=20260630-07:20:37.036040733|1021=2|262=1000000000000000002|268=1|279=0|269=1|55=SYM00084|48=100000084|22=M|270=1.62049|271=300|1023=1|10=114|
8=FIXT.1.1|9=117|35=0|34=21|49=CLIENT|56=EXCHANGE|52=20260630-07:20:33.944970293|50=SESSION1|112=00000000-0000-0000-0000-000000000037|10=080|
8=FIXT.1.1|9=000119|35=1|49=EXCHANGE|56=CLIENT|34=2103|57=SESSION1|52=20260630-07:20:33.722138236|112=00000000-0000-0000-0000-000000000037|10=064|
8=FIXT.1.1|9=000184|35=X|49=EXCHANGE|56=CLIENT|34=2102|57=SESSION1|52=20260630-07:20:27.406995097|1021=2|262=1000000000000000002|268=1|279=0|269=1|55=SYM00084|48=100000084|22=M|270=1.66022|271=300|1023=2|10=130|
8=FIXT.1.1|9=000184|35=X|49=EXCHANGE|56=CLIENT|34=2101|57=SESSION1|52=20260630-07:20:26.324108033|1021=2|262=1000000000000000002|268=1|279=0|269=1|55=SYM00084|48=100000084|22=M|270=1.70891|271=300|1023=1|10=111|
8=FIXT.1.1|9=000167|35=CO|49=EXCHANGE|56=CLIENT|34=2100|57=SESSION1|52=20260630-07:20:26.284990936|324=1000000000000000001|1301=EXMKT|146=1|55=SYM00084|48=100000084|22=M|58=PRE-OPEN_CB_E|10=142|
8=FIXT.1.1|9=000174|35=CO|49=EXCHANGE|56=CLIENT|34=2099|57=SESSION1|52=20260630-07:20:26.283847073|324=1000000000000000001|1301=EXMKT|625=PRE-OPEN_CB_E|146=1|55=SYM00084|48=100000084|22=M|292=o|10=015|
8=FIXT.1.1|9=000150|35=CO|49=EXCHANGE|56=CLIENT|34=2098|57=SESSION1|52=20260630-07:19:58.311054978|324=1000000000000000001|1301=EXMKT|146=1|55=SYM00094|48=100000094|22=M|10=032|
8=FIXT.1.1|9=76|35=0|34=20|49=CLIENT|56=EXCHANGE|52=20260630-07:19:58.532542377|50=SESSION1|10=153|
8=FIXT.1.1|9=000168|35=CO|49=EXCHANGE|56=CLIENT|34=2097|57=SESSION1|52=20260630-07:19:58.310184586|324=1000000000000000001|1301=EXMKT|625=OPEN1_E|146=1|55=SYM00094|48=100000094|22=M|292=o|10=082|
8=FIXT.1.1|9=000078|35=0|49=EXCHANGE|56=CLIENT|34=2096|57=SESSION1|52=20260630-07:19:54.233005999|10=207|
8=FIXT.1.1|9=117|35=0|34=19|49=CLIENT|56=EXCHANGE|52=20260630-07:19:24.455037814|50=SESSION1|112=00000000-0000-0000-0000-000000000038|10=086|
8=FIXT.1.1|9=000119|35=1|49=EXCHANGE|56=CLIENT|34=2095|57=SESSION1|52=20260630-07:19:24.233998652|112=00000000-0000-0000-0000-000000000038|10=096|
8=FIXT.1.1|9=000238|35=X|49=EXCHANGE|56=CLIENT|34=2094|57=SESSION1|52=20260630-07:19:07.637272854|262=1000000000000000002|268=1|279=0|269=2|278=0000000000000048|55=SYM00110|48=100000110|22=M|270=182.50200|271=800|273=05:05:40.636357883|574=4|2446=2|7554=502|10=232|
8=FIXT.1.1|9=000238|35=X|49=EXCHANGE|56=CLIENT|34=2093|57=SESSION1|52=20260630-07:19:07.637426294|262=1000000000000000002|268=1|279=0|269=2|278=0000000000000049|55=SYM00110|48=100000110|22=M|270=182.50200|271=200|273=05:05:40.636357883|574=4|2446=2|7554=501|10=224|
8=FIXT.1.1|9=000187|35=X|49=EXCHANGE|56=CLIENT|34=2092|57=SESSION1|52=20260630-07:19:07.636820898|1021=2|262=1000000000000000002|268=1|279=1|269=0|55=SYM00110|48=100000110|22=M|270=182.50200|271=5500|1023=1|10=023|
8=FIXT.1.1|9=000187|35=X|49=EXCHANGE|56=CLIENT|34=2091|57=SESSION1|52=20260630-07:19:02.562296903|1021=2|262=1000000000000000002|268=1|279=1|269=0|55=SYM00110|48=100000110|22=M|270=182.50200|271=6500|1023=1|10=010|
8=FIXT.1.1|9=000187|35=X|49=EXCHANGE|56=CLIENT|34=2090|57=SESSION1|52=20260630-07:19:02.562213170|1021=2|262=1000000000000000002|268=1|279=1|269=0|55=SYM00110|48=100000110|22=M|270=182.50200|271=6600|1023=1|10=251|
8=FIXT.1.1|9=117|35=0|34=18|49=CLIENT|56=EXCHANGE|52=20260630-07:18:49.047541119|50=SESSION1|112=00000000-0000-0000-0000-000000000039|10=087|
8=FIXT.1.1|9=000119|35=1|49=EXCHANGE|56=CLIENT|34=2089|57=SESSION1|52=20260630-07:18:48.825944662|112=00000000-0000-0000-0000-000000000039|10=104|
8=FIXT.1.1|9=000187|35=X|49=EXCHANGE|56=CLIENT|34=2088|57=SESSION1|52=20260630-07:18:36.447223857|1021=2|262=1000000000000000002|268=1|279=1|269=0|55=SYM00110|48=100000110|22=M|270=182.50200|271=6700|1023=1|10=024|
8=FIXT.1.1|9=117|35=0|34=17|49=CLIENT|56=EXCHANGE|52=20260630-07:18:13.638375360|50=SESSION1|112=00000000-0000-0000-0000-000000000040|10=078|
8=FIXT.1.1|9=000119|35=1|49=EXCHANGE|56=CLIENT|34=2087|57=SESSION1|52=20260630-07:18:13.415343183|112=00000000-0000-0000-0000-000000000040|10=072|
8=FIXT.1.1|9=000167|35=CO|49=EXCHANGE|56=CLIENT|34=2086|57=SESSION1|52=20260630-07:17:58.312109817|324=1000000000000000001|1301=EXMKT|146=1|55=SYM00094|48=100000094|22=M|58=PRE-OPEN_CB_E|10=150|
8=FIXT.1.1|9=000174|35=CO|49=EXCHANGE|56=CLIENT|34=2085|57=SESSION1|52=20260630-07:17:58.311797380|324=1000000000000000001|1301=EXMKT|625=PRE-OPEN_CB_E|146=1|55=SYM00094|48=100000094|22=M|292=o|10=020|
8=FIXT.1.1|9=117|35=0|34=16|49=CLIENT|56=EXCHANGE|52=20260630-07:17:38.229293464|50=SESSION1|112=00000000-0000-0000-0000-000000000041|10=084|
8=FIXT.1.1|9=000119|35=1|49=EXCHANGE|56=CLIENT|34=2084|57=SESSION1|52=20260630-07:17:38.007910820|112=00000000-0000-0000-0000-000000000041|10=071|
8=FIXT.1.1|9=000078|35=0|49=EXCHANGE|56=CLIENT|34=2083|57=SESSION1|52=20260630-07:17:32.598025248|10=200|
8=FIXT.1.1|9=76|35=0|34=15|49=CLIENT|56=EXCHANGE|52=20260630-07:17:02.821526796|50=SESSION1|10=152|
8=FIXT.1.1|9=000078|35=0|49=EXCHANGE|56=CLIENT|34=2082|57=SESSION1|52=20260630-07:17:02.599185049|10=203|
8=FIXT.1.1|9=000150|35=CO|49=EXCHANGE|56=CLIENT|34=2081|57=SESSION1|52=20260630-07:16:32.600849549|324=1000000000000000001|1301=EXMKT|146=1|55=SYM00094|48=100000094|22=M|10=020|
8=FIXT.1.1|9=000168|35=CO|49=EXCHANGE|56=CLIENT|34=2080|57=SESSION1|52=20260630-07:16:32.599367416|324=1000000000000000001|1301=EXMKT|625=OPEN1_E|146=1|55=SYM00094|48=100000094|22=M|292=o|10=077|
8=FIXT.1.1|9=117|35=0|34=14|49=CLIENT|56=EXCHANGE|52=20260630-07:16:29.801515448|50=SESSION1|112=00000000-0000-0000-0000-000000000042|10=077|
8=FIXT.1.1|9=000119|35=1|49=EXCHANGE|56=CLIENT|34=2079|57=SESSION1|52=20260630-07:16:29.579050624|112=00000000-0000-0000-0000-000000000042|10=086|
8=FIXT.1.1|9=000078|35=0|49=EXCHANGE|56=CLIENT|34=2078|57=SESSION1|52=20260630-07:16:24.170205606|10=188|
8=FIXT.1.1|9=117|35=0|34=13|49=CLIENT|56=EXCHANGE|52=20260630-07:15:54.392853530|50=SESSION1|112=00000000-0000-0000-0000-000000000043|10=076|
8=FIXT.1.1|9=000119|35=1|49=EXCHANGE|56=CLIENT|34=2077|57=SESSION1|52=20260630-07:15:54.170427388|112=00000000-0000-0000-0000-000000000043|10=084|
8=FIXT.1.1|9=000078|35=0|49=EXCHANGE|56=CLIENT|34=2076|57=SESSION1|52=20260630-07:15:48.759026877|10=215|
8=FIXT.1.1|9=76|35=0|34=12|49=CLIENT|56=EXCHANGE|52=20260630-07:15:18.981741261|50=SESSION1|10=147|
8=FIXT.1.1|9=000078|35=0|49=EXCHANGE|56=CLIENT|34=2075|57=SESSION1|52=20260630-07:15:18.759854271|10=208|
8=FIXT.1.1|9=117|35=0|34=11|49=CLIENT|56=EXCHANGE|52=20260630-07:14:48.981764878|50=SESSION1|112=00000000-0000-0000-0000-000000000044|10=097|
8=FIXT.1.1|9=000119|35=1|49=EXCHANGE|56=CLIENT|34=2074|57=SESSION1|52=20260630-07:14:48.759178674|112=00000000-0000-0000-0000-000000000044|10=098|
8=FIXT.1.1|9=000167|35=CO|49=EXCHANGE|56=CLIENT|34=2073|57=SESSION1|52=20260630-07:14:32.601193283|324=1000000000000000001|1301=EXMKT|146=1|55=SYM00094|48=100000094|22=M|58=PRE-OPEN_CB_E|10=136|
8=FIXT.1.1|9=000174|35=CO|49=EXCHANGE|56=CLIENT|34=2072|57=SESSION1|52=20260630-07:14:32.600629567|324=1000000000000000001|1301=EXMKT|625=PRE-OPEN_CB_E|146=1|55=SYM00094|48=100000094|22=M|292=o|10=007|
8=FIXT.1.1|9=76|35=0|34=10|49=CLIENT|56=EXCHANGE|52=20260630-07:14:13.572686190|50=SESSION1|10=144|
8=FIXT.1.1|9=000078|35=0|49=EXCHANGE|56=CLIENT|34=2071|57=SESSION1|52=20260630-07:14:13.350926061|10=182|
8=FIXT.1.1|9=75|35=0|34=9|49=CLIENT|56=EXCHANGE|52=20260630-07:13:43.572315760|50=SESSION1|10=097|
8=FIXT.1.1|9=000078|35=0|49=EXCHANGE|56=CLIENT|34=2070|57=SESSION1|52=20260630-07:13:43.350454891|10=190|
8=FIXT.1.1|9=000186|35=X|49=EXCHANGE|56=CLIENT|34=2069|57=SESSION1|52=20260630-07:13:13.350993998|1021=2|262=1000000000000000002|268=1|279=1|269=0|55=SYM00002|48=100000002|22=M|270=56.62020|271=1200|1023=6|10=231|
8=FIXT.1.1|9=75|35=0|34=8|49=CLIENT|56=EXCHANGE|52=20260630-07:13:12.449751539|50=SESSION1|10=103|
8=FIXT.1.1|9=000185|35=X|49=EXCHANGE|56=CLIENT|34=2068|57=SESSION1|52=20260630-07:13:12.226746408|1021=2|262=1000000000000000002|268=1|279=1|269=0|55=SYM00002|48=100000002|22=M|270=56.62020|271=300|1023=6|10=164|
8=FIXT.1.1|9=000357|35=X|49=EXCHANGE|56=CLIENT|34=2067|57=SESSION1|52=20260630-07:12:52.558306055|1021=2|262=1000000000000000002|268=4|279=2|269=0|55=SYM00092|48=100000092|22=M|1023=3|279=2|269=0|55=SYM00092|48=100000092|22=M|1023=3|279=0|269=0|55=SYM00092|48=100000092|22=M|270=34.39450|271=33600|1023=3|279=0|269=0|55=SYM00092|48=100000092|22=M|270=31.29280|271=7100|1023=10|10=059|
8=FIXT.1.1|9=000187|35=X|49=EXCHANGE|56=CLIENT|34=2066|57=SESSION1|52=20260630-07:12:52.556003165|1021=2|262=1000000000000000002|268=1|279=1|269=0|55=SYM00092|48=100000092|22=M|270=35.69415|271=10900|1023=2|10=032|
8=FIXT.1.1|9=000186|35=X|49=EXCHANGE|56=CLIENT|34=2065|57=SESSION1|52=20260630-07:12:52.556205894|1021=2|262=1000000000000000002|268=1|279=1|269=0|55=SYM00092|48=100000092|22=M|270=35.69415|271=8400|1023=2|10=253|
8=FIXT.1.1|9=000186|35=X|49=EXCHANGE|56=CLIENT|34=2064|57=SESSION1|52=20260630-07:12:52.556854258|1021=2|262=1000000000000000002|268=1|279=1|269=0|55=SYM00092|48=100000092|22=M|270=35.69415|271=5900|1023=2|10=002|
8=FIXT.1.1|9=116|35=0|34=7|49=CLIENT|56=EXCHANGE|52=20260630-07:12:40.872581650|50=SESSION1|112=00000000-0000-0000-0000-000000000045|10=028|
8=FIXT.1.1|9=000119|35=1|49=EXCHANGE|56=CLIENT|34=2063|57=SESSION1|52=20260630-07:12:40.650483146|112=00000000-0000-0000-0000-000000000045|10=070|
8=FIXT.1.1|9=000186|35=X|49=EXCHANGE|56=CLIENT|34=2062|57=SESSION1|52=20260630-07:12:35.237824282|1021=2|262=1000000000000000002|268=1|279=1|269=0|55=SYM00092|48=100000092|22=M|270=35.71258|271=2500|1023=4|10=240|
8=FIXT.1.1|9=000187|35=X|49=EXCHANGE|56=CLIENT|34=2061|57=SESSION1|52=20260630-07:12:30.964901784|1021=2|262=1000000000000000002|268=1|279=1|269=0|55=SYM00092|48=100000092|22=M|270=34.39450|271=31100|1023=3|10=031|
8=FIXT.1.1|9=000186|35=X|49=EXCHANGE|56=CLIENT|34=2060|57=SESSION1|52=20260630-07:12:30.399520962|1021=2|262=1000000000000000002|268=1|279=1|269=0|55=SYM00092|48=100000092|22=M|270=35.71258|271=5000|1023=4|10=238|
8=FIXT.1.1|9=000187|35=X|49=EXCHANGE|56=CLIENT|34=2059|57=SESSION1|52=20260630-07:12:27.311992461|1021=2|262=1000000000000000002|268=1|279=1|269=0|55=SYM00092|48=100000092|22=M|270=34.39450|271=28700|1023=3|10=044|
8=FIXT.1.1|9=75|35=0|34=6|49=CLIENT|56=EXCHANGE|52=20260630-07:12:05.463667774|50=SESSION1|10=105|
8=FIXT.1.1|9=000078|35=0|49=EXCHANGE|56=CLIENT|34=2058|57=SESSION1|52=20260630-07:12:05.241145595|10=190|
8=FIXT.1.1|9=001890|35=y|49=EXCHANGE|56=CLIENT|34=2057|57=SESSION1|52=20260630-07:11:35.260959822|1396=Market Segment 1|320=1000000000000000003|560=0|393=1876|1301=EXMKT|1300=SEG6|893=Y|146=4|55=SYM00111|48=100000111|167=SPT|965=1|228=1|231=1|1193=C|107=SYM00112_INSTRUMENT|864=1|865=5|866=20170831|2576=0|870=5|871=113|872=N|871=104|872=0|871=112|872=N|871=114|872=N|871=115|872=N|1205=1|1206=0|1207=2|1208=2|561=1|711=1|311=[N/A]|457=1|458=1001|459=M|2874=SYM00112|15=USD|55=SYM00113|48=100000112|167=CMB|965=1|228=0|231=0|864=3|865=109|866=20260529|865=7|866=20260629|1145=20260629-09:30:00.000000000|865=5|866=20260529|2576=5|870=5|871=113|872=N|871=104|872=0.00000|871=112|872=N|871=114|872=N|871=115|872=N|1205=1|1206=-21358.04040|1207=21400.98840|1208=0.09946|1148=-229.54080|1149=-173.90592|561=1|711=1|311=SYM00111|309=100000111|305=M|457=1|458=1001|459=M|2874=SYM00112|15=USD|555=2|600=SYM00114|602=100000113|603=M|623=1|624=C|600=SYM00115|602=100000114|603=M|623=1|624=B|55=SYM00115|48=100000114|167=FP|541=20260929|965=1|228=3.2148|231=100.0000|1193=P|864=3|865=109|866=20260529|865=7|866=20260929|1145=20260929-09:30:00.000000000|865=5|866=20260529|2576=5|870=5|871=113|872=N|871=104|872=0.00000|871=112|872=N|871=114|872=N|871=115|872=N|1582=1|1583=103|1584=SEG6|1205=1|1206=0.09946|1207=21400.98840|1208=0.09946|1148=3745.49040|1149=4714.31659|561=1|711=1|311=SYM00111|309=100000111|305=M|457=1|458=1001|459=M|2874=SYM00112|15=USD|55=SYM00114|48=100000113|167=FP|541=20260629|965=1|228=3.2148|231=100.0000|1193=P|864=3|865=109|866=20260227|865=7|866=20260629|1145=20260629-09:30:00.000000000|865=5|866=20260227|2576=5|870=5|871=113|872=N|871=104|872=0.00000|871=112|872=N|871=114|872=N|871=115|872=N|1582=1|1583=103|1584=SEG6|1205=1|1206=0.09946|1207=21400.98840|1208=0.09946|1148=4006.72800|1149=4810.96000|561=1|711=1|311=SYM00111|309=100000111|305=M|457=1|458=1001|459=M|2874=SYM00112|15=USD|10=063|
8=FIXT.1.1|9=009819|35=y|49=EXCHANGE|56=CLIENT|34=2056|57=SESSION1|52=20260630-07:11:35.260062226|1396=Market Segment 2|320=1000000000000000003|560=0|393=1876|1301=EXMKT|1300=SEG7|893=N|146=22|55=SYM00116|48=100000115|167=FC|541=20260828|965=1|228=5000|231=5000|1193=C|864=3|865=109|866=20260129|865=7|866=20260828|1145=20260828-09:55:00.000000000|865=5|866=20260129|2576=5|870=5|871=113|872=N|871=104|872=0.00000|871=112|872=N|871=114|872=N|871=115|872=N|1582=1|1583=103|1584=SEG7|1205=1|1206=0.04946|1207=21400.98840|1208=0.04946|1148=88.05082|1149=97.96896|561=1|711=1|311=SYM00117|309=100000116|305=M|457=1|458=1002|459=M|2874=SYM00117|15=THB|55=SYM00118|48=100000117|167=FC|541=20261229|965=1|228=5000|231=5000|1193=C|864=3|865=109|866=20260528|865=7|866=20261229|1145=20261229-09:55:00.000000000|865=5|866=20260528|2576=5|870=5|871=113|872=N|871=104|872=0.00000|871=112|872=N|871=114|872=N|871=115|872=N|1582=1|1583=103|1584=SEG7|1205=1|1206=0.04946|1207=21400.98840|1208=0.04946|1148=88.88308|1149=98.96256|561=1|711=1|311=SYM00117|309=100000116|305=M|457=1|458=1002|459=M|2874=SYM00117|15=THB|55=SYM00119|48=100000118|167=FP|541=20260730|965=1|228=5000|231=5000|1193=P|864=3|865=109|866=20251229|865=7|866=20260730|1145=20260730-09:55:00.000000000|865=5|866=20251229|2576=5|870=5|871=113|872=N|871=104|872=0.00000|871=112|872=N|871=114|872=N|871=115|872=N|1582=1|1583=103|1584=SEG7|1205=1|1206=0.04946|1207=21400.98840|1208=0.04946|1148=91.85092|1149=103.09322|561=1|711=1|311=SYM00117|309=100000116|305=M|457=1|458=1002|459=M|2874=SYM00117|15=THB|55=SYM00120|48=100000119|167=FC|541=20260825|965=1|228=300|231=300|1193=C|864=3|865=109|866=20260220|865=7|866=20260825|1145=20260825-06:15:00.000000000|865=5|866=20260220|2576=5|870=5|871=113|872=N|871=104|872=0.00000|871=112|872=N|871=114|872=N|871=115|872=N|1582=1|1583=103|1584=SEG7|1205=1|1206=0.09946|1207=21400.98840|1208=0.09946|1148=346.45292|1149=431.93664|561=1|711=1|311=SYM00121|309=100000120|305=M|457=1|458=1003|459=M|2874=SYM00121|15=THB|55=SYM00122|48=100000121|167=FP|541=20260828|965=1|228=5000|231=5000|1193=P|864=3|865=109|866=20260129|865=7|866=20260828|1145=20260828-09:55:00.000000000|865=5|866=20260129|2576=5|870=5|871=113|872=N|871=104|872=0.00000|871=112|872=N|871=114|872=N|871=115|872=N|1582=1|1583=103|1584=SEG7|1205=1|1206=0.04946|1207=21400.98840|1208=0.04946|1148=89.97386|1149=100.96265|561=1|711=1|311=SYM00117|309=100000116|305=M|457=1|458=1002|459=M|2874=SYM00117|15=THB|55=SYM00123|48=100000122|167=FC|541=20260629|965=1|228=5000|231=5000|1193=C|864=3|865=109|866=20251127|865=7|866=20260629|1145=20260629-09:55:00.000000000|865=5|866=20251127|2576=5|870=5|871=113|872=N|871=104|872=0.00000|871=112|872=N|871=114|872=N|871=115|872=N|1582=1|1583=103|1584=SEG7|1205=1|1206=0.04946|1207=21400.98840|1208=0.04946|1148=75.40330|1149=87.04868|561=1|711=1|311=SYM00117|309=100000116|305=M|457=1|458=1002|459=M|2874=SYM00117|15=THB|55=SYM00124|48=100000123|167=FC|541=20260924|965=1|228=300|231=300|1193=C|864=3|865=109|866=20260325|865=7|866=20260924|1145=20260924-06:15:00.000000000|865=5|866=20260325|2576=5|870=5|871=113|872=N|871=104|872=0.00000|871=112|872=N|871=114|872=N|871=115|872=N|1582=1|1583=103|1584=SEG7|1205=1|1206=0.09946|1207=21400.98840|1208=0.09946|1148=361.61720|1149=436.99734|561=1|711=1|311=SYM00121|309=100000120|305=M|457=1|458=1003|459=M|2874=SYM00121|15=THB|55=SYM00125|48=100000124|167=FP|541=20261029|965=1|228=5000|231=5000|1193=P|864=3|865=109|866=20260330|865=7|866=20261029|1145=20261029-09:55:00.000000000|865=5|866=20260330|2576=5|870=5|871=113|872=N|871=104|872=0.00000|871=112|872=N|871=114|872=N|871=115|872=N|1582=1|1583=103|1584=SEG7|1205=1|1206=0.04946|1207=21400.98840|1208=0.04946|1148=90.59745|1149=95.51148|561=1|711=1|311=SYM00117|309=100000116|305=M|457=1|458=1002|459=M|2874=SYM00117|15=THB|55=SYM00126|48=100000125|167=FC|541=20261026|965=1|228=300|231=300|1193=C|864=3|865=109|866=20260423|865=7|866=20261026|1145=20261026-06:15:00.000000000|865=5|866=20260429|2576=5|870=5|871=113|872=N|871=104|872=0.00000|871=112|872=N|871=114|872=N|871=115|872=N|1582=1|1583=103|1584=SEG7|1205=1|1206=0.09946|1207=21400.98840|1208=0.09946|1148=394.01440|1149=469.71750|561=1|711=1|311=SYM00121|309=100000120|305=M|457=1|458=1003|459=M|2874=SYM00121|15=THB|55=SYM00127|48=100000126|167=FP|541=20260929|965=1|228=5000|231=5000|1193=P|864=3|865=109|866=20260226|865=7|866=20260929|1145=20260929-09:55:00.000000000|865=5|866=20260226|2576=5|870=5|871=113|872=N|871=104|872=0.00000|871=112|872=N|871=114|872=N|871=115|872=N|1582=1|1583=103|1584=SEG7|1205=1|1206=0.04946|1207=21400.98840|1208=0.04946|1148=88.47002|1149=99.26546|561=1|711=1|311=SYM00117|309=100000116|305=M|457=1|458=1002|459=M|2874=SYM00117|15=THB|55=SYM00128|48=100000127|167=FC|541=20261127|965=1|228=5000|231=5000|1193=C|864=3|865=109|866=20260429|865=7|866=20261127|1145=20261127-09:55:00.000000000|865=5|866=20260429|2576=5|870=5|871=113|872=N|871=104|872=0.00000|871=112|872=N|871=114|872=N|871=115|872=N|1582=1|1583=103|1584=SEG7|1205=1|1206=0.04946|1207=21400.98840|1208=0.04946|1148=90.74912|1149=96.02978|561=1|711=1|311=SYM00117|309=100000116|305=M|457=1|458=1002|459=M|2874=SYM00117|15=THB|55=SYM00129|48=100000128|167=FC|541=20260730|965=1|228=5000|231=5000|1193=C|864=3|865=109|866=20251229|865=7|866=20260730|1145=20260730-09:55:00.000000000|865=5|866=20251229|2576=5|870=5|871=113|872=N|871=104|872=0.00000|871=112|872=N|871=114|872=N|871=115|872=N|1582=1|1583=103|1584=SEG7|1205=1|1206=0.04946|1207=21400.98840|1208=0.04946|1148=81.85630|1149=88.85588|561=1|711=1|311=SYM00117|309=100000116|305=M|457=1|458=1002|459=M|2874=SYM00117|15=THB|55=SYM00117|48=100000116|167=SPT|965=1|228=1|231=1|1193=C|107=SYM00117_INSTRUMENT|864=1|865=5|866=20160211|2576=0|870=5|871=113|872=N|871=104|872=0|871=112|872=N|871=114|872=N|871=115|872=N|1205=1|1206=0|1207=2|1208=2|561=1|711=1|311=[N/A]|457=1|458=1002|459=M|2874=SYM00117|15=THB|55=SYM00130|48=100000129|167=FC|541=20261222|965=1|228=300|231=300|1193=C|864=3|865=109|866=20260624|865=7|866=20261222|1145=20261222-06:15:00.000000000|865=5|866=20260624|2576=5|870=5|871=113|872=N|871=104|872=0.00000|871=112|872=N|871=114|872=N|871=115|872=N|1582=1|1583=103|1584=SEG7|1205=1|1206=0.09946|1207=21400.98840|1208=0.09946|1148=362.53437|1149=436.75833|561=1|711=1|311=SYM00121|309=100000120|305=M|457=1|458=1003|459=M|2874=SYM00121|15=THB|55=SYM00131|48=100000130|167=FC|541=20261029|965=1|228=5000|231=5000|1193=C|864=3|865=109|866=20260330|865=7|866=20261029|1145=20261029-09:55:00.000000000|865=5|866=20260330|2576=5|870=5|871=113|872=N|871=104|872=0.00000|871=112|872=N|871=114|872=N|871=115|872=N|1582=1|1583=103|1584=SEG7|1205=1|1206=0.04946|1207=21400.98840|1208=0.04946|1148=75.40330|1149=87.04868|561=1|711=1|311=SYM00117|309=100000116|305=M|457=1|458=1002|459=M|2874=SYM00117|15=THB|55=SYM00132|48=100000131|167=FP|541=20261127|965=1|228=5000|231=5000|1193=P|864=3|865=109|866=20260429|865=7|866=20261127|1145=20261127-09:55:00.000000000|865=5|866=20260429|2576=5|870=5|871=113|872=N|871=104|872=0.00000|871=112|872=N|871=114|872=N|871=115|872=N|1582=1|1583=103|1584=SEG7|1205=1|1206=0.04946|1207=21400.98840|1208=0.04946|1148=90.03540|1149=97.44598|561=1|711=1|311=SYM00117|309=100000116|305=M|457=1|458=1002|459=M|2874=SYM00117|15=THB|55=SYM00133|48=100000132|167=FP|541=20260629|965=1|228=5000|231=5000|1193=P|864=3|865=109|866=20251127|865=7|866=20260629|1145=20260629-09:55:00.000000000|865=5|866=20251127|2576=5|870=5|871=113|872=N|871=104|872=0.00000|871=112|872=N|871=114|872=N|871=115|872=N|1582=1|1583=103|1584=SEG7|1205=1|1206=0.04946|1207=21400.98840|1208=0.04946|1148=82.37125|1149=91.58090|561=1|711=1|311=SYM00117|309=100000116|305=M|457=1|458=1002|459=M|2874=SYM00117|15=THB|55=SYM00134|48=100000133|167=FC|541=20260723|965=1|228=300|231=300|1193=C|864=3|865=109|866=20260126|865=7|866=20260723|1145=20260723-06:15:00.000000000|865=5|866=20260126|2576=5|870=5|871=113|872=N|871=104|872=0.00000|871=112|872=N|871=114|872=N|871=115|872=N|1582=1|1583=103|1584=SEG7|1205=1|1206=0.09946|1207=21400.98840|1208=0.09946|1148=386.19300|1149=476.31600|561=1|711=1|311=SYM00121|309=100000120|305=M|457=1|458=1003|459=M|2874=SYM00121|15=THB|55=SYM00135|48=100000134|167=FP|541=20261229|965=1|228=5000|231=5000|1193=P|864=3|865=109|866=20260528|865=7|866=20261229|1145=20261229-09:55:00.000000000|865=5|866=20260528|2576=5|870=5|871=113|872=N|871=104|872=0.00000|871=112|872=N|871=114|872=N|871=115|872=N|1582=1|1583=103|1584=SEG7|1205=1|1206=0.04946|1207=21400.98840|1208=0.04946|1148=88.48543|1149=98.39700|561=1|711=1|311=SYM00117|309=100000116|305=M|457=1|458=1002|459=M|2874=SYM00117|15=THB|55=SYM00121|48=100000120|167=SPT|965=1|228=1|231=1|1193=C|107=SYM00121_INSTRUMENT|864=1|865=5|866=20201126|2576=0|870=5|871=113|872=N|871=104|872=0|871=112|872=N|871=114|872=N|871=115|872=N|1205=1|1206=0|1207=2|1208=2|561=1|711=1|311=[N/A]|457=1|458=1003|459=M|2874=SYM00121|15=THB|55=SYM00136|48=100000135|167=FC|541=20261124|965=1|228=300|231=300|1193=C|864=3|865=109|866=20260525|865=7|866=20261124|1145=20261124-06:15:00.000000000|865=5|866=20260525|2576=5|870=5|871=113|872=N|871=104|872=0.00000|871=112|872=N|871=114|872=N|871=115|872=N|1582=1|1583=103|1584=SEG7|1205=1|1206=0.09946|1207=21400.98840|1208=0.09946|1148=394.17584|1149=496.40346|561=1|711=1|311=SYM00121|309=100000120|305=M|457=1|458=1003|459=M|2874=SYM00121|15=THB|55=SYM00137|48=100000136|167=FC|541=20260929|965=1|228=5000|231=5000|1193=C|864=3|865=109|866=20260226|865=7|866=20260929|1145=20260929-09:55:00.000000000|865=5|866=20260226|2576=5|870=5|871=113|872=N|871=104|872=0.00000|871=112|872=N|871=114|872=N|871=115|872=N|1582=1|1583=103|1584=SEG7|1205=1|1206=0.04946|1207=21400.98840|1208=0.04946|1148=87.39402|1149=95.29712|561=1|711=1|311=SYM00117|309=100000116|305=M|457=1|458=1002|459=M|2874=SYM00117|15=THB|10=142|
8=FIXT.1.1|9=035457|35=y|49=EXCHANGE|56=CLIENT|34=2055|57=SESSION1|52=20260630-07:11:35.259547043|1396=Market Segment 3|320=1000000000000000003|560=0|393=1876|1301=EXMKT|1300=SEG5|893=N|146=53|55=SYM00138|48=100000137|167=CS|965=1|228=1|231=1|1193=C|107=SYM00138_INSTRUMENT|864=1|865=5|866=20110101|2576=5|870=5|871=113|872=Y|871=104|872=1.00000|871=112|872=A|871=114|872=Y|871=115|872=N|1582=2|1583=103|1584=SEG8|1583=7|1584=35|1205=8|1206=0.00990|1207=1.94423|1208=0.00990|1206=1.94720|1207=4.88770|1208=0.01970|1206=5.10400|1207=9.91308|1208=0.04946|1206=9.75500|1207=24.27529|1208=0.09946|1206=25.56750|1207=101.67983|1208=0.25138|1206=100.77000|1207=196.31018|1208=0.50050|1206=195.86000|1207=393.67016|1208=1.01270|1206=401.72000|1207=21400.98840|1208=1.94720|1148=15.57710|1149=27.77822|561=100|711=1|311=[N/A]|457=1|458=1004|459=M|2874=SYM00138|15=THB|55=SYM00003|48=100000003|167=CS|965=1|228=1|231=1|1193=C|107=SYM00003_INSTRUMENT|864=1|865=5|866=20110101|2576=5|870=5|871=113|872=Y|871=104|872=1.00000|871=112|872=A|871=114|872=Y|871=115|872=N|1582=2|1583=103|1584=SEG8|1583=7|1584=3|1205=8|1206=0.00990|1207=1.94423|1208=0.00990|1206=1.94720|1207=4.88770|1208=0.01970|1206=5.10400|1207=9.91308|1208=0.04946|1206=9.75500|1207=24.27529|1208=0.09946|1206=25.56750|1207=101.67983|1208=0.25138|1206=100.77000|1207=196.31018|1208=0.50050|1206=195.86000|1207=393.67016|1208=1.01270|1206=401.72000|1207=21400.98840|1208=1.94720|1148=12.19440|1149=21.55842|561=100|711=1|311=[N/A]|457=1|458=1005|459=M|2874=SYM00003|15=THB|55=SYM00139|48=100000138|167=CS|965=1|228=1|231=1|1193=C|107=SYM00139_INSTRUMENT|864=1|865=5|866=20110101|2576=5|870=5|871=113|872=Y|871=104|872=1.00000|871=112|872=A|871=114|872=Y|871=115|872=N|1582=2|1583=103|1584=SEG8|1583=7|1584=8|1205=8|1206=0.00990|1207=1.94423|1208=0.00990|1206=1.94720|1207=4.88770|1208=0.01970|1206=5.10400|1207=9.91308|1208=0.04946|1206=9.75500|1207=24.27529|1208=0.09946|1206=25.56750|1207=101.67983|1208=0.25138|1206=100.77000|1207=196.31018|1208=0.50050|1206=195.86000|1207=393.67016|1208=1.01270|1206=401.72000|1207=21400.98840|1208=1.94720|1148=27.05762|1149=49.22538|561=100|711=1|311=[N/A]|457=1|458=1006|459=M|2874=SYM00139|15=THB|55=SYM00102|48=100000102|167=CS|965=1|228=1|231=1|1193=C|107=SYM00102_INSTRUMENT|864=1|865=5|866=20110101|2576=5|870=5|871=113|872=Y|871=104|872=1.07000|871=112|872=A|871=114|872=Y|871=115|872=N|1582=2|1583=103|1584=SEG8|1583=7|1584=25|1205=8|1206=0.00990|1207=1.94423|1208=0.00990|1206=1.94720|1207=4.88770|1208=0.01970|1206=5.10400|1207=9.91308|1208=0.04946|1206=9.75500|1207=24.27529|1208=0.09946|1206=25.56750|1207=101.67983|1208=0.25138|1206=100.77000|1207=196.31018|1208=0.50050|1206=195.86000|1207=393.67016|1208=1.01270|1206=401.72000|1207=21400.98840|1208=1.94720|1148=1.34067|1149=2.42718|561=100|711=1|311=[N/A]|457=1|458=1007|459=M|2874=SYM00102|15=THB|55=SYM00089|48=100000089|167=CS|965=1|228=1|231=1|1193=C|107=SYM00089_INSTRUMENT|864=1|865=5|866=20110101|2576=5|870=5|871=113|872=Y|871=104|872=1.00000|871=112|872=A|871=114|872=Y|871=115|872=N|1582=2|1583=103|1584=SEG8|1583=7|1584=12|1205=8|1206=0.00990|1207=1.94423|1208=0.00990|1206=1.94720|1207=4.88770|1208=0.01970|1206=5.10400|1207=9.91308|1208=0.04946|1206=9.75500|1207=24.27529|1208=0.09946|1206=25.56750|1207=101.67983|1208=0.25138|1206=100.77000|1207=196.31018|1208=0.50050|1206=195.86000|1207=393.67016|1208=1.01270|1206=401.72000|1207=21400.98840|1208=1.94720|1148=16.52562|1149=30.31800|561=100|711=1|311=[N/A]|457=1|458=1008|459=M|2874=SYM00089|15=THB|55=SYM00110|48=100000110|167=CS|965=1|228=1|231=1|1193=C|107=SYM00110_INSTRUMENT|864=1|865=5|866=20110101|2576=5|870=5|871=113|872=Y|871=104|872=10.00000|871=112|872=A|871=114|872=Y|871=115|872=N|1582=2|1583=103|1584=SEG8|1583=7|1584=2|1205=8|1206=0.00990|1207=1.94423|1208=0.00990|1206=1.94720|1207=4.88770|1208=0.01970|1206=5.10400|1207=9.91308|1208=0.04946|1206=9.75500|1207=24.27529|1208=0.09946|1206=25.56750|1207=101.67983|1208=0.25138|1206=100.77000|1207=196.31018|1208=0.50050|1206=195.86000|1207=393.67016|1208=1.01270|1206=401.72000|1207=21400.98840|1208=1.94720|1148=125.68950|1149=241.87640|561=100|711=1|311=[N/A]|457=1|458=1009|459=M|2874=SYM00110|15=THB|55=SYM00140|48=100000139|167=CS|965=1|228=1|231=1|1193=C|107=SYM00140_INSTRUMENT|864=1|865=5|866=20110101|2576=5|870=5|871=113|872=Y|871=104|872=1.00000|871=112|872=A|871=114|872=Y|871=115|872=N|1582=2|1583=103|1584=SEG8|1583=7|1584=5|1205=8|1206=0.00990|1207=1.94423|1208=0.00990|1206=1.94720|1207=4.88770|1208=0.01970|1206=5.10400|1207=9.91308|1208=0.04946|1206=9.75500|1207=24.27529|1208=0.09946|1206=25.56750|1207=101.67983|1208=0.25138|1206=100.77000|1207=196.31018|1208=0.50050|1206=195.86000|1207=393.67016|1208=1.01270|1206=401.72000|1207=21400.98840|1208=1.94720|1148=11.26496|1149=21.27216|561=100|711=1|311=[N/A]|457=1|458=1010|459=M|2874=SYM00140|15=THB|55=SYM00081|48=100000081|167=CS|965=1|228=1|231=1|1193=C|107=SYM00081_INSTRUMENT|864=1|865=5|866=20141120|2576=5|870=5|871=113|872=Y|871=104|872=1.00000|871=112|872=A|871=114|872=Y|871=115|872=N|1582=2|1583=103|1584=SEG8|1583=7|1584=12|1205=8|1206=0.00990|1207=1.94423|1208=0.00990|1206=1.94720|1207=4.88770|1208=0.01970|1206=5.10400|1207=9.91308|1208=0.04946|1206=9.75500|1207=24.27529|1208=0.09946|1206=25.56750|1207=101.67983|1208=0.25138|1206=100.77000|1207=196.31018|1208=0.50050|1206=195.86000|1207=393.67016|1208=1.01270|1206=401.72000|1207=21400.98840|1208=1.94720|1148=25.29165|1149=47.02898|561=100|711=1|311=[N/A]|457=1|458=1011|459=M|2874=SYM00081|15=THB|55=SYM00087|48=100000087|167=CS|965=1|228=1|231=1|1193=C|107=SYM00087_INSTRUMENT|864=1|865=5|866=20110101|2576=5|870=5|871=113|872=Y|871=104|872=1.00000|871=112|872=A|871=114|872=Y|871=115|872=N|1582=2|1583=103|1584=SEG8|1583=7|1584=5|1205=8|1206=0.00990|1207=1.94423|1208=0.00990|1206=1.94720|1207=4.88770|1208=0.01970|1206=5.10400|1207=9.91308|1208=0.04946|1206=9.75500|1207=24.27529|1208=0.09946|1206=25.56750|1207=101.67983|1208=0.25138|1206=100.77000|1207=196.31018|1208=0.50050|1206=195.86000|1207=393.67016|1208=1.01270|1206=401.72000|1207=21400.98840|1208=1.94720|1148=36.65962|1149=64.93440|561=100|711=1|311=[N/A]|457=1|458=1012|459=M|2874=SYM00087|15=THB|55=SYM00141|48=100000140|167=CS|965=1|228=1|231=1|1193=C|107=SYM00141_INSTRUMENT|864=1|865=5|866=20090819|2576=5|870=5|871=113|872=Y|871=104|872=1.00000|871=112|872=A|871=114|872=Y|871=115|872=N|1582=2|1583=103|1584=SEG8|1583=7|1584=5|1205=8|1206=0.00990|1207=1.94423|1208=0.00990|1206=1.94720|1207=4.88770|1208=0.01970|1206=5.10400|1207=9.91308|1208=0.04946|1206=9.75500|1207=24.27529|1208=0.09946|1206=25.56750|1207=101.67983|1208=0.25138|1206=100.77000|1207=196.31018|1208=0.50050|1206=195.86000|1207=393.67016|1208=1.01270|1206=401.72000|1207=21400.98840|1208=1.94720|1148=4.51122|1149=8.25180|561=100|711=1|311=[N/A]|457=1|458=1013|459=M|2874=SYM00141|15=THB|55=SYM00142|48=100000141|167=CS|965=1|228=1|231=1|1193=C|107=SYM00142_INSTRUMENT|864=1|865=5|866=20121126|2576=5|870=5|871=113|872=Y|871=104|872=0.50000|871=112|872=A|871=114|872=Y|871=115|872=N|1582=2|1583=103|1584=SEG8|1583=7|1584=11|1205=8|1206=0.00990|1207=1.94423|1208=0.00990|1206=1.94720|1207=4.88770|1208=0.01970|1206=5.10400|1207=9.91308|1208=0.04946|1206=9.75500|1207=24.27529|1208=0.09946|1206=25.56750|1207=101.67983|1208=0.25138|1206=100.77000|1207=196.31018|1208=0.50050|1206=195.86000|1207=393.67016|1208=1.01270|1206=401.72000|1207=21400.98840|1208=1.94720|1148=7.69923|1149=13.87672|561=100|711=1|311=[N/A]|457=1|458=1014|459=M|2874=SYM00142|15=THB|55=SYM00143|48=100000142|167=CS|965=1|228=1|231=1|1193=C|107=SYM00143_INSTRUMENT|864=1|865=5|866=20110101|2576=5|870=5|871=113|872=Y|871=104|872=1.00000|871=112|872=A|871=114|872=Y|871=115|872=N|1582=2|1583=103|1584=SEG8|1583=7|1584=9|1205=8|1206=0.00990|1207=1.94423|1208=0.00990|1206=1.94720|1207=4.88770|1208=0.01970|1206=5.10400|1207=9.91308|1208=0.04946|1206=9.75500|1207=24.27529|1208=0.09946|1206=25.56750|1207=101.67983|1208=0.25138|1206=100.77000|1207=196.31018|1208=0.50050|1206=195.86000|1207=393.67016|1208=1.01270|1206=401.72000|1207=21400.98840|1208=1.94720|1148=2.38437|1149=4.41378|561=100|711=1|311=[N/A]|457=1|458=1015|459=M|2874=SYM00143|15=THB|55=SYM00107|48=100000107|167=CS|965=1|228=1|231=1|1193=C|107=SYM00107_INSTRUMENT|864=1|865=5|866=20110101|2576=5|870=5|871=113|872=Y|871=104|872=1.00000|871=112|872=A|871=114|872=Y|871=115|872=N|1582=2|1583=103|1584=SEG8|1583=7|1584=1|1205=8|1206=0.00990|1207=1.94423|1208=0.00990|1206=1.94720|1207=4.88770|1208=0.01970|1206=5.10400|1207=9.91308|1208=0.04946|1206=9.75500|1207=24.27529|1208=0.09946|1206=25.56750|1207=101.67983|1208=0.25138|1206=100.77000|1207=196.31018|1208=0.50050|1206=195.86000|1207=393.67016|1208=1.01270|1206=401.72000|1207=21400.98840|1208=1.94720|1148=11.53278|1149=20.36078|561=100|711=1|311=[N/A]|457=1|458=1016|459=M|2874=SYM00107|15=THB|55=SYM00144|48=100000143|167=CS|965=1|228=1|231=1|1193=C|107=SYM00144_INSTRUMENT|864=1|865=5|866=20170718|2576=5|870=5|871=113|872=Y|871=104|872=2.00000|871=112|872=A|871=114|872=Y|871=115|872=N|1582=2|1583=103|1584=SEG8|1583=7|1584=9|1205=8|1206=0.00990|1207=1.94423|1208=0.00990|1206=1.94720|1207=4.88770|1208=0.01970|1206=5.10400|1207=9.91308|1208=0.04946|1206=9.75500|1207=24.27529|1208=0.09946|1206=25.56750|1207=101.67983|1208=0.25138|1206=100.77000|1207=196.31018|1208=0.50050|1206=195.86000|1207=393.67016|1208=1.01270|1206=401.72000|1207=21400.98840|1208=1.94720|1148=11.95806|1149=22.61147|561=100|711=1|311=[N/A]|457=1|458=1017|459=M|2874=SYM00144|15=THB|55=SYM00105|48=100000105|167=CS|965=1|228=1|231=1|1193=C|107=SYM00105_INSTRUMENT|864=1|865=5|866=20110101|2576=5|870=5|871=113|872=Y|871=104|872=5.15000|871=112|872=A|871=114|872=Y|871=115|872=N|1582=2|1583=103|1584=SEG8|1583=7|1584=2|1205=8|1206=0.00990|1207=1.94423|1208=0.00990|1206=1.94720|1207=4.88770|1208=0.01970|1206=5.10400|1207=9.91308|1208=0.04946|1206=9.75500|1207=24.27529|1208=0.09946|1206=25.56750|1207=101.67983|1208=0.25138|1206=100.77000|1207=196.31018|1208=0.50050|1206=195.86000|1207=393.67016|1208=1.01270|1206=401.72000|1207=21400.98840|1208=1.94720|1148=11.95806|1149=22.61147|561=100|711=1|311=[N/A]|457=1|458=1018|459=M|2874=SYM00105|15=THB|55=SYM00018|48=100000018|167=CS|965=1|228=1|231=1|1193=C|107=SYM00018_INSTRUMENT|864=1|865=5|866=20090616|2576=5|870=5|871=113|872=N|871=104|872=1.00000|871=112|872=A|871=114|872=N|871=115|872=N|1582=2|1583=103|1584=SEG8|1583=7|1584=35|1205=8|1206=0.00990|1207=1.94423|1208=0.00990|1206=1.94720|1207=4.88770|1208=0.01970|1206=5.10400|1207=9.91308|1208=0.04946|1206=9.75500|1207=24.27529|1208=0.09946|1206=25.56750|1207=101.67983|1208=0.25138|1206=100.77000|1207=196.31018|1208=0.50050|1206=195.86000|1207=393.67016|1208=1.01270|1206=401.72000|1207=21400.98840|1208=1.94720|1148=0.10912|1149=0.18907|561=100|711=1|311=[N/A]|457=1|458=1019|459=M|2874=SYM00018|15=THB|55=SYM00145|48=100000144|167=CS|965=1|228=1|231=1|1193=C|107=SYM00145_INSTRUMENT|864=1|865=5|866=20110101|2576=5|870=5|871=113|872=Y|871=104|872=1.00000|871=112|872=A|871=114|872=Y|871=115|872=N|1582=2|1583=103|1584=SEG8|1583=7|1584=25|1205=8|1206=0.00990|1207=1.94423|1208=0.00990|1206=1.94720|1207=4.88770|1208=0.01970|1206=5.10400|1207=9.91308|1208=0.04946|1206=9.75500|1207=24.27529|1208=0.09946|1206=25.56750|1207=101.67983|1208=0.25138|1206=100.77000|1207=196.31018|1208=0.50050|1206=195.86000|1207=393.67016|1208=1.01270|1206=401.72000|1207=21400.98840|1208=1.94720|1148=1.97071|1149=3.77142|561=100|711=1|311=[N/A]|457=1|458=1020|459=M|2874=SYM00145|15=THB|55=SYM00095|48=100000095|167=CS|965=1|228=1|231=1|1193=C|107=SYM00095_INSTRUMENT|864=1|865=5|866=20090115|2576=5|870=5|871=113|872=Y|871=104|872=10.00000|871=112|872=A|871=114|872=Y|871=115|872=N|1582=2|1583=103|1584=SEG8|1583=7|1584=2|1205=8|1206=0.00990|1207=1.94423|1208=0.00990|1206=1.94720|1207=4.88770|1208=0.01970|1206=5.10400|1207=9.91308|1208=0.04946|1206=9.75500|1207=24.27529|1208=0.09946|1206=25.56750|1207=101.67983|1208=0.25138|1206=100.77000|1207=196.31018|1208=0.50050|1206=195.86000|1207=393.67016|1208=1.01270|1206=401.72000|1207=21400.98840|1208=1.94720|1148=67.45190|1149=128.27500|561=100|711=1|311=[N/A]|457=1|458=1021|459=M|2874=SYM00095|15=THB|55=SYM00146|48=100000145|167=CS|965=1|228=1|231=1|1193=C|107=SYM00146_INSTRUMENT|864=1|865=5|866=20110101|2576=5|870=5|871=113|872=Y|871=104|872=0.10000|871=112|872=A|871=114|872=Y|871=115|872=N|1582=2|1583=103|1584=SEG8|1583=7|1584=9|1205=8|1206=0.00990|1207=1.94423|1208=0.00990|1206=1.94720|1207=4.88770|1208=0.01970|1206=5.10400|1207=9.91308|1208=0.04946|1206=9.75500|1207=24.27529|1208=0.09946|1206=25.56750|1207=101.67983|1208=0.25138|1206=100.77000|1207=196.31018|1208=0.50050|1206=195.86000|1207=393.67016|1208=1.01270|1206=401.72000|1207=21400.98840|1208=1.94720|1148=0.12256|1149=0.20498|561=100|711=1|311=[N/A]|457=1|458=1022|459=M|2874=SYM00146|15=THB|55=SYM00147|48=100000146|167=CS|965=1|228=1|231=1|1193=C|107=SYM00147_INSTRUMENT|864=1|865=5|866=20151204|2576=5|870=5|871=113|872=Y|871=104|872=6.92000|871=112|872=A|871=114|872=Y|871=115|872=N|1582=2|1583=103|1584=SEG8|1583=7|1584=9|1205=8|1206=0.00990|1207=1.94423|1208=0.00990|1206=1.94720|1207=4.88770|1208=0.01970|1206=5.10400|1207=9.91308|1208=0.04946|1206=9.75500|1207=24.27529|1208=0.09946|1206=25.56750|1207=101.67983|1208=0.25138|1206=100.77000|1207=196.31018|1208=0.50050|1206=195.86000|1207=393.67016|1208=1.01270|1206=401.72000|1207=21400.98840|1208=1.94720|1148=4.90441|1149=9.23832|561=100|711=1|311=[N/A]|457=1|458=1023|459=M|2874=SYM00147|15=THB|55=SYM00082|48=100000082|167=CS|965=1|228=1|231=1|1193=C|107=SYM00082_INSTRUMENT|864=1|865=5|866=20110101|2576=5|870=5|871=113|872=Y|871=104|872=0.10000|871=112|872=A|871=114|872=Y|871=115|872=N|1582=2|1583=103|1584=SEG8|1583=7|1584=13|1205=8|1206=0.00990|1207=1.94423|1208=0.00990|1206=1.94720|1207=4.88770|1208=0.01970|1206=5.10400|1207=9.91308|1208=0.04946|1206=9.75500|1207=24.27529|1208=0.09946|1206=25.56750|1207=101.67983|1208=0.25138|1206=100.77000|1207=196.31018|1208=0.50050|1206=195.86000|1207=393.67016|1208=1.01270|1206=401.72000|1207=21400.98840|1208=1.94720|1148=15.41710|1149=28.14960|561=100|711=1|311=[N/A]|457=1|458=1024|459=M|2874=SYM00082|15=THB|55=SYM00148|48=100000147|167=CS|965=1|228=1|231=1|1193=C|107=SYM00148_INSTRUMENT|864=1|865=5|866=20110101|2576=5|870=5|871=113|872=Y|871=104|872=10.00000|871=112|872=A|871=114|872=Y|871=115|872=N|1582=2|1583=103|1584=SEG8|1583=7|1584=9|1205=8|1206=0.00990|1207=1.94423|1208=0.00990|1206=1.94720|1207=4.88770|1208=0.01970|1206=5.10400|1207=9.91308|1208=0.04946|1206=9.75500|1207=24.27529|1208=0.09946|1206=25.56750|1207=101.67983|1208=0.25138|1206=100.77000|1207=196.31018|1208=0.50050|1206=195.86000|1207=393.67016|1208=1.01270|1206=401.72000|1207=21400.98840|1208=1.94720|1148=31.29280|1149=60.39830|561=100|711=1|311=[N/A]|457=1|458=1025|459=M|2874=SYM00148|15=THB|55=SYM00149|48=100000148|167=CS|965=1|228=1|231=1|1193=C|107=SYM00149_INSTRUMENT|864=1|865=5|866=20110101|2576=5|870=5|871=113|872=Y|871=104|872=1.00000|871=112|872=A|871=114|872=Y|871=115|872=N|1582=2|1583=103|1584=SEG8|1583=7|1584=35|1205=8|1206=0.00990|1207=1.94423|1208=0.00990|1206=1.94720|1207=4.88770|1208=0.01970|1206=5.10400|1207=9.91308|1208=0.04946|1206=9.75500|1207=24.27529|1208=0.09946|1206=25.56750|1207=101.67983|1208=0.25138|1206=100.77000|1207=196.31018|1208=0.50050|1206=195.86000|1207=393.67016|1208=1.01270|1206=401.72000|1207=21400.98840|1208=1.94720|1148=1.83154|1149=3.34534|561=100|711=1|311=[N/A]|457=1|458=1026|459=M|2874=SYM00149|15=THB|55=SYM00150|48=100000149|167=CS|965=1|228=1|231=1|1193=C|107=SYM00150_INSTRUMENT|864=1|865=5|866=20110101|2576=5|870=5|871=113|872=Y|871=104|872=1.00000|871=112|872=A|871=114|872=Y|871=115|872=N|1582=2|1583=103|1584=SEG8|1583=7|1584=3|1205=8|1206=0.00990|1207=1.94423|1208=0.00990|1206=1.94720|1207=4.88770|1208=0.01970|1206=5.10400|1207=9.91308|1208=0.04946|1206=9.75500|1207=24.27529|1208=0.09946|1206=25.56750|1207=101.67983|1208=0.25138|1206=100.77000|1207=196.31018|1208=0.50050|1206=195.86000|1207=393.67016|1208=1.01270|1206=401.72000|1207=21400.98840|1208=1.94720|1148=1.47544|1149=2.69824|561=100|711=1|311=[N/A]|457=1|458=1027|459=M|2874=SYM00150|15=THB|55=SYM00094|48=100000094|167=CS|965=1|228=1|231=1|1193=C|107=SYM00094_INSTRUMENT|864=1|865=5|866=20110101|2576=5|870=5|871=113|872=Y|871=104|872=0.95000|871=112|872=A|871=114|872=Y|871=115|872=N|1582=2|1583=103|1584=SEG8|1583=7|1584=2|1205=8|1206=0.00990|1207=1.94423|1208=0.00990|1206=1.94720|1207=4.88770|1208=0.01970|1206=5.10400|1207=9.91308|1208=0.04946|1206=9.75500|1207=24.27529|1208=0.09946|1206=25.56750|1207=101.67983|1208=0.25138|1206=100.77000|1207=196.31018|1208=0.50050|1206=195.86000|1207=393.67016|1208=1.01270|1206=401.72000|1207=21400.98840|1208=1.94720|1148=1.64804|1149=3.03848|561=100|711=1|311=[N/A]|457=1|458=1028|459=M|2874=SYM00094|15=THB|55=SYM00086|48=100000086|167=CS|965=1|228=1|231=1|1193=C|107=SYM00086_INSTRUMENT|864=1|865=5|866=20110101|2576=5|870=5|871=113|872=Y|871=104|872=4.00000|871=112|872=A|871=114|872=Y|871=115|872=N|1582=2|1583=103|1584=SEG8|1583=7|1584=28|1205=8|1206=0.00990|1207=1.94423|1208=0.00990|1206=1.94720|1207=4.88770|1208=0.01970|1206=5.10400|1207=9.91308|1208=0.04946|1206=9.75500|1207=24.27529|1208=0.09946|1206=25.56750|1207=101.67983|1208=0.25138|1206=100.77000|1207=196.31018|1208=0.50050|1206=195.86000|1207=393.67016|1208=1.01270|1206=401.72000|1207=21400.98840|1208=1.94720|1148=1.46825|1149=2.79836|561=100|711=1|311=[N/A]|457=1|458=1029|459=M|2874=SYM00086|15=THB|55=SYM00083|48=100000083|167=CS|965=1|228=1|231=1|1193=C|107=SYM00083_INSTRUMENT|864=1|865=5|866=20151230|2576=5|870=5|871=113|872=Y|871=104|872=1.00000|871=112|872=A|871=114|872=Y|871=115|872=N|1582=2|1583=103|1584=SEG8|1583=7|1584=28|1205=8|1206=0.00990|1207=1.94423|1208=0.00990|1206=1.94720|1207=4.88770|1208=0.01970|1206=5.10400|1207=9.91308|1208=0.04946|1206=9.75500|1207=24.27529|1208=0.09946|1206=25.56750|1207=101.67983|1208=0.25138|1206=100.77000|1207=196.31018|1208=0.50050|1206=195.86000|1207=393.67016|1208=1.01270|1206=401.72000|1207=21400.98840|1208=1.94720|1148=4.26014|1149=7.82621|561=100|711=1|311=[N/A]|457=1|458=1030|459=M|2874=SYM00083|15=THB|55=SYM00151|48=100000150|167=CS|965=1|228=1|231=1|1193=C|107=SYM00151_INSTRUMENT|864=1|865=5|866=20151006|2576=5|870=5|871=113|872=Y|871=104|872=0.50000|871=112|872=A|871=114|872=Y|871=115|872=N|1582=2|1583=103|1584=SEG8|1583=7|1584=25|1205=8|1206=0.00990|1207=1.94423|1208=0.00990|1206=1.94720|1207=4.88770|1208=0.01970|1206=5.10400|1207=9.91308|1208=0.04946|1206=9.75500|1207=24.27529|1208=0.09946|1206=25.56750|1207=101.67983|1208=0.25138|1206=100.77000|1207=196.31018|1208=0.50050|1206=195.86000|1207=393.67016|1208=1.01270|1206=401.72000|1207=21400.98840|1208=1.94720|1148=1.22525|1149=2.36440|561=100|711=1|311=[N/A]|457=1|458=1031|459=M|2874=SYM00151|15=THB|55=SYM00152|48=100000151|167=CS|965=1|228=1|231=1|1193=C|107=SYM00152_INSTRUMENT|864=1|865=5|866=20101019|2576=5|870=5|871=113|872=Y|871=104|872=0.25000|871=112|872=A|871=114|872=Y|871=115|872=N|1582=2|1583=103|1584=SEG8|1583=7|1584=9|1205=8|1206=0.00990|1207=1.94423|1208=0.00990|1206=1.94720|1207=4.88770|1208=0.01970|1206=5.10400|1207=9.91308|1208=0.04946|1206=9.75500|1207=24.27529|1208=0.09946|1206=25.56750|1207=101.67983|1208=0.25138|1206=100.77000|1207=196.31018|1208=0.50050|1206=195.86000|1207=393.67016|1208=1.01270|1206=401.72000|1207=21400.98840|1208=1.94720|1148=2.64510|1149=4.96519|561=100|711=1|311=[N/A]|457=1|458=1032|459=M|2874=SYM00152|15=THB|55=SYM00106|48=100000106|167=CS|965=1|228=1|231=1|1193=C|107=SYM00106_INSTRUMENT|864=1|865=5|866=20110101|2576=5|870=5|871=113|872=Y|871=104|872=1.00000|871=112|872=A|871=114|872=Y|871=115|872=N|1582=2|1583=103|1584=SEG8|1583=7|1584=9|1205=8|1206=0.00990|1207=1.94423|1208=0.00990|1206=1.94720|1207=4.88770|1208=0.01970|1206=5.10400|1207=9.91308|1208=0.04946|1206=9.75500|1207=24.27529|1208=0.09946|1206=25.56750|1207=101.67983|1208=0.25138|1206=100.77000|1207=196.31018|1208=0.50050|1206=195.86000|1207=393.67016|1208=1.01270|1206=401.72000|1207=21400.98840|1208=1.94720|1148=25.16595|1149=47.71910|561=100|711=1|311=[N/A]|457=1|458=1033|459=M|2874=SYM00106|15=THB|55=SYM00153|48=100000152|167=CS|965=1|228=1|231=1|1193=C|107=SYM00153_INSTRUMENT|864=1|865=5|866=20140507|2576=5|870=5|871=113|872=Y|871=104|872=1.00000|871=112|872=A|871=114|872=Y|871=115|872=N|1582=2|1583=103|1584=SEG8|1583=7|1584=11|1205=8|1206=0.00990|1207=1.94423|1208=0.00990|1206=1.94720|1207=4.88770|1208=0.01970|1206=5.10400|1207=9.91308|1208=0.04946|1206=9.75500|1207=24.27529|1208=0.09946|1206=25.56750|1207=101.67983|1208=0.25138|1206=100.77000|1207=196.31018|1208=0.50050|1206=195.86000|1207=393.67016|1208=1.01270|1206=401.72000|1207=21400.98840|1208=1.94720|1148=15.82308|1149=28.04275|561=100|711=1|311=[N/A]|457=1|458=1034|459=M|2874=SYM00153|15=THB|55=SYM00154|48=100000153|167=CS|965=1|228=1|231=1|1193=C|107=SYM00154_INSTRUMENT|864=1|865=5|866=20171206|2576=5|870=5|871=113|872=Y|871=104|872=1.00000|871=112|872=A|871=114|872=Y|871=115|872=N|1582=2|1583=103|1584=SEG8|1583=7|1584=13|1205=8|1206=0.00990|1207=1.94423|1208=0.00990|1206=1.94720|1207=4.88770|1208=0.01970|1206=5.10400|1207=9.91308|1208=0.04946|1206=9.75500|1207=24.27529|1208=0.09946|1206=25.56750|1207=101.67983|1208=0.25138|1206=100.77000|1207=196.31018|1208=0.50050|1206=195.86000|1207=393.67016|1208=1.01270|1206=401.72000|1207=21400.98840|1208=1.94720|1148=4.96519|1149=9.08870|561=100|711=1|311=[N/A]|457=1|458=1035|459=M|2874=SYM00154|15=THB|55=SYM00092|48=100000092|167=CS|965=1|228=1|231=1|1193=C|107=SYM00092_INSTRUMENT|864=1|865=5|866=20110101|2576=5|870=5|871=113|872=Y|871=104|872=1.00000|871=112|872=A|871=114|872=Y|871=115|872=N|1582=2|1583=103|1584=SEG8|1583=7|1584=9|1205=8|1206=0.00990|1207=1.94423|1208=0.00990|1206=1.94720|1207=4.88770|1208=0.01970|1206=5.10400|1207=9.91308|1208=0.04946|1206=9.75500|1207=24.27529|1208=0.09946|1206=25.56750|1207=101.67983|1208=0.25138|1206=100.77000|1207=196.31018|1208=0.50050|1206=195.86000|1207=393.67016|1208=1.01270|1206=401.72000|1207=21400.98840|1208=1.94720|1148=25.29165|1149=48.54465|561=100|711=1|311=[N/A]|457=1|458=1036|459=M|2874=SYM00092|15=THB|55=SYM00085|48=100000085|167=CS|965=1|228=1|231=1|1193=C|107=SYM00085_INSTRUMENT|864=1|865=5|866=20110101|2576=5|870=5|871=113|872=Y|871=104|872=0.10000|871=112|872=A|871=114|872=Y|871=115|872=N|1582=2|1583=103|1584=SEG8|1583=7|1584=8|1205=8|1206=0.00990|1207=1.94423|1208=0.00990|1206=1.94720|1207=4.88770|1208=0.01970|1206=5.10400|1207=9.91308|1208=0.04946|1206=9.75500|1207=24.27529|1208=0.09946|1206=25.56750|1207=101.67983|1208=0.25138|1206=100.77000|1207=196.31018|1208=0.50050|1206=195.86000|1207=393.67016|1208=1.01270|1206=401.72000|1207=21400.98840|1208=1.94720|1148=244.38750|1149=442.46280|561=100|711=1|311=[N/A]|457=1|458=1037|459=M|2874=SYM00085|15=THB|55=SYM00155|48=100000154|167=CS|965=1|228=1|231=1|1193=C|107=SYM00155_INSTRUMENT|864=1|865=5|866=20131118|2576=5|870=5|871=113|872=Y|871=104|872=0.50000|871=112|872=A|871=114|872=Y|871=115|872=N|1582=2|1583=103|1584=SEG8|1583=7|1584=5|1205=8|1206=0.00990|1207=1.94423|1208=0.00990|1206=1.94720|1207=4.88770|1208=0.01970|1206=5.10400|1207=9.91308|1208=0.04946|1206=9.75500|1207=24.27529|1208=0.09946|1206=25.56750|1207=101.67983|1208=0.25138|1206=100.77000|1207=196.31018|1208=0.50050|1206=195.86000|1207=393.67016|1208=1.01270|1206=401.72000|1207=21400.98840|1208=1.94720|1148=25.27057|1149=45.70425|561=100|711=1|311=[N/A]|457=1|458=1038|459=M|2874=SYM00155|15=THB|55=SYM00156|48=100000155|167=CS|965=1|228=1|231=1|1193=C|107=SYM00156_INSTRUMENT|864=1|865=5|866=20210210|2576=5|870=5|871=113|872=Y|871=104|872=10.00000|871=112|872=A|871=114|872=Y|871=115|872=N|1582=2|1583=103|1584=SEG8|1583=7|1584=9|1205=8|1206=0.00990|1207=1.94423|1208=0.00990|1206=1.94720|1207=4.88770|1208=0.01970|1206=5.10400|1207=9.91308|1208=0.04946|1206=9.75500|1207=24.27529|1208=0.09946|1206=25.56750|1207=101.67983|1208=0.25138|1206=100.77000|1207=196.31018|1208=0.50050|1206=195.86000|1207=393.67016|1208=1.01270|1206=401.72000|1207=21400.98840|1208=1.94720|1148=9.74171|1149=17.78007|561=100|711=1|311=[N/A]|457=1|458=1039|459=M|2874=SYM00156|15=THB|55=SYM00157|48=100000156|167=CS|965=1|228=1|231=1|1193=C|107=SYM00157_INSTRUMENT|864=1|865=5|866=20110101|2576=5|870=5|871=113|872=Y|871=104|872=1.00000|871=112|872=A|871=114|872=Y|871=115|872=N|1582=2|1583=103|1584=SEG8|1583=7|1584=25|1205=8|1206=0.00990|1207=1.94423|1208=0.00990|1206=1.94720|1207=4.88770|1208=0.01970|1206=5.10400|1207=9.91308|1208=0.04946|1206=9.75500|1207=24.27529|1208=0.09946|1206=25.56750|1207=101.67983|1208=0.25138|1206=100.77000|1207=196.31018|1208=0.50050|1206=195.86000|1207=393.67016|1208=1.01270|1206=401.72000|1207=21400.98840|1208=1.94720|1148=16.68957|1149=30.31800|561=100|711=1|311=[N/A]|457=1|458=1040|459=M|2874=SYM00157|15=THB|55=SYM00158|48=100000157|167=CS|965=1|228=1|231=1|1193=C|107=SYM00158_INSTRUMENT|864=1|865=5|866=20110101|2576=5|870=5|871=113|872=Y|871=104|872=1.00000|871=112|872=A|871=114|872=Y|871=115|872=N|1582=2|1583=103|1584=SEG8|1583=7|1584=9|1205=8|1206=0.00990|1207=1.94423|1208=0.00990|1206=1.94720|1207=4.88770|1208=0.01970|1206=5.10400|1207=9.91308|1208=0.04946|1206=9.75500|1207=24.27529|1208=0.09946|1206=25.56750|1207=101.67983|1208=0.25138|1206=100.77000|1207=196.31018|1208=0.50050|1206=195.86000|1207=393.67016|1208=1.01270|1206=401.72000|1207=21400.98840|1208=1.94720|1148=6.46032|1149=11.59298|561=100|711=1|311=[N/A]|457=1|458=1041|459=M|2874=SYM00158|15=THB|55=SYM00084|48=100000084|167=CS|965=1|228=1|231=1|1193=C|107=SYM00084_INSTRUMENT|864=1|865=5|866=20110101|2576=5|870=5|871=113|872=Y|871=104|872=1.00000|871=112|872=A|871=114|872=Y|871=115|872=N|1582=2|1583=103|1584=SEG8|1583=7|1584=9|1205=8|1206=0.00990|1207=1.94423|1208=0.00990|1206=1.94720|1207=4.88770|1208=0.01970|1206=5.10400|1207=9.91308|1208=0.04946|1206=9.75500|1207=24.27529|1208=0.09946|1206=25.56750|1207=101.67983|1208=0.25138|1206=100.77000|1207=196.31018|1208=0.50050|1206=195.86000|1207=393.67016|1208=1.01270|1206=401.72000|1207=21400.98840|1208=1.94720|1148=0.99644|1149=1.86989|561=100|711=1|311=[N/A]|457=1|458=1042|459=M|2874=SYM00084|15=THB|55=SYM00159|48=100000158|167=CS|965=1|228=1|231=1|1193=C|107=SYM00159_INSTRUMENT|864=1|865=5|866=20170404|2576=5|870=5|871=113|872=Y|871=104|872=1.00000|871=112|872=A|871=114|872=Y|871=115|872=N|1582=2|1583=103|1584=SEG8|1583=7|1584=9|1205=8|1206=0.00990|1207=1.94423|1208=0.00990|1206=1.94720|1207=4.88770|1208=0.01970|1206=5.10400|1207=9.91308|1208=0.04946|1206=9.75500|1207=24.27529|1208=0.09946|1206=25.56750|1207=101.67983|1208=0.25138|1206=100.77000|1207=196.31018|1208=0.50050|1206=195.86000|1207=393.67016|1208=1.01270|1206=401.72000|1207=21400.98840|1208=1.94720|1148=1.16620|1149=2.19230|561=100|711=1|311=[N/A]|457=1|458=1043|459=M|2874=SYM00159|15=THB|55=SYM00160|48=100000159|167=CS|965=1|228=1|231=1|1193=C|107=SYM00160_INSTRUMENT|864=1|865=5|866=20160927|2576=5|870=5|871=113|872=Y|871=104|872=5.00000|871=112|872=A|871=114|872=Y|871=115|872=N|1582=2|1583=103|1584=SEG8|1583=7|1584=9|1205=8|1206=0.00990|1207=1.94423|1208=0.00990|1206=1.94720|1207=4.88770|1208=0.01970|1206=5.10400|1207=9.91308|1208=0.04946|1206=9.75500|1207=24.27529|1208=0.09946|1206=25.56750|1207=101.67983|1208=0.25138|1206=100.77000|1207=196.31018|1208=0.50050|1206=195.86000|1207=393.67016|1208=1.01270|1206=401.72000|1207=21400.98840|1208=1.94720|1148=5.19069|1149=9.49843|561=100|711=1|311=[N/A]|457=1|458=1044|459=M|2874=SYM00160|15=THB|55=SYM00108|48=100000108|167=CS|965=1|228=1|231=1|1193=C|107=SYM00108_INSTRUMENT|864=1|865=5|866=20200701|2576=5|870=5|871=113|872=Y|871=104|872=0.50000|871=112|872=A|871=114|872=Y|871=115|872=N|1582=2|1583=103|1584=SEG8|1583=7|1584=22|1205=8|1206=0.00990|1207=1.94423|1208=0.00990|1206=1.94720|1207=4.88770|1208=0.01970|1206=5.10400|1207=9.91308|1208=0.04946|1206=9.75500|1207=24.27529|1208=0.09946|1206=25.56750|1207=101.67983|1208=0.25138|1206=100.77000|1207=196.31018|1208=0.50050|1206=195.86000|1207=393.67016|1208=1.01270|1206=401.72000|1207=21400.98840|1208=1.94720|1148=5.43992|1149=9.86860|561=100|711=1|311=[N/A]|457=1|458=1045|459=M|2874=SYM00108|15=THB|55=SYM00161|48=100000160|167=CS|965=1|228=1|231=1|1193=C|107=SYM00161_INSTRUMENT|864=1|865=5|866=20170407|2576=5|870=5|871=113|872=Y|871=104|872=1.00000|871=112|872=A|871=114|872=Y|871=115|872=N|1582=2|1583=103|1584=SEG8|1583=7|1584=9|1205=8|1206=0.00990|1207=1.94423|1208=0.00990|1206=1.94720|1207=4.88770|1208=0.01970|1206=5.10400|1207=9.91308|1208=0.04946|1206=9.75500|1207=24.27529|1208=0.09946|1206=25.56750|1207=101.67983|1208=0.25138|1206=100.77000|1207=196.31018|1208=0.50050|1206=195.86000|1207=393.67016|1208=1.01270|1206=401.72000|1207=21400.98840|1208=1.94720|1148=3.56968|1149=6.51634|561=100|711=1|311=[N/A]|457=1|458=1046|459=M|2874=SYM00161|15=THB|55=SYM00162|48=100000161|167=CS|965=1|228=1|231=1|1193=C|107=SYM00162_INSTRUMENT|864=1|865=5|866=20110101|2576=5|870=5|871=113|872=Y|871=104|872=10.00000|871=112|872=A|871=114|872=Y|871=115|872=N|1582=2|1583=103|1584=SEG8|1583=7|1584=2|1205=8|1206=0.00990|1207=1.94423|1208=0.00990|1206=1.94720|1207=4.88770|1208=0.01970|1206=5.10400|1207=9.91308|1208=0.04946|1206=9.75500|1207=24.27529|1208=0.09946|1206=25.56750|1207=101.67983|1208=0.25138|1206=100.77000|1207=196.31018|1208=0.50050|1206=195.86000|1207=393.67016|1208=1.01270|1206=401.72000|1207=21400.98840|1208=1.94720|1148=19.13464|1149=35.71258|561=100|711=1|311=[N/A]|457=1|458=1047|459=M|2874=SYM00162|15=THB|55=SYM00163|48=100000162|167=CS|965=1|228=1|231=1|1193=C|107=SYM00163_INSTRUMENT|864=1|865=5|866=20110101|2576=5|870=5|871=113|872=Y|871=104|872=1.00000|871=112|872=A|871=114|872=Y|871=115|872=N|1582=2|1583=103|1584=SEG8|1583=7|1584=13|1205=8|1206=0.00990|1207=1.94423|1208=0.00990|1206=1.94720|1207=4.88770|1208=0.01970|1206=5.10400|1207=9.91308|1208=0.04946|1206=9.75500|1207=24.27529|1208=0.09946|1206=25.56750|1207=101.67983|1208=0.25138|1206=100.77000|1207=196.31018|1208=0.50050|1206=195.86000|1207=393.67016|1208=1.01270|1206=401.72000|1207=21400.98840|1208=1.94720|1148=128.27500|1149=228.36660|561=100|711=1|311=[N/A]|457=1|458=1048|459=M|2874=SYM00163|15=THB|55=SYM00164|48=100000163|167=CS|965=1|228=1|231=1|1193=C|107=SYM00164_INSTRUMENT|864=1|865=5|866=20110101|2576=5|870=5|871=113|872=Y|871=104|872=1.00000|871=112|872=A|871=114|872=Y|871=115|872=N|1582=2|1583=103|1584=SEG8|1583=7|1584=3|1205=8|1206=0.00990|1207=1.94423|1208=0.00990|1206=1.94720|1207=4.88770|1208=0.01970|1206=5.10400|1207=9.91308|1208=0.04946|1206=9.75500|1207=24.27529|1208=0.09946|1206=25.56750|1207=101.67983|1208=0.25138|1206=100.77000|1207=196.31018|1208=0.50050|1206=195.86000|1207=393.67016|1208=1.01270|1206=401.72000|1207=21400.98840|1208=1.94720|1148=125.69370|1149=227.40720|561=100|711=1|311=[N/A]|457=1|458=1049|459=M|2874=SYM00164|15=THB|55=SYM00165|48=100000164|167=CS|965=1|228=1|231=1|1193=C|107=SYM00165_INSTRUMENT|864=1|865=5|866=20110101|2576=5|870=5|871=113|872=Y|871=104|872=1.00000|871=112|872=A|871=114|872=Y|871=115|872=N|1582=2|1583=103|1584=SEG8|1583=7|1584=25|1205=8|1206=0.00990|1207=1.94423|1208=0.00990|1206=1.94720|1207=4.88770|1208=0.01970|1206=5.10400|1207=9.91308|1208=0.04946|1206=9.75500|1207=24.27529|1208=0.09946|1206=25.56750|1207=101.67983|1208=0.25138|1206=100.77000|1207=196.31018|1208=0.50050|1206=195.86000|1207=393.67016|1208=1.01270|1206=401.72000|1207=21400.98840|1208=1.94720|1148=14.20158|1149=25.90902|561=100|711=1|311=[N/A]|457=1|458=1050|459=M|2874=SYM00165|15=THB|55=SYM00166|48=100000165|167=CS|965=1|228=1|231=1|1193=C|107=SYM00166_INSTRUMENT|864=1|865=5|866=20110101|2576=5|870=5|871=113|872=Y|871=104|872=1.00000|871=112|872=A|871=114|872=Y|871=115|872=N|1582=2|1583=103|1584=SEG8|1583=7|1584=5|1205=8|1206=0.00990|1207=1.94423|1208=0.00990|1206=1.94720|1207=4.88770|1208=0.01970|1206=5.10400|1207=9.91308|1208=0.04946|1206=9.75500|1207=24.27529|1208=0.09946|1206=25.56750|1207=101.67983|1208=0.25138|1206=100.77000|1207=196.31018|1208=0.50050|1206=195.86000|1207=393.67016|1208=1.01270|1206=401.72000|1207=21400.98840|1208=1.94720|1148=3.96152|1149=7.12068|561=100|711=1|311=[N/A]|457=1|458=1051|459=M|2874=SYM00166|15=THB|55=SYM00167|48=100000166|167=CS|965=1|228=1|231=1|1193=C|107=SYM00167_INSTRUMENT|864=1|865=5|866=20130515|2576=5|870=5|871=113|872=Y|871=104|872=0.10000|871=112|872=A|871=114|872=Y|871=115|872=N|1582=2|1583=103|1584=SEG8|1583=7|1584=13|1205=8|1206=0.00990|1207=1.94423|1208=0.00990|1206=1.94720|1207=4.88770|1208=0.01970|1206=5.10400|1207=9.91308|1208=0.04946|1206=9.75500|1207=24.27529|1208=0.09946|1206=25.56750|1207=101.67983|1208=0.25138|1206=100.77000|1207=196.31018|1208=0.50050|1206=195.86000|1207=393.67016|1208=1.01270|1206=401.72000|1207=21400.98840|1208=1.94720|1148=1.16620|1149=2.19230|561=100|711=1|311=[N/A]|457=1|458=1052|459=M|2874=SYM00167|15=THB|55=SYM00168|48=100000167|167=CS|965=1|228=1|231=1|1193=C|107=SYM00168_INSTRUMENT|864=1|865=5|866=20181016|2576=5|870=5|871=113|872=Y|871=104|872=1.00000|871=112|872=A|871=114|872=Y|871=115|872=N|1582=2|1583=103|1584=SEG8|1583=7|1584=12|1205=8|1206=0.00990|1207=1.94423|1208=0.00990|1206=1.94720|1207=4.88770|1208=0.01970|1206=5.10400|1207=9.91308|1208=0.04946|1206=9.75500|1207=24.27529|1208=0.09946|1206=25.56750|1207=101.67983|1208=0.25138|1206=100.77000|1207=196.31018|1208=0.50050|1206=195.86000|1207=393.67016|1208=1.01270|1206=401.72000|1207=21400.98840|1208=1.94720|1148=10.19288|1149=18.71100|561=100|711=1|311=[N/A]|457=1|458=1053|459=M|2874=SYM00168|15=THB|55=SYM00109|48=100000109|167=CS|965=1|228=1|231=1|1193=C|107=SYM00109_INSTRUMENT|864=1|865=5|866=20110101|2576=5|870=5|871=113|872=Y|871=104|872=0.50000|871=112|872=A|871=114|872=Y|871=115|872=N|1582=2|1583=103|1584=SEG8|1583=7|1584=25|1205=8|1206=0.00990|1207=1.94423|1208=0.00990|1206=1.94720|1207=4.88770|1208=0.01970|1206=5.10400|1207=9.91308|1208=0.04946|1206=9.75500|1207=24.27529|1208=0.09946|1206=25.56750|1207=101.67983|1208=0.25138|1206=100.77000|1207=196.31018|1208=0.50050|1206=195.86000|1207=393.67016|1208=1.01270|1206=401.72000|1207=21400.98840|1208=1.94720|1148=45.70425|1149=84.45338|561=100|711=1|311=[N/A]|457=1|458=1054|459=M|2874=SYM00109|15=THB|55=SYM00169|48=100000168|167=CS|965=1|228=1|231=1|1193=C|107=SYM00169_INSTRUMENT|864=1|865=5|866=20230301|2576=5|870=5|871=113|872=Y|871=104|872=4.00000|871=112|872=A|871=114|872=Y|871=115|872=N|1582=2|1583=103|1584=SEG8|1583=7|1584=6|1205=8|1206=0.00990|1207=1.94423|1208=0.00990|1206=1.94720|1207=4.88770|1208=0.01970|1206=5.10400|1207=9.91308|1208=0.04946|1206=9.75500|1207=24.27529|1208=0.09946|1206=25.56750|1207=101.67983|1208=0.25138|1206=100.77000|1207=196.31018|1208=0.50050|1206=195.86000|1207=393.67016|1208=1.01270|1206=401.72000|1207=21400.98840|1208=1.94720|1148=9.88416|1149=17.35856|561=100|711=1|311=[N/A]|457=1|458=1055|459=M|2874=SYM00169|15=THB|55=SYM00170|48=100000169|167=CS|965=1|228=1|231=1|1193=C|107=SYM00170_INSTRUMENT|864=1|865=5|866=20110101|2576=5|870=5|871=113|872=Y|871=104|872=1.00000|871=112|872=A|871=114|872=Y|871=115|872=N|1582=2|1583=103|1584=SEG8|1583=7|1584=25|1205=8|1206=0.00990|1207=1.94423|1208=0.00990|1206=1.94720|1207=4.88770|1208=0.01970|1206=5.10400|1207=9.91308|1208=0.04946|1206=9.75500|1207=24.27529|1208=0.09946|1206=25.56750|1207=101.67983|1208=0.25138|1206=100.77000|1207=196.31018|1208=0.50050|1206=195.86000|1207=393.67016|1208=1.01270|1206=401.72000|1207=21400.98840|1208=1.94720|1148=5.44362|1149=9.61557|561=100|711=1|311=[N/A]|457=1|458=1056|459=M|2874=SYM00170|15=THB|10=209|
